Workbook

Sheet Trading History
K2: UnRealised | W2: Realised
K3: Total | O3: Short Term | S3: Long Term
A4: DATE | B4: EXCH | C4: ACTION | D4: QTY | E4: PRICE | F4: COST | G4: REMARKS | H4: STT | I4: ADD CHRG | J4: Current Price | K4: Gain % | L4: Gain | M4: Gross | N4: Units | O4: Gain % | P4: Gain | Q4: Gross | R4: Units | S4: Gain % | T4: Gain | U4: Gross | V4: Units | W4: Price | X4: Date | Y4: Gain % | Z4: Gain | AA4: Gross | AB4: Units | AC4: DIV | AD4: Broker
A5: 45981 | B5: NSE | C5: Buy | D5: 20 | E5: 379 | F5: 7618 | G5: CN#252608441505 | I5: 38 | J5: =Index!$C$2
A6: 45968 | B6: NSE | C6: Buy | D6: 10 | E6: 372.95 | F6: 3748.1 | G6: CN#252607899666 | I6: 18.6 | J6: =Index!$C$2
A7: 46017 | B7: NSE | C7: Buy | D7: 10 | E7: 405.95 | F7: 4088.28 | G7: ~ | H7: 4.07 | I7: 24.71
A8: 46002 | B8: NSE | C8: Buy | D8: 10 | E8: 384.75 | F8: 3874.73 | G8: ~ | H8: 3.86 | I8: 23.37
A9: 45996 | B9: NSE | C9: Buy | D9: 10 | E9: 378.15 | F9: 3808.28 | G9: ~ | H9: 3.76 | I9: 23.02
A10: 45995 | B10: NSE | C10: Buy | D10: 10 | E10: 375.65 | F10: 3783.14 | G10: ~ | H10: 3.72 | I10: 22.92
A11: 45993 | B11: BSE | C11: Buy | D11: 10 | E11: 379 | F11: 3816.95 | G11: ~ | H11: 3.81 | I11: 23.14
A12: 45989 | B12: BSE | C12: Buy | D12: 10 | E12: 376.55 | F12: 3792.18 | G12: ~ | H12: 3.76 | I12: 22.92
A13: 45988 | B13: BSE | C13: Buy | D13: 10 | E13: 376.6 | F13: 3792.66 | G13: ~ | H13: 3.75 | I13: 22.91
A14: 45982 | B14: BSE | C14: Buy | D14: 20 | E14: 379.55 | F14: 7644.91 | G14: ~ | H14: 7.59 | I14: 46.32
A15: 45981 | B15: NSE | C15: Buy | D15: 13 | E15: 379 | F15: 4961.98 | G15: ~ | H15: 4.9 | I15: 30.08
A16: 45981 | B16: NSE | C16: Buy | D16: 7 | E16: 379 | F16: 2671.85 | G16: ~ | H16: 2.63 | I16: 16.22
A17: 45978 | B17: NSE | C17: Buy | D17: 20 | E17: 387.6 | F17: 7806.99 | G17: ~ | H17: 7.78 | I17: 47.21
A18: 45975 | B18: NSE | C18: Buy | D18: 10 | E18: 384 | F18: 3867.22 | G18: ~ | H18: 3.85 | I18: 23.37
... A30: 45903 | B30: NSE | C30: Buy | D30: 10 | E30: 381.85 | F30: 3845.58 | G30: ~ | H30: 3.83 | I30: 23.25
A31: 45890 | B31: DIV | C31: Buy | D31: 100 | E31: 5.15 | F31: 515 | G31: Final-Dividend of Rs.5.1500/- per share on Ex-Date: 21-AUG-2025 | H31: 0 | I31: 0 | J31: =Index!$C$2 | K31: =IF(AND( C8="Buy", ISBLANK(W8), B8<>"DIV"), L8/SUM(F8:I8), "") | L31: =IF(AND( C8="Buy", ISBLANK(W8), B8<>"DIV"), (1-Index!$F$2*2)*((J8*D8)-(E8*D8)), "") | M31: =IF(AND( C8="Buy", ISBLANK(W8), B8<>"DIV"), ((E8*D8)+L8), "") | N31: =IF(AND( C8="Buy", ISBLANK(W8), B8<>"DIV"), D8, "") | O31: =IF(AND( C8="Buy", ISBLANK(W8), B8<>"DIV", NOW()-A8 < 365), P8/SUM(F8:I8), "") | P31: =IF(AND( C8="Buy", ISBLANK(W8), B8<>"DIV", NOW()-A8 < 365), (1-Index!$F$2*2)*((J8*D8)-(E8*D8)), "") | Q31: =IF(AND( C8="Buy", ISBLANK(W8), B8<>"DIV", NOW()-A8 < 365), ((E8*D8)+P8), "") | R31: =IF(AND( C8="Buy", ISBLANK(W8), B8<>"DIV", NOW()-A8 < 365), D8, "") | S31: =IF(AND( C8="Buy", ISBLANK(W8), B8<>"DIV", NOW()-A8 > 365), T8/SUM(F8:I8), "") | T31: =IF(AND( C8="Buy", ISBLANK(W8), B8<>"DIV", NOW()-A8 > 365), (1-Index!$F$2*2)*((J8*D8)-(E8*D8)), "") | U31: =IF(AND( C8="Buy", ISBLANK(W8), B8<>"DIV", NOW()-A8 > 365), ((E8*D8)+T8), "") | V31: =IF(AND( C8="Buy", ISBLANK(W8), B8<>"DIV", NOW()-A8 > 365), D8, "") | Y31: =IF(AND( C8="Buy", W8<>"", AA8<>"", B8<>"DIV"), Z8/SUM(F8:I8), "") | AC31: =IF(B8="DIV", F8,"")
A32: 45875 | B32: DIV | C32: Buy | D32: 100 | E32: 5.5 | F32: 550 | G32: Interim-Dividend of Rs.5.5000/- per share on Ex-Date: 06-AUG-2025 | H32: 0 | I32: 0 | J32: =Index!$C$2 | K32: =IF(AND( C9="Buy", ISBLANK(W9), B9<>"DIV"), L9/SUM(F9:I9), "") | L32: =IF(AND( C9="Buy", ISBLANK(W9), B9<>"DIV"), (1-Index!$F$2*2)*((J9*D9)-(E9*D9)), "") | M32: =IF(AND( C9="Buy", ISBLANK(W9), B9<>"DIV"), ((E9*D9)+L9), "") | N32: =IF(AND( C9="Buy", ISBLANK(W9), B9<>"DIV"), D9, "") | O32: =IF(AND( C9="Buy", ISBLANK(W9), B9<>"DIV", NOW()-A9 < 365), P9/SUM(F9:I9), "") | P32: =IF(AND( C9="Buy", ISBLANK(W9), B9<>"DIV", NOW()-A9 < 365), (1-Index!$F$2*2)*((J9*D9)-(E9*D9)), "") | Q32: =IF(AND( C9="Buy", ISBLANK(W9), B9<>"DIV", NOW()-A9 < 365), ((E9*D9)+P9), "") | R32: =IF(AND( C9="Buy", ISBLANK(W9), B9<>"DIV", NOW()-A9 < 365), D9, "") | S32: =IF(AND( C9="Buy", ISBLANK(W9), B9<>"DIV", NOW()-A9 > 365), T9/SUM(F9:I9), "") | T32: =IF(AND( C9="Buy", ISBLANK(W9), B9<>"DIV", NOW()-A9 > 365), (1-Index!$F$2*2)*((J9*D9)-(E9*D9)), "") | U32: =IF(AND( C9="Buy", ISBLANK(W9), B9<>"DIV", NOW()-A9 > 365), ((E9*D9)+T9), "") | V32: =IF(AND( C9="Buy", ISBLANK(W9), B9<>"DIV", NOW()-A9 > 365), D9, "") | Y32: =IF(AND( C9="Buy", W9<>"", AA9<>"", B9<>"DIV"), Z9/SUM(F9:I9), "") | AC32: =IF(B9="DIV", F9,"")
A33: 45811 | B33: NSE | C33: Buy | D33: 30 | E33: 397.49 | F33: 11924.82 | G33: ~ | H33: 11.84 | I33: 71.98 | J33: =Index!$C$2 | K33: =IF(AND( C10="Buy", ISBLANK(W10), B10<>"DIV"), L10/SUM(F10:I10), "") | L33: =IF(AND( C10="Buy", ISBLANK(W10), B10<>"DIV"), (1-Index!$F$2*2)*((J10*D10)-(E10*D10)), "") | M33: =IF(AND( C10="Buy", ISBLANK(W10), B10<>"DIV"), ((E10*D10)+L10), "") | N33: =IF(AND( C10="Buy", ISBLANK(W10), B10<>"DIV"), D10, "") | O33: =IF(AND( C10="Buy", ISBLANK(W10), B10<>"DIV", NOW()-A10 < 365), P10/SUM(F10:I10), "") | P33: =IF(AND( C10="Buy", ISBLANK(W10), B10<>"DIV", NOW()-A10 < 365), (1-Index!$F$2*2)*((J10*D10)-(E10*D10)), "") | Q33: =IF(AND( C10="Buy", ISBLANK(W10), B10<>"DIV", NOW()-A10 < 365), ((E10*D10)+P10), "") | R33: =IF(AND( C10="Buy", ISBLANK(W10), B10<>"DIV", NOW()-A10 < 365), D10, "") | S33: =IF(AND( C10="Buy", ISBLANK(W10), B10<>"DIV", NOW()-A10 > 365), T10/SUM(F10:I10), "") | T33: =IF(AND( C10="Buy", ISBLANK(W10), B10<>"DIV", NOW()-A10 > 365), (1-Index!$F$2*2)*((J10*D10)-(E10*D10)), "") | U33: =IF(AND( C10="Buy", ISBLANK(W10), B10<>"DIV", NOW()-A10 > 365), ((E10*D10)+T10), "") | V33: =IF(AND( C10="Buy", ISBLANK(W10), B10<>"DIV", NOW()-A10 > 365), D10, "") | Y33: =IF(AND( C10="Buy", W10<>"", AA10<>"", B10<>"DIV"), Z10/SUM(F10:I10), "") | AC33: =IF(B10="DIV", F10,"")
A34: 45806 | B34: NSE | C34: Buy | D34: 10 | E34: 401.94 | F34: 4019.39 | G34: ~ | H34: 4.01 | I34: 24.38 | J34: =Index!$C$2 | K34: =IF(AND( C11="Buy", ISBLANK(W11), B11<>"DIV"), L11/SUM(F11:I11), "") | L34: =IF(AND( C11="Buy", ISBLANK(W11), B11<>"DIV"), (1-Index!$F$2*2)*((J11*D11)-(E11*D11)), "") | M34: =IF(AND( C11="Buy", ISBLANK(W11), B11<>"DIV"), ((E11*D11)+L11), "") | N34: =IF(AND( C11="Buy", ISBLANK(W11), B11<>"DIV"), D11, "") | O34: =IF(AND( C11="Buy", ISBLANK(W11), B11<>"DIV", NOW()-A11 < 365), P11/SUM(F11:I11), "") | P34: =IF(AND( C11="Buy", ISBLANK(W11), B11<>"DIV", NOW()-A11 < 365), (1-Index!$F$2*2)*((J11*D11)-(E11*D11)), "") | Q34: =IF(AND( C11="Buy", ISBLANK(W11), B11<>"DIV", NOW()-A11 < 365), ((E11*D11)+P11), "") | R34: =IF(AND( C11="Buy", ISBLANK(W11), B11<>"DIV", NOW()-A11 < 365), D11, "") | S34: =IF(AND( C11="Buy", ISBLANK(W11), B11<>"DIV", NOW()-A11 > 365), T11/SUM(F11:I11), "") | T34: =IF(AND( C11="Buy", ISBLANK(W11), B11<>"DIV", NOW()-A11 > 365), (1-Index!$F$2*2)*((J11*D11)-(E11*D11)), "") | U34: =IF(AND( C11="Buy", ISBLANK(W11), B11<>"DIV", NOW()-A11 > 365), ((E11*D11)+T11), "") | V34: =IF(AND( C11="Buy", ISBLANK(W11), B11<>"DIV", NOW()-A11 > 365), D11, "") | Y34: =IF(AND( C11="Buy", W11<>"", AA11<>"", B11<>"DIV"), Z11/SUM(F11:I11), "") | AC34: =IF(B11="DIV", F11,"")
A35: 45705 | B35: NSE | C35: Buy | D35: 40 | E35: 356.71 | F35: 14268.34 | G35: ~ | H35: 14.15 | I35: 86.19 | J35: =Index!$C$2 | K35: =IF(AND( C12="Buy", ISBLANK(W12), B12<>"DIV"), L12/SUM(F12:I12), "") | L35: =IF(AND( C12="Buy", ISBLANK(W12), B12<>"DIV"), (1-Index!$F$2*2)*((J12*D12)-(E12*D12)), "") | M35: =IF(AND( C12="Buy", ISBLANK(W12), B12<>"DIV"), ((E12*D12)+L12), "") | N35: =IF(AND( C12="Buy", ISBLANK(W12), B12<>"DIV"), D12, "") | O35: =IF(AND( C12="Buy", ISBLANK(W12), B12<>"DIV", NOW()-A12 < 365), P12/SUM(F12:I12), "") | P35: =IF(AND( C12="Buy", ISBLANK(W12), B12<>"DIV", NOW()-A12 < 365), (1-Index!$F$2*2)*((J12*D12)-(E12*D12)), "") | Q35: =IF(AND( C12="Buy", ISBLANK(W12), B12<>"DIV", NOW()-A12 < 365), ((E12*D12)+P12), "") | R35: =IF(AND( C12="Buy", ISBLANK(W12), B12<>"DIV", NOW()-A12 < 365), D12, "") | S35: =IF(AND( C12="Buy", ISBLANK(W12), B12<>"DIV", NOW()-A12 > 365), T12/SUM(F12:I12), "") | T35: =IF(AND( C12="Buy", ISBLANK(W12), B12<>"DIV", NOW()-A12 > 365), (1-Index!$F$2*2)*((J12*D12)-(E12*D12)), "") | U35: =IF(AND( C12="Buy", ISBLANK(W12), B12<>"DIV", NOW()-A12 > 365), ((E12*D12)+T12), "") | V35: =IF(AND( C12="Buy", ISBLANK(W12), B12<>"DIV", NOW()-A12 > 365), D12, "") | Y35: =IF(AND( C12="Buy", W12<>"", AA12<>"", B12<>"DIV"), Z12/SUM(F12:I12), "") | AC35: =IF(B12="DIV", F12,"")
A36: 45699 | B36: NSE | C36: Buy | D36: 10 | E36: 365.01 | F36: 3650.14 | G36: ~ | H36: 3.62 | I36: 22.02 | J36: =Index!$C$2 | K36: =IF(AND( C13="Buy", ISBLANK(W13), B13<>"DIV"), L13/SUM(F13:I13), "") | L36: =IF(AND( C13="Buy", ISBLANK(W13), B13<>"DIV"), (1-Index!$F$2*2)*((J13*D13)-(E13*D13)), "") | M36: =IF(AND( C13="Buy", ISBLANK(W13), B13<>"DIV"), ((E13*D13)+L13), "") | N36: =IF(AND( C13="Buy", ISBLANK(W13), B13<>"DIV"), D13, "") | O36: =IF(AND( C13="Buy", ISBLANK(W13), B13<>"DIV", NOW()-A13 < 365), P13/SUM(F13:I13), "") | P36: =IF(AND( C13="Buy", ISBLANK(W13), B13<>"DIV", NOW()-A13 < 365), (1-Index!$F$2*2)*((J13*D13)-(E13*D13)), "") | Q36: =IF(AND( C13="Buy", ISBLANK(W13), B13<>"DIV", NOW()-A13 < 365), ((E13*D13)+P13), "") | R36: =IF(AND( C13="Buy", ISBLANK(W13), B13<>"DIV", NOW()-A13 < 365), D13, "") | S36: =IF(AND( C13="Buy", ISBLANK(W13), B13<>"DIV", NOW()-A13 > 365), T13/SUM(F13:I13), "") | T36: =IF(AND( C13="Buy", ISBLANK(W13), B13<>"DIV", NOW()-A13 > 365), (1-Index!$F$2*2)*((J13*D13)-(E13*D13)), "") | U36: =IF(AND( C13="Buy", ISBLANK(W13), B13<>"DIV", NOW()-A13 > 365), ((E13*D13)+T13), "") | V36: =IF(AND( C13="Buy", ISBLANK(W13), B13<>"DIV", NOW()-A13 > 365), D13, "") | Y36: =IF(AND( C13="Buy", W13<>"", AA13<>"", B13<>"DIV"), Z13/SUM(F13:I13), "") | AC36: =IF(B13="DIV", F13,"")
A37: 45694 | B37: NSE | C37: Buy | D37: 10 | E37: 381.69 | F37: 3816.91 | G37: ~ | H37: 3.78 | I37: 23.13 | J37: =Index!$C$2 | K37: =IF(AND( C14="Buy", ISBLANK(W14), B14<>"DIV"), L14/SUM(F14:I14), "") | L37: =IF(AND( C14="Buy", ISBLANK(W14), B14<>"DIV"), (1-Index!$F$2*2)*((J14*D14)-(E14*D14)), "") | M37: =IF(AND( C14="Buy", ISBLANK(W14), B14<>"DIV"), ((E14*D14)+L14), "") | N37: =IF(AND( C14="Buy", ISBLANK(W14), B14<>"DIV"), D14, "") | O37: =IF(AND( C14="Buy", ISBLANK(W14), B14<>"DIV", NOW()-A14 < 365), P14/SUM(F14:I14), "") | P37: =IF(AND( C14="Buy", ISBLANK(W14), B14<>"DIV", NOW()-A14 < 365), (1-Index!$F$2*2)*((J14*D14)-(E14*D14)), "") | Q37: =IF(AND( C14="Buy", ISBLANK(W14), B14<>"DIV", NOW()-A14 < 365), ((E14*D14)+P14), "") | R37: =IF(AND( C14="Buy", ISBLANK(W14), B14<>"DIV", NOW()-A14 < 365), D14, "") | S37: =IF(AND( C14="Buy", ISBLANK(W14), B14<>"DIV", NOW()-A14 > 365), T14/SUM(F14:I14), "") | T37: =IF(AND( C14="Buy", ISBLANK(W14), B14<>"DIV", NOW()-A14 > 365), (1-Index!$F$2*2)*((J14*D14)-(E14*D14)), "") | U37: =IF(AND( C14="Buy", ISBLANK(W14), B14<>"DIV", NOW()-A14 > 365), ((E14*D14)+T14), "") | V37: =IF(AND( C14="Buy", ISBLANK(W14), B14<>"DIV", NOW()-A14 > 365), D14, "") | Y37: =IF(AND( C14="Buy", W14<>"", AA14<>"", B14<>"DIV"), Z14/SUM(F14:I14), "") | AC37: =IF(B14="DIV", F14,"")
A38: 45282 | B38: NSE | C38: Sell | D38: 10 | E38: 359.01 | F38: 3595.9 | G38: ~ | H38: 0.84 | I38: 4.96 | J38: =Index!$C$2 | K38: =IF(AND( C15="Buy", ISBLANK(W15), B15<>"DIV"), L15/SUM(F15:I15), "") | L38: =IF(AND( C15="Buy", ISBLANK(W15), B15<>"DIV"), (1-Index!$F$2*2)*((J15*D15)-(E15*D15)), "") | M38: =IF(AND( C15="Buy", ISBLANK(W15), B15<>"DIV"), ((E15*D15)+L15), "") | N38: =IF(AND( C15="Buy", ISBLANK(W15), B15<>"DIV"), D15, "") | O38: =IF(AND( C15="Buy", ISBLANK(W15), B15<>"DIV", NOW()-A15 < 365), P15/SUM(F15:I15), "") | P38: =IF(AND( C15="Buy", ISBLANK(W15), B15<>"DIV", NOW()-A15 < 365), (1-Index!$F$2*2)*((J15*D15)-(E15*D15)), "") | Q38: =IF(AND( C15="Buy", ISBLANK(W15), B15<>"DIV", NOW()-A15 < 365), ((E15*D15)+P15), "") | R38: =IF(AND( C15="Buy", ISBLANK(W15), B15<>"DIV", NOW()-A15 < 365), D15, "") | S38: =IF(AND( C15="Buy", ISBLANK(W15), B15<>"DIV", NOW()-A15 > 365), T15/SUM(F15:I15), "") | T38: =IF(AND( C15="Buy", ISBLANK(W15), B15<>"DIV", NOW()-A15 > 365), (1-Index!$F$2*2)*((J15*D15)-(E15*D15)), "") | U38: =IF(AND( C15="Buy", ISBLANK(W15), B15<>"DIV", NOW()-A15 > 365), ((E15*D15)+T15), "") | V38: =IF(AND( C15="Buy", ISBLANK(W15), B15<>"DIV", NOW()-A15 > 365), D15, "") | Y38: =IF(AND( C15="Buy", W15<>"", AA15<>"", B15<>"DIV"), Z15/SUM(F15:I15), "") | AC38: =IF(B15="DIV", F15,"")
A39: 45251 | B39: DIV | C39: Buy | D39: 10 | E39: 15.25 | F39: 152.5 | G39: Interim-Dividend of Rs.15.2500/- per share on Ex-Date: 21-NOV-2023 | H39: 0 | I39: 0 | J39: =Index!$C$2 | K39: =IF(AND( C16="Buy", ISBLANK(W16), B16<>"DIV"), L16/SUM(F16:I16), "") | L39: =IF(AND( C16="Buy", ISBLANK(W16), B16<>"DIV"), (1-Index!$F$2*2)*((J16*D16)-(E16*D16)), "") | M39: =IF(AND( C16="Buy", ISBLANK(W16), B16<>"DIV"), ((E16*D16)+L16), "") | N39: =IF(AND( C16="Buy", ISBLANK(W16), B16<>"DIV"), D16, "") | O39: =IF(AND( C16="Buy", ISBLANK(W16), B16<>"DIV", NOW()-A16 < 365), P16/SUM(F16:I16), "") | P39: =IF(AND( C16="Buy", ISBLANK(W16), B16<>"DIV", NOW()-A16 < 365), (1-Index!$F$2*2)*((J16*D16)-(E16*D16)), "") | Q39: =IF(AND( C16="Buy", ISBLANK(W16), B16<>"DIV", NOW()-A16 < 365), ((E16*D16)+P16), "") | R39: =IF(AND( C16="Buy", ISBLANK(W16), B16<>"DIV", NOW()-A16 < 365), D16, "") | S39: =IF(AND( C16="Buy", ISBLANK(W16), B16<>"DIV", NOW()-A16 > 365), T16/SUM(F16:I16), "") | T39: =IF(AND( C16="Buy", ISBLANK(W16), B16<>"DIV", NOW()-A16 > 365), (1-Index!$F$2*2)*((J16*D16)-(E16*D16)), "") | U39: =IF(AND( C16="Buy", ISBLANK(W16), B16<>"DIV", NOW()-A16 > 365), ((E16*D16)+T16), "") | V39: =IF(AND( C16="Buy", ISBLANK(W16), B16<>"DIV", NOW()-A16 > 365), D16, "") | Y39: =IF(AND( C16="Buy", W16<>"", AA16<>"", B16<>"DIV"), Z16/SUM(F16:I16), "") | AC39: =IF(B16="DIV", F16,"")
A40: 45183 | B40: NSE | C40: Sell | D40: 3 | E40: 274.53667 | F40: 829.4 | G40: ~ | H40: 0.84 | I40: 4.96 | J40: =Index!$C$2 | K40: =IF(AND( C17="Buy", ISBLANK(W17), B17<>"DIV"), L17/SUM(F17:I17), "") | L40: =IF(AND( C17="Buy", ISBLANK(W17), B17<>"DIV"), (1-Index!$F$2*2)*((J17*D17)-(E17*D17)), "") | M40: =IF(AND( C17="Buy", ISBLANK(W17), B17<>"DIV"), ((E17*D17)+L17), "") | N40: =IF(AND( C17="Buy", ISBLANK(W17), B17<>"DIV"), D17, "") | O40: =IF(AND( C17="Buy", ISBLANK(W17), B17<>"DIV", NOW()-A17 < 365), P17/SUM(F17:I17), "") | P40: =IF(AND( C17="Buy", ISBLANK(W17), B17<>"DIV", NOW()-A17 < 365), (1-Index!$F$2*2)*((J17*D17)-(E17*D17)), "") | Q40: =IF(AND( C17="Buy", ISBLANK(W17), B17<>"DIV", NOW()-A17 < 365), ((E17*D17)+P17), "") | R40: =IF(AND( C17="Buy", ISBLANK(W17), B17<>"DIV", NOW()-A17 < 365), D17, "") | S40: =IF(AND( C17="Buy", ISBLANK(W17), B17<>"DIV", NOW()-A17 > 365), T17/SUM(F17:I17), "") | T40: =IF(AND( C17="Buy", ISBLANK(W17), B17<>"DIV", NOW()-A17 > 365), (1-Index!$F$2*2)*((J17*D17)-(E17*D17)), "") | U40: =IF(AND( C17="Buy", ISBLANK(W17), B17<>"DIV", NOW()-A17 > 365), ((E17*D17)+T17), "") | V40: =IF(AND( C17="Buy", ISBLANK(W17), B17<>"DIV", NOW()-A17 > 365), D17, "") | Y40: =IF(AND( C17="Buy", W17<>"", AA17<>"", B17<>"DIV"), Z17/SUM(F17:I17), "") | AC40: =IF(B17="DIV", F17,"")
A41: 45183 | B41: NSE | C41: Sell | D41: 66 | E41: 274.54 | F41: 18247.02 | G41: ~ | H41: 18.39 | I41: 108.99 | J41: =Index!$C$2 | K41: =IF(AND( C18="Buy", ISBLANK(W18), B18<>"DIV"), L18/SUM(F18:I18), "") | L41: =IF(AND( C18="Buy", ISBLANK(W18), B18<>"DIV"), (1-Index!$F$2*2)*((J18*D18)-(E18*D18)), "") | M41: =IF(AND( C18="Buy", ISBLANK(W18), B18<>"DIV"), ((E18*D18)+L18), "") | N41: =IF(AND( C18="Buy", ISBLANK(W18), B18<>"DIV"), D18, "") | O41: =IF(AND( C18="Buy", ISBLANK(W18), B18<>"DIV", NOW()-A18 < 365), P18/SUM(F18:I18), "") | P41: =IF(AND( C18="Buy", ISBLANK(W18), B18<>"DIV", NOW()-A18 < 365), (1-Index!$F$2*2)*((J18*D18)-(E18*D18)), "") | Q41: =IF(AND( C18="Buy", ISBLANK(W18), B18<>"DIV", NOW()-A18 < 365), ((E18*D18)+P18), "") | R41: =IF(AND( C18="Buy", ISBLANK(W18), B18<>"DIV", NOW()-A18 < 365), D18, "") | S41: =IF(AND( C18="Buy", ISBLANK(W18), B18<>"DIV", NOW()-A18 > 365), T18/SUM(F18:I18), "") | T41: =IF(AND( C18="Buy", ISBLANK(W18), B18<>"DIV", NOW()-A18 > 365), (1-Index!$F$2*2)*((J18*D18)-(E18*D18)), "") | U41: =IF(AND( C18="Buy", ISBLANK(W18), B18<>"DIV", NOW()-A18 > 365), ((E18*D18)+T18), "") | V41: =IF(AND( C18="Buy", ISBLANK(W18), B18<>"DIV", NOW()-A18 > 365), D18, "") | Y41: =IF(AND( C18="Buy", W18<>"", AA18<>"", B18<>"DIV"), Z18/SUM(F18:I18), "") | AC41: =IF(B18="DIV", F18,"")
A42: 45183 | B42: NSE | C42: Sell | D42: 31 | E42: 274.53936 | F42: 8570.55 | G42: ~ | H42: 8.64 | I42: 51.21 | J42: =Index!$C$2 | K42: =IF(AND( C19="Buy", ISBLANK(W19), B19<>"DIV"), L19/SUM(F19:I19), "") | L42: =IF(AND( C19="Buy", ISBLANK(W19), B19<>"DIV"), (1-Index!$F$2*2)*((J19*D19)-(E19*D19)), "") | M42: =IF(AND( C19="Buy", ISBLANK(W19), B19<>"DIV"), ((E19*D19)+L19), "") | N42: =IF(AND( C19="Buy", ISBLANK(W19), B19<>"DIV"), D19, "") | O42: =IF(AND( C19="Buy", ISBLANK(W19), B19<>"DIV", NOW()-A19 < 365), P19/SUM(F19:I19), "") | P42: =IF(AND( C19="Buy", ISBLANK(W19), B19<>"DIV", NOW()-A19 < 365), (1-Index!$F$2*2)*((J19*D19)-(E19*D19)), "") | Q42: =IF(AND( C19="Buy", ISBLANK(W19), B19<>"DIV", NOW()-A19 < 365), ((E19*D19)+P19), "") | R42: =IF(AND( C19="Buy", ISBLANK(W19), B19<>"DIV", NOW()-A19 < 365), D19, "") | S42: =IF(AND( C19="Buy", ISBLANK(W19), B19<>"DIV", NOW()-A19 > 365), T19/SUM(F19:I19), "") | T42: =IF(AND( C19="Buy", ISBLANK(W19), B19<>"DIV", NOW()-A19 > 365), (1-Index!$F$2*2)*((J19*D19)-(E19*D19)), "") | U42: =IF(AND( C19="Buy", ISBLANK(W19), B19<>"DIV", NOW()-A19 > 365), ((E19*D19)+T19), "") | V42: =IF(AND( C19="Buy", ISBLANK(W19), B19<>"DIV", NOW()-A19 > 365), D19, "") | Y42: =IF(AND( C19="Buy", W19<>"", AA19<>"", B19<>"DIV"), Z19/SUM(F19:I19), "") | AC42: =IF(B19="DIV", F19,"")
A43: 45162 | B43: NSE | C43: Buy | D43: 10 | E43: 72.978 | F43: 2337.44 | G43: ~ | H43: 6.9 | I43: 42.42 | J43: =Index!$C$2 | L43: =IF(AND( C20="Buy", ISBLANK(W20), B20<>"DIV"), (1-Index!$F$2*2)*((J20*D20)-(E20*D20)), "") | M43: =IF(AND( C20="Buy", ISBLANK(W20), B20<>"DIV"), ((E20*D20)+L20), "") | N43: =IF(AND( C20="Buy", ISBLANK(W20), B20<>"DIV"), D20, "") | P43: =IF(AND( C20="Buy", ISBLANK(W20), B20<>"DIV", NOW()-A20 < 365), (1-Index!$F$2*2)*((J20*D20)-(E20*D20)), "") | Q43: =IF(AND( C20="Buy", ISBLANK(W20), B20<>"DIV", NOW()-A20 < 365), ((E20*D20)+P20), "") | R43: =IF(AND( C20="Buy", ISBLANK(W20), B20<>"DIV", NOW()-A20 < 365), D20, "") | T43: =IF(AND( C20="Buy", ISBLANK(W20), B20<>"DIV", NOW()-A20 > 365), (J20*D20)-(E20*D20)-(2*SUM(H20:I20)), "") | U43: =IF(AND( C20="Buy", ISBLANK(W20), B20<>"DIV", NOW()-A20 > 365), ((E20*D20)+T20), "") | V43: =IF(AND( C20="Buy", ISBLANK(W20), B20<>"DIV", NOW()-A20 > 365), D20, "") | W43: 359.01 | X43: 45282 | Y43: =IF(AND( C20="Buy", W20<>"", AA20<>"", B20<>"DIV"), Z20/SUM(F20:I20), "") | Z43: -367.7287 | AA43: 372.95 | AB43: 1 | AC43: =IF(B20="DIV", F20,"")
A44: 45162 | B44: NSE | C44: Buy | D44: 20 | E44: 153.364 | F44: 4674.88 | G44: ~ | H44: 6.9 | I44: 42.42 | J44: =Index!$C$2 | L44: =IF(AND( C21="Buy", ISBLANK(W21), B21<>"DIV"), (1-Index!$F$2*2)*((J21*D21)-(E21*D21)), "") | M44: =IF(AND( C21="Buy", ISBLANK(W21), B21<>"DIV"), ((E21*D21)+L21), "") | N44: =IF(AND( C21="Buy", ISBLANK(W21), B21<>"DIV"), D21, "") | P44: =IF(AND( C21="Buy", ISBLANK(W21), B21<>"DIV", NOW()-A21 < 365), (1-Index!$F$2*2)*((J21*D21)-(E21*D21)), "") | Q44: =IF(AND( C21="Buy", ISBLANK(W21), B21<>"DIV", NOW()-A21 < 365), ((E21*D21)+P21), "") | R44: =IF(AND( C21="Buy", ISBLANK(W21), B21<>"DIV", NOW()-A21 < 365), D21, "") | T44: =IF(AND( C21="Buy", ISBLANK(W21), B21<>"DIV", NOW()-A21 > 365), (J21*D21)-(E21*D21)-(2*SUM(H21:I21)), "") | U44: =IF(AND( C21="Buy", ISBLANK(W21), B21<>"DIV", NOW()-A21 > 365), ((E21*D21)+T21), "") | V44: =IF(AND( C21="Buy", ISBLANK(W21), B21<>"DIV", NOW()-A21 > 365), D21, "") | W44: 274.54 | X44: 45183 | Y44: =IF(AND( C21="Buy", W21<>"", AA21<>"", B21<>"DIV"), Z21/SUM(F21:I21), "") | Z44: -3309.5583 | AA44: 3356.55 | AB44: 9 | AC44: =IF(B21="DIV", F21,"")
A45: 45156 | B45: DIV | C45: Buy | D45: 80 | E45: 4 | F45: 320 | G45: Final-Dividend of Rs.4.0000/- per share on Ex-Date: 18-AUG-2023 | H45: 0 | I45: 0 | J45: =Index!$C$2 | L45: =IF(AND( C22="Buy", ISBLANK(W22), B22<>"DIV"), (1-Index!$F$2*2)*((J22*D22)-(E22*D22)), "") | M45: =IF(AND( C22="Buy", ISBLANK(W22), B22<>"DIV"), ((E22*D22)+L22), "") | N45: =IF(AND( C22="Buy", ISBLANK(W22), B22<>"DIV"), D22, "") | P45: =IF(AND( C22="Buy", ISBLANK(W22), B22<>"DIV", NOW()-A22 < 365), (1-Index!$F$2*2)*((J22*D22)-(E22*D22)), "") | Q45: =IF(AND( C22="Buy", ISBLANK(W22), B22<>"DIV", NOW()-A22 < 365), ((E22*D22)+P22), "") | R45: =IF(AND( C22="Buy", ISBLANK(W22), B22<>"DIV", NOW()-A22 < 365), D22, "") | T45: =IF(AND( C22="Buy", ISBLANK(W22), B22<>"DIV", NOW()-A22 > 365), (J22*D22)-(E22*D22)-(2*SUM(H22:I22)), "") | U45: =IF(AND( C22="Buy", ISBLANK(W22), B22<>"DIV", NOW()-A22 > 365), ((E22*D22)+T22), "") | V45: =IF(AND( C22="Buy", ISBLANK(W22), B22<>"DIV", NOW()-A22 > 365), D22, "") | Y45: =IF(AND( C22="Buy", W22<>"", AA22<>"", B22<>"DIV"), Z22/SUM(F22:I22), "") | AC45: =IF(B22="DIV", F22,"")
A46: 45131 | B46: NSE | C46: Buy | D46: 10 | E46: 228.945 | F46: 2305.65 | G46: ~ | H46: 2.28 | I46: 13.87 | J46: =Index!$C$2 | L46: =IF(AND( C23="Buy", ISBLANK(W23), B23<>"DIV"), (1-Index!$F$2*2)*((J23*D23)-(E23*D23)), "") | M46: =IF(AND( C23="Buy", ISBLANK(W23), B23<>"DIV"), ((E23*D23)+L23), "") | N46: =IF(AND( C23="Buy", ISBLANK(W23), B23<>"DIV"), D23, "") | P46: =IF(AND( C23="Buy", ISBLANK(W23), B23<>"DIV", NOW()-A23 < 365), (1-Index!$F$2*2)*((J23*D23)-(E23*D23)), "") | Q46: =IF(AND( C23="Buy", ISBLANK(W23), B23<>"DIV", NOW()-A23 < 365), ((E23*D23)+P23), "") | R46: =IF(AND( C23="Buy", ISBLANK(W23), B23<>"DIV", NOW()-A23 < 365), D23, "") | T46: =IF(AND( C23="Buy", ISBLANK(W23), B23<>"DIV", NOW()-A23 > 365), (J23*D23)-(E23*D23)-(2*SUM(H23:I23)), "") | U46: =IF(AND( C23="Buy", ISBLANK(W23), B23<>"DIV", NOW()-A23 > 365), ((E23*D23)+T23), "") | V46: =IF(AND( C23="Buy", ISBLANK(W23), B23<>"DIV", NOW()-A23 > 365), D23, "") | W46: 274.54 | X46: 45183 | Y46: =IF(AND( C23="Buy", W23<>"", AA23<>"", B23<>"DIV"), Z23/SUM(F23:I23), "") | Z46: -3916.885 | AA46: 3972.5 | AB46: 10 | AC46: =IF(B23="DIV", F23,"")
A47: 45099 | B47: NSE | C47: Buy | D47: 50 | E47: 229.3038 | F47: 11546.31 | G47: ~ | H47: 11 | I47: 70.31 | J47: =Index!$C$2 | L47: =IF(AND( C24="Buy", ISBLANK(W24), B24<>"DIV"), (1-Index!$F$2*2)*((J24*D24)-(E24*D24)), "") | M47: =IF(AND( C24="Buy", ISBLANK(W24), B24<>"DIV"), ((E24*D24)+L24), "") | N47: =IF(AND( C24="Buy", ISBLANK(W24), B24<>"DIV"), D24, "") | P47: =IF(AND( C24="Buy", ISBLANK(W24), B24<>"DIV", NOW()-A24 < 365), (1-Index!$F$2*2)*((J24*D24)-(E24*D24)), "") | Q47: =IF(AND( C24="Buy", ISBLANK(W24), B24<>"DIV", NOW()-A24 < 365), ((E24*D24)+P24), "") | R47: =IF(AND( C24="Buy", ISBLANK(W24), B24<>"DIV", NOW()-A24 < 365), D24, "") | T47: =IF(AND( C24="Buy", ISBLANK(W24), B24<>"DIV", NOW()-A24 > 365), (J24*D24)-(E24*D24)-(2*SUM(H24:I24)), "") | U47: =IF(AND( C24="Buy", ISBLANK(W24), B24<>"DIV", NOW()-A24 > 365), ((E24*D24)+T24), "") | V47: =IF(AND( C24="Buy", ISBLANK(W24), B24<>"DIV", NOW()-A24 > 365), D24, "") | W47: 274.54 | X47: 45183 | Y47: =IF(AND( C24="Buy", W24<>"", AA24<>"", B24<>"DIV"), Z24/SUM(F24:I24), "") | Z47: -3892.728 | AA47: 3948 | AB47: 10 | AC47: =IF(B24="DIV", F24,"")
A48: 45034 | B48: NSE | C48: Buy | D48: 10 | E48: 231.054 | F48: 2326.96 | G48: ~ | H48: 2.31 | I48: 14.15 | J48: =Index!$C$2 | L48: =IF(AND( C25="Buy", ISBLANK(W25), B25<>"DIV"), (1-Index!$F$2*2)*((J25*D25)-(E25*D25)), "") | M48: =IF(AND( C25="Buy", ISBLANK(W25), B25<>"DIV"), ((E25*D25)+L25), "") | N48: =IF(AND( C25="Buy", ISBLANK(W25), B25<>"DIV"), D25, "") | P48: =IF(AND( C25="Buy", ISBLANK(W25), B25<>"DIV", NOW()-A25 < 365), (1-Index!$F$2*2)*((J25*D25)-(E25*D25)), "") | Q48: =IF(AND( C25="Buy", ISBLANK(W25), B25<>"DIV", NOW()-A25 < 365), ((E25*D25)+P25), "") | R48: =IF(AND( C25="Buy", ISBLANK(W25), B25<>"DIV", NOW()-A25 < 365), D25, "") | T48: =IF(AND( C25="Buy", ISBLANK(W25), B25<>"DIV", NOW()-A25 > 365), (J25*D25)-(E25*D25)-(2*SUM(H25:I25)), "") | U48: =IF(AND( C25="Buy", ISBLANK(W25), B25<>"DIV", NOW()-A25 > 365), ((E25*D25)+T25), "") | V48: =IF(AND( C25="Buy", ISBLANK(W25), B25<>"DIV", NOW()-A25 > 365), D25, "") | W48: 274.54 | X48: 45183 | Y48: =IF(AND( C25="Buy", W25<>"", AA25<>"", B25<>"DIV"), Z25/SUM(F25:I25), "") | Z48: -3870.05 | AA48: 3925 | AB48: 10 | AC48: =IF(B25="DIV", F25,"")
A49: 44965 | B49: DIV | C49: Buy | D49: 10 | E49: 5.25 | F49: 52.5 | G49: Dividend of Rs.5.2500/- per share on 08-FEB-2023 | H49: 0 | I49: 0 | J49: =Index!$C$2 | L49: =IF(AND( C26="Buy", ISBLANK(W26), B26<>"DIV"), (1-Index!$F$2*2)*((J26*D26)-(E26*D26)), "") | M49: =IF(AND( C26="Buy", ISBLANK(W26), B26<>"DIV"), ((E26*D26)+L26), "") | N49: =IF(AND( C26="Buy", ISBLANK(W26), B26<>"DIV"), D26, "") | P49: =IF(AND( C26="Buy", ISBLANK(W26), B26<>"DIV", NOW()-A26 < 365), (1-Index!$F$2*2)*((J26*D26)-(E26*D26)), "") | Q49: =IF(AND( C26="Buy", ISBLANK(W26), B26<>"DIV", NOW()-A26 < 365), ((E26*D26)+P26), "") | R49: =IF(AND( C26="Buy", ISBLANK(W26), B26<>"DIV", NOW()-A26 < 365), D26, "") | T49: =IF(AND( C26="Buy", ISBLANK(W26), B26<>"DIV", NOW()-A26 > 365), (J26*D26)-(E26*D26)-(2*SUM(H26:I26)), "") | U49: =IF(AND( C26="Buy", ISBLANK(W26), B26<>"DIV", NOW()-A26 > 365), ((E26*D26)+T26), "") | V49: =IF(AND( C26="Buy", ISBLANK(W26), B26<>"DIV", NOW()-A26 > 365), D26, "") | Y49: =IF(AND( C26="Buy", W26<>"", AA26<>"", B26<>"DIV"), Z26/SUM(F26:I26), "") | AC49: =IF(B26="DIV", F26,"")
A50: 44950 | B50: NSE | C50: Buy | D50: 10 | E50: 229.253 | F50: 2308.77 | G50: ~ | H50: 2.28 | I50: 13.99 | J50: =Index!$C$2 | L50: =IF(AND( C27="Buy", ISBLANK(W27), B27<>"DIV"), (1-Index!$F$2*2)*((J27*D27)-(E27*D27)), "") | M50: =IF(AND( C27="Buy", ISBLANK(W27), B27<>"DIV"), ((E27*D27)+L27), "") | N50: =IF(AND( C27="Buy", ISBLANK(W27), B27<>"DIV"), D27, "") | P50: =IF(AND( C27="Buy", ISBLANK(W27), B27<>"DIV", NOW()-A27 < 365), (1-Index!$F$2*2)*((J27*D27)-(E27*D27)), "") | Q50: =IF(AND( C27="Buy", ISBLANK(W27), B27<>"DIV", NOW()-A27 < 365), ((E27*D27)+P27), "") | R50: =IF(AND( C27="Buy", ISBLANK(W27), B27<>"DIV", NOW()-A27 < 365), D27, "") | T50: =IF(AND( C27="Buy", ISBLANK(W27), B27<>"DIV", NOW()-A27 > 365), (J27*D27)-(E27*D27)-(2*SUM(H27:I27)), "") | U50: =IF(AND( C27="Buy", ISBLANK(W27), B27<>"DIV", NOW()-A27 > 365), ((E27*D27)+T27), "") | V50: =IF(AND( C27="Buy", ISBLANK(W27), B27<>"DIV", NOW()-A27 > 365), D27, "") | W50: 274.54 | X50: 45183 | Y50: =IF(AND( C27="Buy", W27<>"", AA27<>"", B27<>"DIV"), Z27/SUM(F27:I27), "") | Z50: -7626.71 | AA50: 7735 | AB50: 20 | AC50: =IF(B27="DIV", F27,"")
A51: 44242 | B51: NSE | C51: Sell | D51: 400 | E51: 130.29705 | F51: 52480.04 | H51: 47.76 | I51: 313.42 | J51: =Index!$C$2 | L51: =IF(AND( C28="Buy", ISBLANK(W28), B28<>"DIV"), (1-Index!$F$2*2)*((J28*D28)-(E28*D28)), "") | M51: =IF(AND( C28="Buy", ISBLANK(W28), B28<>"DIV"), ((E28*D28)+L28), "") | N51: =IF(AND( C28="Buy", ISBLANK(W28), B28<>"DIV"), D28, "") | P51: =IF(AND( C28="Buy", ISBLANK(W28), B28<>"DIV", NOW()-A28 < 365), (1-Index!$F$2*2)*((J28*D28)-(E28*D28)), "") | Q51: =IF(AND( C28="Buy", ISBLANK(W28), B28<>"DIV", NOW()-A28 < 365), ((E28*D28)+P28), "") | R51: =IF(AND( C28="Buy", ISBLANK(W28), B28<>"DIV", NOW()-A28 < 365), D28, "") | T51: =IF(AND( C28="Buy", ISBLANK(W28), B28<>"DIV", NOW()-A28 > 365), (J28*D28)-(E28*D28)-(2*SUM(H28:I28)), "") | U51: =IF(AND( C28="Buy", ISBLANK(W28), B28<>"DIV", NOW()-A28 > 365), ((E28*D28)+T28), "") | V51: =IF(AND( C28="Buy", ISBLANK(W28), B28<>"DIV", NOW()-A28 > 365), D28, "") | Y51: =IF(AND( C28="Buy", W28<>"", AA28<>"", B28<>"DIV"), Z28/SUM(F28:I28), "") | AC51: =IF(B28="DIV", F28,"")
A52: 44239 | B52: NSE | C52: Sell | D52: 500 | E52: 132.34026 | F52: 66635.15 | H52: 67.13 | I52: 397.74 | J52: =Index!$C$2 | L52: =IF(AND(#REF!= "Buy", ISBLANK(#REF!),#REF!<> "DIV"), (1-Index!$F$2*2)*((#REF!*#REF!)-(#REF!*#REF!)), "") | M52: =IF(AND(#REF!= "Buy", ISBLANK(#REF!),#REF!<> "DIV"), ((#REF!*#REF!)+#REF!), "") | N52: =IF(AND(#REF!= "Buy", ISBLANK(#REF!),#REF!<> "DIV"),#REF!, "") | P52: =IF(AND(#REF!= "Buy", ISBLANK(#REF!),#REF!<> "DIV", NOW()-#REF! < 365), (1-Index!$F$2*2)*((#REF!*#REF!)-(#REF!*#REF!)), "") | Q52: =IF(AND(#REF!= "Buy", ISBLANK(#REF!),#REF!<> "DIV", NOW()-#REF! < 365), ((#REF!*#REF!)+#REF!), "") | R52: =IF(AND(#REF!= "Buy", ISBLANK(#REF!),#REF!<> "DIV", NOW()-#REF! < 365),#REF!, "") | T52: =IF(AND(#REF!= "Buy", ISBLANK(#REF!),#REF!<> "DIV", NOW()-#REF! > 365), (#REF!*#REF!)-(#REF!*#REF!)-(2*SUM(#REF!)), "") | U52: =IF(AND(#REF!= "Buy", ISBLANK(#REF!),#REF!<> "DIV", NOW()-#REF! > 365), ((#REF!*#REF!)+#REF!), "") | V52: =IF(AND(#REF!= "Buy", ISBLANK(#REF!),#REF!<> "DIV", NOW()-#REF! > 365),#REF!, "") | Y52: #REF! | AC52: =IF(#REF!="DIV",#REF!, "")
...

Sheet Index
B1: Code | C1: NSE:COALINDIA
B2: Current Price | C2: 449.6 | E2: Commission | F2: 0.007
B3: 52 Week High | C3: 461.55
B4: 52 Week Low | C4: 349.25
B6: UnRealised
A8: All | B8: Units | C8: =SUM('Trading History'!$N$4:$N1001) | E8: ST Units | F8: =IFERROR(SUM('Trading History'!$R$4:$R1001), 0) | H8: LT Units | I8: =SUM('Trading History'!$V$4:$V1001) | K8: Units | L8: =SUM('Trading History'!$AB$4:$AB1001)
B9: Avg % | C9: =IFERROR(Index!C10/(Index!C8*Index!$C$2), 0) | E9: ST Avg % | F9: =IFERROR(Index!F10/(Index!F8*Index!$C$2), 0) | H9: LT Avg % | I9: =IFERROR(Index!I10/(Index!I8*Index!$C$2), 0) | K9: Avg % | L9: =IFERROR(Index!L10/(Index!L8*Index!$C$2), 0)
B10: Gain | C10: =SUM('Trading History'!$L$4:$L1001) | E10: ST Gain | F10: =SUM('Trading History'!$P$4:$P1001) | H10: LT Gain | I10: =SUM('Trading History'!$T$4:$T1001) | K10: Gain | L10: =SUM('Trading History'!$Z$4:$Z1001)
B11: Invested | C11: =Index!C12-Index!C10 | E11: ST Invested | F11: =Index!F12-Index!F10 | H11: LT Invested | I11: =Index!I12-Index!I10 | K11: Invested | L11: =Index!L12-Index!L10
B12: Gross | C12: =SUM('Trading History'!$M$4:$M1001) | E12: ST Gross | F12: =SUM('Trading History'!$Q$4:$Q1001) | H12: LT Gross | I12: =SUM('Trading History'!$U$4:$U1001) | K12: Gross | L12: =SUM('Trading History'!$AA$4:$AA1001)
K13: Dividends | L13: =SUMIF('Trading History'!$B19:$B1001,"DIV",'Trading History'!$AC$4:$AC1001)
A15: 0.5 | B15: Units | C15: =SUMIFS('Trading History'!$N$4:$N1001, 'Trading History'!$K$4:$K1001, _xludf.CONCAT(">", $A15)) | E15: ST Units | F15: =IFERROR(SUMIFS('Trading History'!$R$4:$R1001, 'Trading History'!$O$4:$O1001, _xludf.CONCAT(">", $A15)), 0) | H15: LT Units | I15: =SUMIFS('Trading History'!$V$4:$V1001, 'Trading History'!$S$4:$S1001, _xludf.CONCAT(">", $A15)) | K15: Units | L15: =SUMIFS('Trading History'!$AB$4:$AB1001, 'Trading History'!$Y$4:$Y1001, _xludf.CONCAT(">", $A15))
B16: Avg % | C16: =IFERROR(Index!C17/(Index!C15*Index!$C$2), 0) | E16: ST Avg % | F16: =IFERROR(Index!F17/(Index!F15*Index!$C$2), 0) | H16: LT Avg % | I16: =IFERROR(Index!I17/(Index!I15*Index!$C$2), 0) | K16: Avg % | L16: =IFERROR(Index!L17/(Index!L15*Index!$C$2), 0)
B17: Gain | C17: =SUMIFS('Trading History'!$L$4:$L1001, 'Trading History'!$K$4:$K1001, _xludf.CONCAT(">", $A15)) | E17: ST Gain | F17: =SUMIFS('Trading History'!$P$4:$P1001, 'Trading History'!$O$4:$O1001, _xludf.CONCAT(">", $A15)) | H17: LT Gain | I17: =SUMIFS('Trading History'!$T$4:$T1001, 'Trading History'!$S$4:$S1001, _xludf.CONCAT(">", $A15)) | K17: Gain | L17: =SUMIFS('Trading History'!$Z$4:$Z1001, 'Trading History'!$Y$4:$Y1001, _xludf.CONCAT(">", $A15))
B18: Invested | C18: =Index!C19-Index!C17 | E18: ST Invested | F18: =Index!F19-Index!F17 | H18: LT Invested | I18: =Index!I19-Index!I17 | K18: Invested | L18: =Index!L19-Index!L17
B19: Gross | C19: =SUMIFS('Trading History'!$M$4:$M1001, 'Trading History'!$K$4:$K1001, _xludf.CONCAT(">", $A15)) | E19: ST Gross | F19: =SUMIFS('Trading History'!$Q$4:$Q1001, 'Trading History'!$O$4:$O1001, _xludf.CONCAT(">", $A15)) | H19: LT Gross | I19: =SUMIFS('Trading History'!$U$4:$U1001, 'Trading History'!$S$4:$S1001, _xludf.CONCAT(">", $A15)) | K19: Gross | L19: =SUMIFS('Trading History'!$AA$4:$AA1001, 'Trading History'!$Y$4:$Y1001, _xludf.CONCAT(">", $A15))
A22: 0.45 | B22: Units | C22: =SUMIFS('Trading History'!$N$4:$N1001, 'Trading History'!$K$4:$K1001, _xludf.CONCAT(">", $A22)) | E22: ST Units | F22: =IFERROR(SUMIFS('Trading History'!$R$4:$R1001, 'Trading History'!$O$4:$O1001, _xludf.CONCAT(">", $A22)), 0) | H22: LT Units | I22: =SUMIFS('Trading History'!$V$4:$V1001, 'Trading History'!$S$4:$S1001, _xludf.CONCAT(">", $A22)) | K22: Units | L22: =SUMIFS('Trading History'!$AB$4:$AB1001, 'Trading History'!$Y$4:$Y1001, _xludf.CONCAT(">", $A22))
B23: Avg % | C23: =IFERROR(Index!C24/(Index!C22*Index!$C$2), 0) | E23: ST Avg % | F23: =IFERROR(Index!F24/(Index!F22*Index!$C$2), 0) | H23: LT Avg % | I23: =IFERROR(Index!I24/(Index!I22*Index!$C$2), 0) | K23: Avg % | L23: =IFERROR(Index!L24/(Index!L22*Index!$C$2), 0)
B24: Gain | C24: =SUMIFS('Trading History'!$L$4:$L1001, 'Trading History'!$K$4:$K1001, _xludf.CONCAT(">", $A22)) | E24: ST Gain | F24: =SUMIFS('Trading History'!$P$4:$P1001, 'Trading History'!$O$4:$O1001, _xludf.CONCAT(">", $A22)) | H24: LT Gain | I24: =SUMIFS('Trading History'!$T$4:$T1001, 'Trading History'!$S$4:$S1001, _xludf.CONCAT(">", $A22)) | K24: Gain | L24: =SUMIFS('Trading History'!$Z$4:$Z1001, 'Trading History'!$Y$4:$Y1001, _xludf.CONCAT(">", $A22))
B25: Invested | C25: =Index!C26-Index!C24 | E25: ST Invested | F25: =Index!F26-Index!F24 | H25: LT Invested | I25: =Index!I26-Index!I24 | K25: Invested | L25: =Index!L26-Index!L24
B26: Gross | C26: =SUMIFS('Trading History'!$M$4:$M1001, 'Trading History'!$K$4:$K1001, _xludf.CONCAT(">", $A22)) | E26: ST Gross | F26: =SUMIFS('Trading History'!$Q$4:$Q1001, 'Trading History'!$O$4:$O1001, _xludf.CONCAT(">", $A22)) | H26: LT Gross | I26: =SUMIFS('Trading History'!$U$4:$U1001, 'Trading History'!$S$4:$S1001, _xludf.CONCAT(">", $A22)) | K26: Gross | L26: =SUMIFS('Trading History'!$AA$4:$AA1001, 'Trading History'!$Y$4:$Y1001, _xludf.CONCAT(">", $A22))
A29: 0.4 | B29: Units | C29: =SUMIFS('Trading History'!$N$4:$N1001, 'Trading History'!$K$4:$K1001, _xludf.CONCAT(">", $A29)) | E29: ST Units | F29: =IFERROR(SUMIFS('Trading History'!$R$4:$R1001, 'Trading History'!$O$4:$O1001, _xludf.CONCAT(">", $A29)), 0) | H29: LT Units | I29: =SUMIFS('Trading History'!$V$4:$V1001, 'Trading History'!$S$4:$S1001, _xludf.CONCAT(">", $A29)) | K29: Units | L29: =SUMIFS('Trading History'!$AB$4:$AB1001, 'Trading History'!$Y$4:$Y1001, _xludf.CONCAT(">", $A29))
B30: Avg % | C30: =IFERROR(Index!C31/(Index!C29*Index!$C$2), 0) | E30: ST Avg % | F30: =IFERROR(Index!F31/(Index!F29*Index!$C$2), 0) | H30: LT Avg % | I30: =IFERROR(Index!I31/(Index!I29*Index!$C$2), 0) | K30: Avg % | L30: =IFERROR(Index!L31/(Index!L29*Index!$C$2), 0)
B31: Gain | C31: =SUMIFS('Trading History'!$L$4:$L1001, 'Trading History'!$K$4:$K1001, _xludf.CONCAT(">", $A29)) | E31: ST Gain | F31: =SUMIFS('Trading History'!$P$4:$P1001, 'Trading History'!$O$4:$O1001, _xludf.CONCAT(">", $A29)) | H31: LT Gain | I31: =SUMIFS('Trading History'!$T$4:$T1001, 'Trading History'!$S$4:$S1001, _xludf.CONCAT(">", $A29)) | K31: Gain | L31: =SUMIFS('Trading History'!$Z$4:$Z1001, 'Trading History'!$Y$4:$Y1001, _xludf.CONCAT(">", $A29))
B32: Invested | C32: =Index!C33-Index!C31 | E32: ST Invested | F32: =Index!F33-Index!F31 | H32: LT Invested | I32: =Index!I33-Index!I31 | K32: Invested | L32: =Index!L33-Index!L31
B33: Gross | C33: =SUMIFS('Trading History'!$M$4:$M1001, 'Trading History'!$K$4:$K1001, _xludf.CONCAT(">", $A29)) | E33: ST Gross | F33: =SUMIFS('Trading History'!$Q$4:$Q1001, 'Trading History'!$O$4:$O1001, _xludf.CONCAT(">", $A29)) | H33: LT Gross | I33: =SUMIFS('Trading History'!$U$4:$U1001, 'Trading History'!$S$4:$S1001, _xludf.CONCAT(">", $A29)) | K33: Gross | L33: =SUMIFS('Trading History'!$AA$4:$AA1001, 'Trading History'!$Y$4:$Y1001, _xludf.CONCAT(">", $A29))
A36: 0.35 | B36: Units | C36: =SUMIFS('Trading History'!$N$4:$N1001, 'Trading History'!$K$4:$K1001, _xludf.CONCAT(">", $A36)) | E36: ST Units | F36: =IFERROR(SUMIFS('Trading History'!$R$4:$R1001, 'Trading History'!$O$4:$O1001, _xludf.CONCAT(">", $A36)), 0) | H36: LT Units | I36: =SUMIFS('Trading History'!$V$4:$V1001, 'Trading History'!$S$4:$S1001, _xludf.CONCAT(">", $A36)) | K36: Units | L36: =SUMIFS('Trading History'!$AB$4:$AB1001, 'Trading History'!$Y$4:$Y1001, _xludf.CONCAT(">", $A36))
B37: Avg % | C37: =IFERROR(Index!C38/(Index!C36*Index!$C$2), 0) | E37: ST Avg % | F37: =IFERROR(Index!F38/(Index!F36*Index!$C$2), 0) | H37: LT Avg % | I37: =IFERROR(Index!I38/(Index!I36*Index!$C$2), 0) | K37: Avg % | L37: =IFERROR(Index!L38/(Index!L36*Index!$C$2), 0)
B38: Gain | C38: =SUMIFS('Trading History'!$L$4:$L1001, 'Trading History'!$K$4:$K1001, _xludf.CONCAT(">", $A36)) | E38: ST Gain | F38: =SUMIFS('Trading History'!$P$4:$P1001, 'Trading History'!$O$4:$O1001, _xludf.CONCAT(">", $A36)) | H38: LT Gain | I38: =SUMIFS('Trading History'!$T$4:$T1001, 'Trading History'!$S$4:$S1001, _xludf.CONCAT(">", $A36)) | K38: Gain | L38: =SUMIFS('Trading History'!$Z$4:$Z1001, 'Trading History'!$Y$4:$Y1001, _xludf.CONCAT(">", $A36))
B39: Invested | C39: =Index!C40-Index!C38 | E39: ST Invested | F39: =Index!F40-Index!F38 | H39: LT Invested | I39: =Index!I40-Index!I38 | K39: Invested | L39: =Index!L40-Index!L38
B40: Gross | C40: =SUMIFS('Trading History'!$M$4:$M1001, 'Trading History'!$K$4:$K1001, _xludf.CONCAT(">", $A36)) | E40: ST Gross | F40: =SUMIFS('Trading History'!$Q$4:$Q1001, 'Trading History'!$O$4:$O1001, _xludf.CONCAT(">", $A36)) | H40: LT Gross | I40: =SUMIFS('Trading History'!$U$4:$U1001, 'Trading History'!$S$4:$S1001, _xludf.CONCAT(">", $A36)) | K40: Gross | L40: =SUMIFS('Trading History'!$AA$4:$AA1001, 'Trading History'!$Y$4:$Y1001, _xludf.CONCAT(">", $A36))
A43: 0.3 | B43: Units | C43: =SUMIFS('Trading History'!$N$4:$N1001, 'Trading History'!$K$4:$K1001, _xludf.CONCAT(">", $A43)) | E43: ST Units | F43: =IFERROR(SUMIFS('Trading History'!$R$4:$R1001, 'Trading History'!$O$4:$O1001, _xludf.CONCAT(">", $A43)), 0) | H43: LT Units | I43: =SUMIFS('Trading History'!$V$4:$V1001, 'Trading History'!$S$4:$S1001, _xludf.CONCAT(">", $A43)) | K43: Units | L43: =SUMIFS('Trading History'!$AB$4:$AB1001, 'Trading History'!$Y$4:$Y1001, _xludf.CONCAT(">", $A43))
B44: Avg % | C44: =IFERROR(Index!C45/(Index!C43*Index!$C$2), 0) | E44: ST Avg % | F44: =IFERROR(Index!F45/(Index!F43*Index!$C$2), 0) | H44: LT Avg % | I44: =IFERROR(Index!I45/(Index!I43*Index!$C$2), 0) | K44: Avg % | L44: =IFERROR(Index!L45/(Index!L43*Index!$C$2), 0)
B45: Gain | C45: =SUMIFS('Trading History'!$L$4:$L1001, 'Trading History'!$K$4:$K1001, _xludf.CONCAT(">", $A43)) | E45: ST Gain | F45: =SUMIFS('Trading History'!$P$4:$P1001, 'Trading History'!$O$4:$O1001, _xludf.CONCAT(">", $A43)) | H45: LT Gain | I45: =SUMIFS('Trading History'!$T$4:$T1001, 'Trading History'!$S$4:$S1001, _xludf.CONCAT(">", $A43)) | K45: Gain | L45: =SUMIFS('Trading History'!$Z$4:$Z1001, 'Trading History'!$Y$4:$Y1001, _xludf.CONCAT(">", $A43))
B46: Invested | C46: =Index!C47-Index!C45 | E46: ST Invested | F46: =Index!F47-Index!F45 | H46: LT Invested | I46: =Index!I47-Index!I45 | K46: Invested | L46: =Index!L47-Index!L45
B47: Gross | C47: =SUMIFS('Trading History'!$M$4:$M1001, 'Trading History'!$K$4:$K1001, _xludf.CONCAT(">", $A43)) | E47: ST Gross | F47: =SUMIFS('Trading History'!$Q$4:$Q1001, 'Trading History'!$O$4:$O1001, _xludf.CONCAT(">", $A43)) | H47: LT Gross | I47: =SUMIFS('Trading History'!$U$4:$U1001, 'Trading History'!$S$4:$S1001, _xludf.CONCAT(">", $A43)) | K47: Gross | L47: =SUMIFS('Trading History'!$AA$4:$AA1001, 'Trading History'!$Y$4:$Y1001, _xludf.CONCAT(">", $A43))
A50: 0.25 | B50: Units | C50: =SUMIFS('Trading History'!$N$4:$N1001, 'Trading History'!$K$4:$K1001, _xludf.CONCAT(">", $A50)) | E50: ST Units | F50: =IFERROR(SUMIFS('Trading History'!$R$4:$R1001, 'Trading History'!$O$4:$O1001, _xludf.CONCAT(">", $A50)), 0) | H50: LT Units | I50: =SUMIFS('Trading History'!$V$4:$V1001, 'Trading History'!$S$4:$S1001, _xludf.CONCAT(">", $A50)) | K50: Units | L50: =SUMIFS('Trading History'!$AB$4:$AB1001, 'Trading History'!$Y$4:$Y1001, _xludf.CONCAT(">", $A50))
B51: Avg % | C51: =IFERROR(Index!C52/(Index!C50*Index!$C$2), 0) | E51: ST Avg % | F51: =IFERROR(Index!F52/(Index!F50*Index!$C$2), 0) | H51: LT Avg % | I51: =IFERROR(Index!I52/(Index!I50*Index!$C$2), 0) | K51: Avg % | L51: =IFERROR(Index!L52/(Index!L50*Index!$C$2), 0)
B52: Gain | C52: =SUMIFS('Trading History'!$L$4:$L1001, 'Trading History'!$K$4:$K1001, _xludf.CONCAT(">", $A50)) | E52: ST Gain | F52: =SUMIFS('Trading History'!$P$4:$P1001, 'Trading History'!$O$4:$O1001, _xludf.CONCAT(">", $A50)) | H52: LT Gain | I52: =SUMIFS('Trading History'!$T$4:$T1001, 'Trading History'!$S$4:$S1001, _xludf.CONCAT(">", $A50)) | K52: Gain | L52: =SUMIFS('Trading History'!$Z$4:$Z1001, 'Trading History'!$Y$4:$Y1001, _xludf.CONCAT(">", $A50))
B53: Invested | C53: =Index!C54-Index!C52 | E53: ST Invested | F53: =Index!F54-Index!F52 | H53: LT Invested | I53: =Index!I54-Index!I52 | K53: Invested | L53: =Index!L54-Index!L52
...
