Workbook

Sheet Trading History
K2: UnRealised | W2: Realised
K3: Total | O3: Short Term | S3: Long Term
A4: DATE | B4: EXCH | C4: ACTION | D4: QTY | E4: PRICE | F4: COST | G4: REMARKS | H4: STT | I4: ADD CHRG | J4: Current Price | K4: Gain % | L4: Gain | M4: Gross | N4: Units | O4: Gain % | P4: Gain | Q4: Gross | R4: Units | S4: Gain % | T4: Gain | U4: Gross | V4: Units | W4: Price | X4: Date | Y4: Gain % | Z4: Gain | AA4: Gross | AB4: Units | AC4: DIV | AD4: Broker
A5: 46059 | B5: NSE | C5: Buy | D5: 1 | E5: 4077.8 | F5: 4098.19 | G5: CN#252611604850 | I5: 20.39 | J5: =Index!$C$2
A6: 46063 | B6: NSE | C6: Buy | D6: 1 | E6: 4175.9 | F6: 4205.49 | G6: CN#252611730667 | H6: 4.17 | I6: 25.42 | J6: =Index!$C$2
A7: 46049 | B7: NSE | C7: Buy | D7: 2 | E7: 3754.3 | F7: 7561.81 | G7: ~ | H7: 7.49 | I7: 45.72
A8: 46038 | B8: NSE | C8: Buy | D8: 1 | E8: 3951.8 | F8: 3979.79 | G8: ~ | H8: 3.95 | I8: 24.04
A9: 46034 | B9: NSE | C9: Buy | D9: 2 | E9: 4016.9 | F9: 8090.73 | G9: ~ | H9: 8.05 | I9: 48.88
A10: 46020 | B10: NSE | C10: Buy | D10: 1 | E10: 4246.3 | F10: 4276.43 | G10: ~ | H10: 4.27 | I10: 25.86
A11: 46017 | B11: NSE | C11: Buy | D11: 1 | E11: 4296.1 | F11: 4326.54 | G11: ~ | H11: 4.31 | I11: 26.13
A12: 46015 | B12: NSE | C12: Buy | D12: 1 | E12: 4204 | F12: 4233.77 | G12: ~ | H12: 4.18 | I12: 25.59
A13: 46014 | B13: NSE | C13: Buy | D13: 1 | E13: 4229 | F13: 4258.93 | G13: ~ | H13: 4.21 | I13: 25.72
A14: 46009 | B14: BSE | C14: Buy | D14: 1 | E14: 4008.4 | F14: 4036.82 | G14: ~ | H14: 4.02 | I14: 24.4
A15: 46007 | B15: NSE | C15: Buy | D15: 2 | E15: 4109.8 | F15: 8277.87 | G15: ~ | H15: 8.2 | I15: 50.07
A16: 45978 | B16: NSE | C16: Buy | D16: 1 | E16: 4404.5 | F16: 4435.71 | G16: ~ | H16: 4.42 | I16: 26.79
A17: 45975 | B17: NSE | C17: Buy | D17: 1 | E17: 4342.1 | F17: 4372.84 | G17: ~ | H17: 4.35 | I17: 26.39
A18: 45974 | B18: NSE | C18: Buy | D18: 1 | E18: 4374 | F18: 4404.99 | G18: ~ | H18: 4.35 | I18: 26.64
... A27: 45903 | B27: BSE | C27: Buy | D27: 2 | E27: 5386.5 | F27: 10849.47 | G27: ~ | H27: 10.79 | I27: 65.68
A28: 45950 | B28: BSE | C28: Buy | D28: 2 | E28: 4836.11 | F28: =D5*E5 | G28: ~ | J28: =Index!$C$2 | K28: =IF(AND( C5="Buy", ISBLANK(W5), B5<>"DIV"), L5/sum(F5:I5), "") | L28: =IF(AND( C5="Buy", ISBLANK(W5), B5<>"DIV"), (1-Index!$F$2*2)*((J5*D5)-(E5*D5)), "") | M28: =IF(AND( C5="Buy", ISBLANK(W5), B5<>"DIV"), ((E5*D5)+L5), "") | N28: =IF(AND( C5="Buy", ISBLANK(W5), B5<>"DIV"), D5, "") | O28: =IF(AND( C5="Buy", ISBLANK(W5), B5<>"DIV", NOW()-A5 < 365), P5/sum(F5:I5), "") | P28: =IF(AND( C5="Buy", ISBLANK(W5), B5<>"DIV", NOW()-A5 < 365), (1-Index!$F$2*2)*((J5*D5)-(E5*D5)), "") | Q28: =IF(AND( C5="Buy", ISBLANK(W5), B5<>"DIV", NOW()-A5 < 365), ((E5*D5)+P5), "") | R28: =IF(AND( C5="Buy", ISBLANK(W5), B5<>"DIV", NOW()-A5 < 365), D5, "") | S28: =IF(AND( C5="Buy", ISBLANK(W5), B5<>"DIV", NOW()-A5 > 365), T5/sum(F5:I5), "") | T28: =IF(AND( C5="Buy", ISBLANK(W5), B5<>"DIV", NOW()-A5 > 365), (1-Index!$F$2*2)*((J5*D5)-(E5*D5)), "") | U28: =IF(AND( C5="Buy", ISBLANK(W5), B5<>"DIV", NOW()-A5 > 365), ((E5*D5)+T5), "") | V28: =IF(AND( C5="Buy", ISBLANK(W5), B5<>"DIV", NOW()-A5 > 365), D5, "") | Y28: =IF(AND( C5="Buy", W5<>"", AA5<>"", B5<>"DIV"), Z5/sum(F5:I5), "") | AC28: =if(B5="DIV", F5,"")
A29: 45947 | B29: BSE | C29: Buy | D29: 2 | E29: 4844.88 | F29: =D6*E6 | G29: ~ | J29: =Index!$C$2 | K29: =IF(AND( C6="Buy", ISBLANK(W6), B6<>"DIV"), L6/sum(F6:I6), "") | L29: =IF(AND( C6="Buy", ISBLANK(W6), B6<>"DIV"), (1-Index!$F$2*2)*((J6*D6)-(E6*D6)), "") | M29: =IF(AND( C6="Buy", ISBLANK(W6), B6<>"DIV"), ((E6*D6)+L6), "") | N29: =IF(AND( C6="Buy", ISBLANK(W6), B6<>"DIV"), D6, "") | O29: =IF(AND( C6="Buy", ISBLANK(W6), B6<>"DIV", NOW()-A6 < 365), P6/sum(F6:I6), "") | P29: =IF(AND( C6="Buy", ISBLANK(W6), B6<>"DIV", NOW()-A6 < 365), (1-Index!$F$2*2)*((J6*D6)-(E6*D6)), "") | Q29: =IF(AND( C6="Buy", ISBLANK(W6), B6<>"DIV", NOW()-A6 < 365), ((E6*D6)+P6), "") | R29: =IF(AND( C6="Buy", ISBLANK(W6), B6<>"DIV", NOW()-A6 < 365), D6, "") | S29: =IF(AND( C6="Buy", ISBLANK(W6), B6<>"DIV", NOW()-A6 > 365), T6/sum(F6:I6), "") | T29: =IF(AND( C6="Buy", ISBLANK(W6), B6<>"DIV", NOW()-A6 > 365), (1-Index!$F$2*2)*((J6*D6)-(E6*D6)), "") | U29: =IF(AND( C6="Buy", ISBLANK(W6), B6<>"DIV", NOW()-A6 > 365), ((E6*D6)+T6), "") | V29: =IF(AND( C6="Buy", ISBLANK(W6), B6<>"DIV", NOW()-A6 > 365), D6, "") | Y29: =IF(AND( C6="Buy", W6<>"", AA6<>"", B6<>"DIV"), Z6/sum(F6:I6), "") | AC29: =if(B6="DIV", F6,"")
A30: 45903 | B30: BSE | C30: Buy | D30: 2 | E30: 5424.73 | F30: 10849.47 | G30: ~ | H30: 10.79 | I30: 65.68 | J30: =Index!$C$2 | K30: =IF(AND( C7="Buy", ISBLANK(W7), B7<>"DIV"), L7/sum(F7:I7), "") | L30: =IF(AND( C7="Buy", ISBLANK(W7), B7<>"DIV"), (1-Index!$F$2*2)*((J7*D7)-(E7*D7)), "") | M30: =IF(AND( C7="Buy", ISBLANK(W7), B7<>"DIV"), ((E7*D7)+L7), "") | N30: =IF(AND( C7="Buy", ISBLANK(W7), B7<>"DIV"), D7, "") | O30: =IF(AND( C7="Buy", ISBLANK(W7), B7<>"DIV", NOW()-A7 < 365), P7/sum(F7:I7), "") | P30: =IF(AND( C7="Buy", ISBLANK(W7), B7<>"DIV", NOW()-A7 < 365), (1-Index!$F$2*2)*((J7*D7)-(E7*D7)), "") | Q30: =IF(AND( C7="Buy", ISBLANK(W7), B7<>"DIV", NOW()-A7 < 365), ((E7*D7)+P7), "") | R30: =IF(AND( C7="Buy", ISBLANK(W7), B7<>"DIV", NOW()-A7 < 365), D7, "") | S30: =IF(AND( C7="Buy", ISBLANK(W7), B7<>"DIV", NOW()-A7 > 365), T7/sum(F7:I7), "") | T30: =IF(AND( C7="Buy", ISBLANK(W7), B7<>"DIV", NOW()-A7 > 365), (1-Index!$F$2*2)*((J7*D7)-(E7*D7)), "") | U30: =IF(AND( C7="Buy", ISBLANK(W7), B7<>"DIV", NOW()-A7 > 365), ((E7*D7)+T7), "") | V30: =IF(AND( C7="Buy", ISBLANK(W7), B7<>"DIV", NOW()-A7 > 365), D7, "") | Y30: =IF(AND( C7="Buy", W7<>"", AA7<>"", B7<>"DIV"), Z7/sum(F7:I7), "") | AC30: =if(B7="DIV", F7,"")
A31: 45855 | B31: NSE | C31: Buy | D31: 2 | E31: 5478.06 | F31: 10956.12 | G31: ~ | H31: 10.88 | I31: 66.24 | J31: =Index!$C$2 | K31: =IF(AND( C8="Buy", ISBLANK(W8), B8<>"DIV"), L8/sum(F8:I8), "") | L31: =IF(AND( C8="Buy", ISBLANK(W8), B8<>"DIV"), (1-Index!$F$2*2)*((J8*D8)-(E8*D8)), "") | M31: =IF(AND( C8="Buy", ISBLANK(W8), B8<>"DIV"), ((E8*D8)+L8), "") | N31: =IF(AND( C8="Buy", ISBLANK(W8), B8<>"DIV"), D8, "") | O31: =IF(AND( C8="Buy", ISBLANK(W8), B8<>"DIV", NOW()-A8 < 365), P8/sum(F8:I8), "") | P31: =IF(AND( C8="Buy", ISBLANK(W8), B8<>"DIV", NOW()-A8 < 365), (1-Index!$F$2*2)*((J8*D8)-(E8*D8)), "") | Q31: =IF(AND( C8="Buy", ISBLANK(W8), B8<>"DIV", NOW()-A8 < 365), ((E8*D8)+P8), "") | R31: =IF(AND( C8="Buy", ISBLANK(W8), B8<>"DIV", NOW()-A8 < 365), D8, "") | S31: =IF(AND( C8="Buy", ISBLANK(W8), B8<>"DIV", NOW()-A8 > 365), T8/sum(F8:I8), "") | T31: =IF(AND( C8="Buy", ISBLANK(W8), B8<>"DIV", NOW()-A8 > 365), (1-Index!$F$2*2)*((J8*D8)-(E8*D8)), "") | U31: =IF(AND( C8="Buy", ISBLANK(W8), B8<>"DIV", NOW()-A8 > 365), ((E8*D8)+T8), "") | V31: =IF(AND( C8="Buy", ISBLANK(W8), B8<>"DIV", NOW()-A8 > 365), D8, "") | Y31: =IF(AND( C8="Buy", W8<>"", AA8<>"", B8<>"DIV"), Z8/sum(F8:I8), "") | AC31: =if(B8="DIV", F8,"")
A32: 45820 | B32: DIV | C32: Buy | D32: 3 | E32: 5 | F32: 15 | G32: Annual-Dividend of Rs.5.0000/- per share on Ex-Date: 12-JUN-2025 | H32: 0 | I32: 0 | J32: =Index!$C$2 | K32: =IF(AND( C9="Buy", ISBLANK(W9), B9<>"DIV"), L9/sum(F9:I9), "") | L32: =IF(AND( C9="Buy", ISBLANK(W9), B9<>"DIV"), (1-Index!$F$2*2)*((J9*D9)-(E9*D9)), "") | M32: =IF(AND( C9="Buy", ISBLANK(W9), B9<>"DIV"), ((E9*D9)+L9), "") | N32: =IF(AND( C9="Buy", ISBLANK(W9), B9<>"DIV"), D9, "") | O32: =IF(AND( C9="Buy", ISBLANK(W9), B9<>"DIV", NOW()-A9 < 365), P9/sum(F9:I9), "") | P32: =IF(AND( C9="Buy", ISBLANK(W9), B9<>"DIV", NOW()-A9 < 365), (1-Index!$F$2*2)*((J9*D9)-(E9*D9)), "") | Q32: =IF(AND( C9="Buy", ISBLANK(W9), B9<>"DIV", NOW()-A9 < 365), ((E9*D9)+P9), "") | R32: =IF(AND( C9="Buy", ISBLANK(W9), B9<>"DIV", NOW()-A9 < 365), D9, "") | S32: =IF(AND( C9="Buy", ISBLANK(W9), B9<>"DIV", NOW()-A9 > 365), T9/sum(F9:I9), "") | T32: =IF(AND( C9="Buy", ISBLANK(W9), B9<>"DIV", NOW()-A9 > 365), (1-Index!$F$2*2)*((J9*D9)-(E9*D9)), "") | U32: =IF(AND( C9="Buy", ISBLANK(W9), B9<>"DIV", NOW()-A9 > 365), ((E9*D9)+T9), "") | V32: =IF(AND( C9="Buy", ISBLANK(W9), B9<>"DIV", NOW()-A9 > 365), D9, "") | Y32: =IF(AND( C9="Buy", W9<>"", AA9<>"", B9<>"DIV"), Z9/sum(F9:I9), "") | AC32: =if(B9="DIV", F9,"")
A33: 45812 | B33: NSE | C33: Buy | D33: 1 | E33: 5582.82 | F33: 5582.82 | G33: ~ | H33: 5.57 | I33: 33.75 | J33: =Index!$C$2 | K33: =IF(AND( C10="Buy", ISBLANK(W10), B10<>"DIV"), L10/sum(F10:I10), "") | L33: =IF(AND( C10="Buy", ISBLANK(W10), B10<>"DIV"), (1-Index!$F$2*2)*((J10*D10)-(E10*D10)), "") | M33: =IF(AND( C10="Buy", ISBLANK(W10), B10<>"DIV"), ((E10*D10)+L10), "") | N33: =IF(AND( C10="Buy", ISBLANK(W10), B10<>"DIV"), D10, "") | O33: =IF(AND( C10="Buy", ISBLANK(W10), B10<>"DIV", NOW()-A10 < 365), P10/sum(F10:I10), "") | P33: =IF(AND( C10="Buy", ISBLANK(W10), B10<>"DIV", NOW()-A10 < 365), (1-Index!$F$2*2)*((J10*D10)-(E10*D10)), "") | Q33: =IF(AND( C10="Buy", ISBLANK(W10), B10<>"DIV", NOW()-A10 < 365), ((E10*D10)+P10), "") | R33: =IF(AND( C10="Buy", ISBLANK(W10), B10<>"DIV", NOW()-A10 < 365), D10, "") | S33: =IF(AND( C10="Buy", ISBLANK(W10), B10<>"DIV", NOW()-A10 > 365), T10/sum(F10:I10), "") | T33: =IF(AND( C10="Buy", ISBLANK(W10), B10<>"DIV", NOW()-A10 > 365), (1-Index!$F$2*2)*((J10*D10)-(E10*D10)), "") | U33: =IF(AND( C10="Buy", ISBLANK(W10), B10<>"DIV", NOW()-A10 > 365), ((E10*D10)+T10), "") | V33: =IF(AND( C10="Buy", ISBLANK(W10), B10<>"DIV", NOW()-A10 > 365), D10, "") | Y33: =IF(AND( C10="Buy", W10<>"", AA10<>"", B10<>"DIV"), Z10/sum(F10:I10), "") | AC33: =if(B10="DIV", F10,"")
A34: 45811 | B34: NSE | C34: Buy | D34: 1 | E34: 5655.83 | F34: 5655.83 | G34: ~ | H34: 5.62 | I34: 34.21 | J34: =Index!$C$2 | K34: =IF(AND( C11="Buy", ISBLANK(W11), B11<>"DIV"), L11/sum(F11:I11), "") | L34: =IF(AND( C11="Buy", ISBLANK(W11), B11<>"DIV"), (1-Index!$F$2*2)*((J11*D11)-(E11*D11)), "") | M34: =IF(AND( C11="Buy", ISBLANK(W11), B11<>"DIV"), ((E11*D11)+L11), "") | N34: =IF(AND( C11="Buy", ISBLANK(W11), B11<>"DIV"), D11, "") | O34: =IF(AND( C11="Buy", ISBLANK(W11), B11<>"DIV", NOW()-A11 < 365), P11/sum(F11:I11), "") | P34: =IF(AND( C11="Buy", ISBLANK(W11), B11<>"DIV", NOW()-A11 < 365), (1-Index!$F$2*2)*((J11*D11)-(E11*D11)), "") | Q34: =IF(AND( C11="Buy", ISBLANK(W11), B11<>"DIV", NOW()-A11 < 365), ((E11*D11)+P11), "") | R34: =IF(AND( C11="Buy", ISBLANK(W11), B11<>"DIV", NOW()-A11 < 365), D11, "") | S34: =IF(AND( C11="Buy", ISBLANK(W11), B11<>"DIV", NOW()-A11 > 365), T11/sum(F11:I11), "") | T34: =IF(AND( C11="Buy", ISBLANK(W11), B11<>"DIV", NOW()-A11 > 365), (1-Index!$F$2*2)*((J11*D11)-(E11*D11)), "") | U34: =IF(AND( C11="Buy", ISBLANK(W11), B11<>"DIV", NOW()-A11 > 365), ((E11*D11)+T11), "") | V34: =IF(AND( C11="Buy", ISBLANK(W11), B11<>"DIV", NOW()-A11 > 365), D11, "") | Y34: =IF(AND( C11="Buy", W11<>"", AA11<>"", B11<>"DIV"), Z11/sum(F11:I11), "") | AC34: =if(B11="DIV", F11,"")
A35: 45811 | B35: NSE | C35: Buy | D35: 1 | E35: 5655.83 | F35: 5655.83 | G35: ~ | H35: 5.62 | I35: 34.21 | J35: =Index!$C$2 | L35: =IF(AND( C12="Buy", ISBLANK(W12), B12<>"DIV"), (1-Index!$F$2*2)*((J12*D12)-(E12*D12)), "") | M35: =IF(AND( C12="Buy", ISBLANK(W12), B12<>"DIV"), ((E12*D12)+L12), "") | N35: =IF(AND( C12="Buy", ISBLANK(W12), B12<>"DIV"), D12, "") | P35: =IF(AND( C12="Buy", ISBLANK(W12), B12<>"DIV", NOW()-A12 < 365), (1-Index!$F$2*2)*((J12*D12)-(E12*D12)), "") | Q35: =IF(AND( C12="Buy", ISBLANK(W12), B12<>"DIV", NOW()-A12 < 365), ((E12*D12)+P12), "") | R35: =IF(AND( C12="Buy", ISBLANK(W12), B12<>"DIV", NOW()-A12 < 365), D12, "") | S35: =IF(AND( C12="Buy", ISBLANK(W12), B12<>"DIV", NOW()-A12 > 365), T12/sum(F12:I12), "") | T35: =IF(AND( C12="Buy", ISBLANK(W12), B12<>"DIV", NOW()-A12 > 365), (1-Index!$F$2*2)*((J12*D12)-(E12*D12)), "") | U35: =IF(AND( C12="Buy", ISBLANK(W12), B12<>"DIV", NOW()-A12 > 365), ((E12*D12)+T12), "") | V35: =IF(AND( C12="Buy", ISBLANK(W12), B12<>"DIV", NOW()-A12 > 365), D12, "") | Y35: =IF(AND( C12="Buy", W12<>"", AA12<>"", B12<>"DIV"), Z12/sum(F12:I12), "") | AC35: =if(B12="DIV", F12,"")

Sheet Index
B1: Code | C1: NSE:TRENT
B2: Current Price | C2: 4113.8 | E2: Commission | F2: 0.007
B3: 52 Week High | C3: =IFERROR(__xludf.DUMMYFUNCTION("GOOGLEFINANCE($C$1, ""high52"")"),6261.0)
B4: 52 Week Low | C4: =IFERROR(__xludf.DUMMYFUNCTION("GOOGLEFINANCE($C$1, ""low52"")"),3645.0)
B6: UnRealised
A8: All | B8: Units | C8: =SUM('Trading History'!$N$4:$N1007) | E8: ST Units | F8: =IFERROR(SUM('Trading History'!$R$4:$R1007), 0) | H8: LT Units | I8: =SUM('Trading History'!$V$4:$V1007) | K8: Units | L8: =SUM('Trading History'!$AB$4:$AB1007)
B9: Avg % | C9: =IFERROR(Index!C10/(Index!C8*Index!$C$2), 0) | E9: ST Avg % | F9: =IFERROR(Index!F10/(Index!F8*Index!$C$2), 0) | H9: LT Avg % | I9: =IFERROR(Index!I10/(Index!I8*Index!$C$2), 0) | K9: Avg % | L9: =IFERROR(Index!L10/(Index!L8*Index!$C$2), 0)
B10: Gain | C10: =SUM('Trading History'!$L$4:$L1007) | E10: ST Gain | F10: =SUM('Trading History'!$P$4:$P1007) | H10: LT Gain | I10: =SUM('Trading History'!$T$4:$T1007) | K10: Gain | L10: =SUM('Trading History'!$Z$4:$Z1007)
B11: Invested | C11: =Index!C12-Index!C10 | E11: ST Invested | F11: =Index!F12-Index!F10 | H11: LT Invested | I11: =Index!I12-Index!I10 | K11: Invested | L11: =Index!L12-Index!L10
B12: Gross | C12: =SUM('Trading History'!$M$4:$M1007) | E12: ST Gross | F12: =SUM('Trading History'!$Q$4:$Q1007) | H12: LT Gross | I12: =SUM('Trading History'!$U$4:$U1007) | K12: Gross | L12: =SUM('Trading History'!$AA$4:$AA1007)
K13: Dividends | L13: =SUMIF('Trading History'!$B16:$B1007,"DIV",'Trading History'!$AC$4:$AC1007)
A15: 0.5 | B15: Units | C15: =SUMIFS('Trading History'!$N$4:$N1007, 'Trading History'!$K$4:$K1007, CONCAT(">", $A15)) | E15: ST Units | F15: =IFERROR(SUMIFS('Trading History'!$R$4:$R1007, 'Trading History'!$O$4:$O1007, CONCAT(">", $A15)), 0) | H15: LT Units | I15: =SUMIFS('Trading History'!$V$4:$V1007, 'Trading History'!$S$4:$S1007, CONCAT(">", $A15)) | K15: Units | L15: =SUMIFS('Trading History'!$AB$4:$AB1007, 'Trading History'!$Y$4:$Y1007, CONCAT(">", $A15))
B16: Avg % | C16: =IFERROR(Index!C17/(Index!C15*Index!$C$2), 0) | E16: ST Avg % | F16: =IFERROR(Index!F17/(Index!F15*Index!$C$2), 0) | H16: LT Avg % | I16: =IFERROR(Index!I17/(Index!I15*Index!$C$2), 0) | K16: Avg % | L16: =IFERROR(Index!L17/(Index!L15*Index!$C$2), 0)
B17: Gain | C17: =SUMIFS('Trading History'!$L$4:$L1007, 'Trading History'!$K$4:$K1007, CONCAT(">", $A15)) | E17: ST Gain | F17: =SUMIFS('Trading History'!$P$4:$P1007, 'Trading History'!$O$4:$O1007, CONCAT(">", $A15)) | H17: LT Gain | I17: =SUMIFS('Trading History'!$T$4:$T1007, 'Trading History'!$S$4:$S1007, CONCAT(">", $A15)) | K17: Gain | L17: =SUMIFS('Trading History'!$Z$4:$Z1007, 'Trading History'!$Y$4:$Y1007, CONCAT(">", $A15))
B18: Invested | C18: =Index!C19-Index!C17 | E18: ST Invested | F18: =Index!F19-Index!F17 | H18: LT Invested | I18: =Index!I19-Index!I17 | K18: Invested | L18: =Index!L19-Index!L17
B19: Gross | C19: =SUMIFS('Trading History'!$M$4:$M1007, 'Trading History'!$K$4:$K1007, CONCAT(">", $A15)) | E19: ST Gross | F19: =SUMIFS('Trading History'!$Q$4:$Q1007, 'Trading History'!$O$4:$O1007, CONCAT(">", $A15)) | H19: LT Gross | I19: =SUMIFS('Trading History'!$U$4:$U1007, 'Trading History'!$S$4:$S1007, CONCAT(">", $A15)) | K19: Gross | L19: =SUMIFS('Trading History'!$AA$4:$AA1007, 'Trading History'!$Y$4:$Y1007, CONCAT(">", $A15))
A22: 0.45 | B22: Units | C22: =SUMIFS('Trading History'!$N$4:$N1007, 'Trading History'!$K$4:$K1007, CONCAT(">", $A22)) | E22: ST Units | F22: =IFERROR(SUMIFS('Trading History'!$R$4:$R1007, 'Trading History'!$O$4:$O1007, CONCAT(">", $A22)), 0) | H22: LT Units | I22: =SUMIFS('Trading History'!$V$4:$V1007, 'Trading History'!$S$4:$S1007, CONCAT(">", $A22)) | K22: Units | L22: =SUMIFS('Trading History'!$AB$4:$AB1007, 'Trading History'!$Y$4:$Y1007, CONCAT(">", $A22))
B23: Avg % | C23: =IFERROR(Index!C24/(Index!C22*Index!$C$2), 0) | E23: ST Avg % | F23: =IFERROR(Index!F24/(Index!F22*Index!$C$2), 0) | H23: LT Avg % | I23: =IFERROR(Index!I24/(Index!I22*Index!$C$2), 0) | K23: Avg % | L23: =IFERROR(Index!L24/(Index!L22*Index!$C$2), 0)
B24: Gain | C24: =SUMIFS('Trading History'!$L$4:$L1007, 'Trading History'!$K$4:$K1007, CONCAT(">", $A22)) | E24: ST Gain | F24: =SUMIFS('Trading History'!$P$4:$P1007, 'Trading History'!$O$4:$O1007, CONCAT(">", $A22)) | H24: LT Gain | I24: =SUMIFS('Trading History'!$T$4:$T1007, 'Trading History'!$S$4:$S1007, CONCAT(">", $A22)) | K24: Gain | L24: =SUMIFS('Trading History'!$Z$4:$Z1007, 'Trading History'!$Y$4:$Y1007, CONCAT(">", $A22))
B25: Invested | C25: =Index!C26-Index!C24 | E25: ST Invested | F25: =Index!F26-Index!F24 | H25: LT Invested | I25: =Index!I26-Index!I24 | K25: Invested | L25: =Index!L26-Index!L24
B26: Gross | C26: =SUMIFS('Trading History'!$M$4:$M1007, 'Trading History'!$K$4:$K1007, CONCAT(">", $A22)) | E26: ST Gross | F26: =SUMIFS('Trading History'!$Q$4:$Q1007, 'Trading History'!$O$4:$O1007, CONCAT(">", $A22)) | H26: LT Gross | I26: =SUMIFS('Trading History'!$U$4:$U1007, 'Trading History'!$S$4:$S1007, CONCAT(">", $A22)) | K26: Gross | L26: =SUMIFS('Trading History'!$AA$4:$AA1007, 'Trading History'!$Y$4:$Y1007, CONCAT(">", $A22))
A29: 0.4 | B29: Units | C29: =SUMIFS('Trading History'!$N$4:$N1007, 'Trading History'!$K$4:$K1007, CONCAT(">", $A29)) | E29: ST Units | F29: =IFERROR(SUMIFS('Trading History'!$R$4:$R1007, 'Trading History'!$O$4:$O1007, CONCAT(">", $A29)), 0) | H29: LT Units | I29: =SUMIFS('Trading History'!$V$4:$V1007, 'Trading History'!$S$4:$S1007, CONCAT(">", $A29)) | K29: Units | L29: =SUMIFS('Trading History'!$AB$4:$AB1007, 'Trading History'!$Y$4:$Y1007, CONCAT(">", $A29))
B30: Avg % | C30: =IFERROR(Index!C31/(Index!C29*Index!$C$2), 0) | E30: ST Avg % | F30: =IFERROR(Index!F31/(Index!F29*Index!$C$2), 0) | H30: LT Avg % | I30: =IFERROR(Index!I31/(Index!I29*Index!$C$2), 0) | K30: Avg % | L30: =IFERROR(Index!L31/(Index!L29*Index!$C$2), 0)
B31: Gain | C31: =SUMIFS('Trading History'!$L$4:$L1007, 'Trading History'!$K$4:$K1007, CONCAT(">", $A29)) | E31: ST Gain | F31: =SUMIFS('Trading History'!$P$4:$P1007, 'Trading History'!$O$4:$O1007, CONCAT(">", $A29)) | H31: LT Gain | I31: =SUMIFS('Trading History'!$T$4:$T1007, 'Trading History'!$S$4:$S1007, CONCAT(">", $A29)) | K31: Gain | L31: =SUMIFS('Trading History'!$Z$4:$Z1007, 'Trading History'!$Y$4:$Y1007, CONCAT(">", $A29))
B32: Invested | C32: =Index!C33-Index!C31 | E32: ST Invested | F32: =Index!F33-Index!F31 | H32: LT Invested | I32: =Index!I33-Index!I31 | K32: Invested | L32: =Index!L33-Index!L31
B33: Gross | C33: =SUMIFS('Trading History'!$M$4:$M1007, 'Trading History'!$K$4:$K1007, CONCAT(">", $A29)) | E33: ST Gross | F33: =SUMIFS('Trading History'!$Q$4:$Q1007, 'Trading History'!$O$4:$O1007, CONCAT(">", $A29)) | H33: LT Gross | I33: =SUMIFS('Trading History'!$U$4:$U1007, 'Trading History'!$S$4:$S1007, CONCAT(">", $A29)) | K33: Gross | L33: =SUMIFS('Trading History'!$AA$4:$AA1007, 'Trading History'!$Y$4:$Y1007, CONCAT(">", $A29))
A36: 0.35 | B36: Units | C36: =SUMIFS('Trading History'!$N$4:$N1007, 'Trading History'!$K$4:$K1007, CONCAT(">", $A36)) | E36: ST Units | F36: =IFERROR(SUMIFS('Trading History'!$R$4:$R1007, 'Trading History'!$O$4:$O1007, CONCAT(">", $A36)), 0) | H36: LT Units | I36: =SUMIFS('Trading History'!$V$4:$V1007, 'Trading History'!$S$4:$S1007, CONCAT(">", $A36)) | K36: Units | L36: =SUMIFS('Trading History'!$AB$4:$AB1007, 'Trading History'!$Y$4:$Y1007, CONCAT(">", $A36))
B37: Avg % | C37: =IFERROR(Index!C38/(Index!C36*Index!$C$2), 0) | E37: ST Avg % | F37: =IFERROR(Index!F38/(Index!F36*Index!$C$2), 0) | H37: LT Avg % | I37: =IFERROR(Index!I38/(Index!I36*Index!$C$2), 0) | K37: Avg % | L37: =IFERROR(Index!L38/(Index!L36*Index!$C$2), 0)
B38: Gain | C38: =SUMIFS('Trading History'!$L$4:$L1007, 'Trading History'!$K$4:$K1007, CONCAT(">", $A36)) | E38: ST Gain | F38: =SUMIFS('Trading History'!$P$4:$P1007, 'Trading History'!$O$4:$O1007, CONCAT(">", $A36)) | H38: LT Gain | I38: =SUMIFS('Trading History'!$T$4:$T1007, 'Trading History'!$S$4:$S1007, CONCAT(">", $A36)) | K38: Gain | L38: =SUMIFS('Trading History'!$Z$4:$Z1007, 'Trading History'!$Y$4:$Y1007, CONCAT(">", $A36))
B39: Invested | C39: =Index!C40-Index!C38 | E39: ST Invested | F39: =Index!F40-Index!F38 | H39: LT Invested | I39: =Index!I40-Index!I38 | K39: Invested | L39: =Index!L40-Index!L38
B40: Gross | C40: =SUMIFS('Trading History'!$M$4:$M1007, 'Trading History'!$K$4:$K1007, CONCAT(">", $A36)) | E40: ST Gross | F40: =SUMIFS('Trading History'!$Q$4:$Q1007, 'Trading History'!$O$4:$O1007, CONCAT(">", $A36)) | H40: LT Gross | I40: =SUMIFS('Trading History'!$U$4:$U1007, 'Trading History'!$S$4:$S1007, CONCAT(">", $A36)) | K40: Gross | L40: =SUMIFS('Trading History'!$AA$4:$AA1007, 'Trading History'!$Y$4:$Y1007, CONCAT(">", $A36))
A43: 0.3 | B43: Units | C43: =SUMIFS('Trading History'!$N$4:$N1007, 'Trading History'!$K$4:$K1007, CONCAT(">", $A43)) | E43: ST Units | F43: =IFERROR(SUMIFS('Trading History'!$R$4:$R1007, 'Trading History'!$O$4:$O1007, CONCAT(">", $A43)), 0) | H43: LT Units | I43: =SUMIFS('Trading History'!$V$4:$V1007, 'Trading History'!$S$4:$S1007, CONCAT(">", $A43)) | K43: Units | L43: =SUMIFS('Trading History'!$AB$4:$AB1007, 'Trading History'!$Y$4:$Y1007, CONCAT(">", $A43))
B44: Avg % | C44: =IFERROR(Index!C45/(Index!C43*Index!$C$2), 0) | E44: ST Avg % | F44: =IFERROR(Index!F45/(Index!F43*Index!$C$2), 0) | H44: LT Avg % | I44: =IFERROR(Index!I45/(Index!I43*Index!$C$2), 0) | K44: Avg % | L44: =IFERROR(Index!L45/(Index!L43*Index!$C$2), 0)
B45: Gain | C45: =SUMIFS('Trading History'!$L$4:$L1007, 'Trading History'!$K$4:$K1007, CONCAT(">", $A43)) | E45: ST Gain | F45: =SUMIFS('Trading History'!$P$4:$P1007, 'Trading History'!$O$4:$O1007, CONCAT(">", $A43)) | H45: LT Gain | I45: =SUMIFS('Trading History'!$T$4:$T1007, 'Trading History'!$S$4:$S1007, CONCAT(">", $A43)) | K45: Gain | L45: =SUMIFS('Trading History'!$Z$4:$Z1007, 'Trading History'!$Y$4:$Y1007, CONCAT(">", $A43))
B46: Invested | C46: =Index!C47-Index!C45 | E46: ST Invested | F46: =Index!F47-Index!F45 | H46: LT Invested | I46: =Index!I47-Index!I45 | K46: Invested | L46: =Index!L47-Index!L45
B47: Gross | C47: =SUMIFS('Trading History'!$M$4:$M1007, 'Trading History'!$K$4:$K1007, CONCAT(">", $A43)) | E47: ST Gross | F47: =SUMIFS('Trading History'!$Q$4:$Q1007, 'Trading History'!$O$4:$O1007, CONCAT(">", $A43)) | H47: LT Gross | I47: =SUMIFS('Trading History'!$U$4:$U1007, 'Trading History'!$S$4:$S1007, CONCAT(">", $A43)) | K47: Gross | L47: =SUMIFS('Trading History'!$AA$4:$AA1007, 'Trading History'!$Y$4:$Y1007, CONCAT(">", $A43))
A50: 0.25 | B50: Units | C50: =SUMIFS('Trading History'!$N$4:$N1007, 'Trading History'!$K$4:$K1007, CONCAT(">", $A50)) | E50: ST Units | F50: =IFERROR(SUMIFS('Trading History'!$R$4:$R1007, 'Trading History'!$O$4:$O1007, CONCAT(">", $A50)), 0) | H50: LT Units | I50: =SUMIFS('Trading History'!$V$4:$V1007, 'Trading History'!$S$4:$S1007, CONCAT(">", $A50)) | K50: Units | L50: =SUMIFS('Trading History'!$AB$4:$AB1007, 'Trading History'!$Y$4:$Y1007, CONCAT(">", $A50))
B51: Avg % | C51: =IFERROR(Index!C52/(Index!C50*Index!$C$2), 0) | E51: ST Avg % | F51: =IFERROR(Index!F52/(Index!F50*Index!$C$2), 0) | H51: LT Avg % | I51: =IFERROR(Index!I52/(Index!I50*Index!$C$2), 0) | K51: Avg % | L51: =IFERROR(Index!L52/(Index!L50*Index!$C$2), 0)
B52: Gain | C52: =SUMIFS('Trading History'!$L$4:$L1007, 'Trading History'!$K$4:$K1007, CONCAT(">", $A50)) | E52: ST Gain | F52: =SUMIFS('Trading History'!$P$4:$P1007, 'Trading History'!$O$4:$O1007, CONCAT(">", $A50)) | H52: LT Gain | I52: =SUMIFS('Trading History'!$T$4:$T1007, 'Trading History'!$S$4:$S1007, CONCAT(">", $A50)) | K52: Gain | L52: =SUMIFS('Trading History'!$Z$4:$Z1007, 'Trading History'!$Y$4:$Y1007, CONCAT(">", $A50))
B53: Invested | C53: =Index!C54-Index!C52 | E53: ST Invested | F53: =Index!F54-Index!F52 | H53: LT Invested | I53: =Index!I54-Index!I52 | K53: Invested | L53: =Index!L54-Index!L52
...
