Workbook

Sheet Index
B2: Current Price | C2: =IFERROR(__xludf.DUMMYFUNCTION("GOOGLEFINANCE(""NSE:IRCTC"", ""price"")"),620.5) -> 620.5 | E2: Commission | F2: 0.007
B4: UnRealised
B6: Units | C6: =sum('Trading History'!M4:M1003) -> 450 | E6: ST Units | F6: =sum('Trading History'!P4:P1003) -> 200 | H6: LT Units | I6: =sum('Trading History'!S4:S1003) -> 250 | K6: Units | L6: =sum('Trading History'!V4:V1003) -> 350
B7: Avg % | C7: =Index!C8/(Index!C6*Index!$C$2) -> 0.62419109 | E7: ST Avg % | F7: =Index!F8/(Index!F6*Index!$C$2) -> 0.64127422 | H7: LT Avg % | I7: =IFERROR(Index!I8/(Index!I6*Index!$C$2), 0) -> 0.6138307 | K7: Avg % | L7: =IFERROR(Index!L8/(Index!L6*AVERAGE('Trading History'!T4:T1003)),0) -> 0.23517681
B8: Gain | C8: =sum('Trading History'!K4:K1003) -> 174289.76 | E8: ST Gain | F8: =sum('Trading History'!N4:N1003) -> 79582.131 | H8: LT Gain | I8: =sum('Trading History'!Q4:Q1003) -> 95220.488 | K8: Gain | L8: =sum('Trading History'!W4:W1003) -> 27345.044
B9: Invested | C9: =Index!C10-Index!C8 -> 102460.54 | E9: ST Invested | F9: =Index!F10-Index!F8 -> 43387.9 | H9: LT Invested | I9: =Index!I10-Index!I8 -> 59072.64 | K9: Invested | L9: =L8-L10 -> -88463.69
B10: Gross | C10: =sum('Trading History'!L4:L1003) -> 276750.3 | E10: ST Gross | F10: =sum('Trading History'!O4:O1003) -> 122970.03 | H10: LT Gross | I10: =sum('Trading History'!R4:R1003) -> 154293.13 | K10: Gross | L10: =sum('Trading History'!X4:X1003) -> 115808.73
K11: Dividends | L11: =SUMIF('Trading History'!B4:B1003,"DIV",'Trading History'!Y4:Y1003) -> 4061.5

Sheet Trading History
K2: UnRealised | T2: Realised
K3: Total | N3: Short Term | Q3: Long Term
A4: DATE | B4: EXCH | C4: ACTION | D4: QTY | E4: PRICE | F4: COST | G4: REMARKS | H4: STT | I4: ADD CHRG | J4: Current Price | K4: Gain | L4: Gross | M4: Units | N4: Gain | O4: Gross | P4: Units | Q4: Gain | R4: Gross | S4: Units | T4: Price | U4: Date | V4: Units | W4: Gain | X4: Gross | Y4: DIV | Z4: Broker
A5: 45722 | B5: NSE | C5: Buy | D5: 2 | E5: 222.24 | F5: 444.48 | G5: ~ | H5: 0.44 | I5: 2.68 | J5: =Index!$C$2 -> 620.5 | K5: =IF(AND( C5="Buy", ISBLANK(T5), B5<>"DIV"), (1-Index!$F$2*2)*((J5*D5)-(E5*D5)), "") -> 785.36872 | L5: =IF(AND( C5="Buy", ISBLANK(T5), B5<>"DIV"), ((E5*D5)+K5), "") -> 1229.8487 | M5: =IF(AND( C5="Buy", ISBLANK(T5), B5<>"DIV"), D5, "") -> 2 | N5: =IF(AND( C5="Buy", ISBLANK(T5), B5<>"DIV", NOW()-A5 < 365), (1-Index!$F$2*2)*((J5*D5)-(E5*D5)), "") -> 785.36872 | O5: =IF(AND( C5="Buy", ISBLANK(T5), B5<>"DIV", NOW()-A5 < 365), ((E5*D5)+N5), "") -> 1229.8487 | P5: =IF(AND( C5="Buy", ISBLANK(T5), B5<>"DIV", NOW()-A5 < 365), D5, "") -> 2 | Q5: =IF(AND( C5="Buy", ISBLANK(T5), B5<>"DIV", NOW()-A5 > 365), (J5*D5)-(E5*D5)-(2*sum(H5:I5)), "") | R5: =IF(AND( C5="Buy", ISBLANK(T5), B5<>"DIV", NOW()-A5 > 365), ((E5*D5)+Q5), "") | S5: =IF(AND( C5="Buy", ISBLANK(T5), B5<>"DIV", NOW()-A5 > 365), D5, "") | Y5: =if(B5="DIV", F5,"")
A6: 45722 | B6: NSE | C6: Buy | D6: 1 | E6: 222.27 | F6: 222.27 | G6: ~ | H6: 0.22 | I6: 1.34 | J6: =Index!$C$2 -> 620.5 | K6: =IF(AND( C6="Buy", ISBLANK(T6), B6<>"DIV"), (1-Index!$F$2*2)*((J6*D6)-(E6*D6)), "") -> 392.65478 | L6: =IF(AND( C6="Buy", ISBLANK(T6), B6<>"DIV"), ((E6*D6)+K6), "") -> 614.92478 | M6: =IF(AND( C6="Buy", ISBLANK(T6), B6<>"DIV"), D6, "") -> 1 | N6: =IF(AND( C6="Buy", ISBLANK(T6), B6<>"DIV", NOW()-A6 < 365), (1-Index!$F$2*2)*((J6*D6)-(E6*D6)), "") -> 392.65478 | O6: =IF(AND( C6="Buy", ISBLANK(T6), B6<>"DIV", NOW()-A6 < 365), ((E6*D6)+N6), "") -> 614.92478 | P6: =IF(AND( C6="Buy", ISBLANK(T6), B6<>"DIV", NOW()-A6 < 365), D6, "") -> 1 | Q6: =IF(AND( C6="Buy", ISBLANK(T6), B6<>"DIV", NOW()-A6 > 365), (J6*D6)-(E6*D6)-(2*sum(H6:I6)), "") | R6: =IF(AND( C6="Buy", ISBLANK(T6), B6<>"DIV", NOW()-A6 > 365), ((E6*D6)+Q6), "") | S6: =IF(AND( C6="Buy", ISBLANK(T6), B6<>"DIV", NOW()-A6 > 365), D6, "") | Y6: =if(B6="DIV", F6,"")
A7: 45722 | B7: NSE | C7: Buy | D7: 1 | E7: 222.26 | F7: 222.26 | G7: ~ | H7: 0.22 | I7: 1.34 | J7: =Index!$C$2 -> 620.5 | K7: =IF(AND( C7="Buy", ISBLANK(T7), B7<>"DIV"), (1-Index!$F$2*2)*((J7*D7)-(E7*D7)), "") -> 392.66464 | L7: =IF(AND( C7="Buy", ISBLANK(T7), B7<>"DIV"), ((E7*D7)+K7), "") -> 614.92464 | M7: =IF(AND( C7="Buy", ISBLANK(T7), B7<>"DIV"), D7, "") -> 1 | N7: =IF(AND( C7="Buy", ISBLANK(T7), B7<>"DIV", NOW()-A7 < 365), (1-Index!$F$2*2)*((J7*D7)-(E7*D7)), "") -> 392.66464 | O7: =IF(AND( C7="Buy", ISBLANK(T7), B7<>"DIV", NOW()-A7 < 365), ((E7*D7)+N7), "") -> 614.92464 | P7: =IF(AND( C7="Buy", ISBLANK(T7), B7<>"DIV", NOW()-A7 < 365), D7, "") -> 1 | Q7: =IF(AND( C7="Buy", ISBLANK(T7), B7<>"DIV", NOW()-A7 > 365), (J7*D7)-(E7*D7)-(2*sum(H7:I7)), "") | R7: =IF(AND( C7="Buy", ISBLANK(T7), B7<>"DIV", NOW()-A7 > 365), ((E7*D7)+Q7), "") | S7: =IF(AND( C7="Buy", ISBLANK(T7), B7<>"DIV", NOW()-A7 > 365), D7, "") | Y7: =if(B7="DIV", F7,"")
A8: 45722 | B8: NSE | C8: Buy | D8: 8 | E8: 222.29 | F8: 1778.3 | G8: ~ | H8: 1.78 | I8: 10.68 | J8: =Index!$C$2 -> 620.5 | K8: =IF(AND( C8="Buy", ISBLANK(T8), B8<>"DIV"), (1-Index!$F$2*2)*((J8*D8)-(E8*D8)), "") -> 3141.0805 | L8: =IF(AND( C8="Buy", ISBLANK(T8), B8<>"DIV"), ((E8*D8)+K8), "") -> 4919.4005 | M8: =IF(AND( C8="Buy", ISBLANK(T8), B8<>"DIV"), D8, "") -> 8 | N8: =IF(AND( C8="Buy", ISBLANK(T8), B8<>"DIV", NOW()-A8 < 365), (1-Index!$F$2*2)*((J8*D8)-(E8*D8)), "") -> 3141.0805 | O8: =IF(AND( C8="Buy", ISBLANK(T8), B8<>"DIV", NOW()-A8 < 365), ((E8*D8)+N8), "") -> 4919.4005 | P8: =IF(AND( C8="Buy", ISBLANK(T8), B8<>"DIV", NOW()-A8 < 365), D8, "") -> 8 | Q8: =IF(AND( C8="Buy", ISBLANK(T8), B8<>"DIV", NOW()-A8 > 365), (J8*D8)-(E8*D8)-(2*sum(H8:I8)), "") | R8: =IF(AND( C8="Buy", ISBLANK(T8), B8<>"DIV", NOW()-A8 > 365), ((E8*D8)+Q8), "") | S8: =IF(AND( C8="Buy", ISBLANK(T8), B8<>"DIV", NOW()-A8 > 365), D8, "") | Y8: =if(B8="DIV", F8,"")
A9: 45722 | B9: NSE | C9: Buy | D9: 1 | E9: 222.33 | F9: 222.33 | G9: ~ | H9: 0.22 | I9: 1.34 | J9: =Index!$C$2 -> 620.5 | K9: =IF(AND( C9="Buy", ISBLANK(T9), B9<>"DIV"), (1-Index!$F$2*2)*((J9*D9)-(E9*D9)), "") -> 392.59562 | L9: =IF(AND( C9="Buy", ISBLANK(T9), B9<>"DIV"), ((E9*D9)+K9), "") -> 614.92562 | M9: =IF(AND( C9="Buy", ISBLANK(T9), B9<>"DIV"), D9, "") -> 1 | N9: =IF(AND( C9="Buy", ISBLANK(T9), B9<>"DIV", NOW()-A9 < 365), (1-Index!$F$2*2)*((J9*D9)-(E9*D9)), "") -> 392.59562 | O9: =IF(AND( C9="Buy", ISBLANK(T9), B9<>"DIV", NOW()-A9 < 365), ((E9*D9)+N9), "") -> 614.92562 | P9: =IF(AND( C9="Buy", ISBLANK(T9), B9<>"DIV", NOW()-A9 < 365), D9, "") -> 1 | Q9: =IF(AND( C9="Buy", ISBLANK(T9), B9<>"DIV", NOW()-A9 > 365), (J9*D9)-(E9*D9)-(2*sum(H9:I9)), "") | R9: =IF(AND( C9="Buy", ISBLANK(T9), B9<>"DIV", NOW()-A9 > 365), ((E9*D9)+Q9), "") | S9: =IF(AND( C9="Buy", ISBLANK(T9), B9<>"DIV", NOW()-A9 > 365), D9, "") | Y9: =if(B9="DIV", F9,"")
A10: 45722 | B10: NSE | C10: Buy | D10: 2 | E10: 222.25 | F10: 444.5 | G10: ~ | H10: 0.44 | I10: 2.68 | J10: =Index!$C$2 -> 620.5 | K10: =IF(AND( C10="Buy", ISBLANK(T10), B10<>"DIV"), (1-Index!$F$2*2)*((J10*D10)-(E10*D10)), "") -> 785.349 | L10: =IF(AND( C10="Buy", ISBLANK(T10), B10<>"DIV"), ((E10*D10)+K10), "") -> 1229.849 | M10: =IF(AND( C10="Buy", ISBLANK(T10), B10<>"DIV"), D10, "") -> 2 | N10: =IF(AND( C10="Buy", ISBLANK(T10), B10<>"DIV", NOW()-A10 < 365), (1-Index!$F$2*2)*((J10*D10)-(E10*D10)), "") -> 785.349 | O10: =IF(AND( C10="Buy", ISBLANK(T10), B10<>"DIV", NOW()-A10 < 365), ((E10*D10)+N10), "") -> 1229.849 | P10: =IF(AND( C10="Buy", ISBLANK(T10), B10<>"DIV", NOW()-A10 < 365), D10, "") -> 2 | Q10: =IF(AND( C10="Buy", ISBLANK(T10), B10<>"DIV", NOW()-A10 > 365), (J10*D10)-(E10*D10)-(2*sum(H10:I10)), "") | R10: =IF(AND( C10="Buy", ISBLANK(T10), B10<>"DIV", NOW()-A10 > 365), ((E10*D10)+Q10), "") | S10: =IF(AND( C10="Buy", ISBLANK(T10), B10<>"DIV", NOW()-A10 > 365), D10, "") | Y10: =if(B10="DIV", F10,"")
A11: 45722 | B11: NSE | C11: Buy | D11: 8 | E11: 222.33 | F11: 1778.62 | G11: ~ | H11: 1.78 | I11: 10.68 | J11: =Index!$C$2 -> 620.5 | K11: =IF(AND( C11="Buy", ISBLANK(T11), B11<>"DIV"), (1-Index!$F$2*2)*((J11*D11)-(E11*D11)), "") -> 3140.765 | L11: =IF(AND( C11="Buy", ISBLANK(T11), B11<>"DIV"), ((E11*D11)+K11), "") -> 4919.405 | M11: =IF(AND( C11="Buy", ISBLANK(T11), B11<>"DIV"), D11, "") -> 8 | N11: =IF(AND( C11="Buy", ISBLANK(T11), B11<>"DIV", NOW()-A11 < 365), (1-Index!$F$2*2)*((J11*D11)-(E11*D11)), "") -> 3140.765 | O11: =IF(AND( C11="Buy", ISBLANK(T11), B11<>"DIV", NOW()-A11 < 365), ((E11*D11)+N11), "") -> 4919.405 | P11: =IF(AND( C11="Buy", ISBLANK(T11), B11<>"DIV", NOW()-A11 < 365), D11, "") -> 8 | Q11: =IF(AND( C11="Buy", ISBLANK(T11), B11<>"DIV", NOW()-A11 > 365), (J11*D11)-(E11*D11)-(2*sum(H11:I11)), "") | R11: =IF(AND( C11="Buy", ISBLANK(T11), B11<>"DIV", NOW()-A11 > 365), ((E11*D11)+Q11), "") | S11: =IF(AND( C11="Buy", ISBLANK(T11), B11<>"DIV", NOW()-A11 > 365), D11, "") | Y11: =if(B11="DIV", F11,"")
A12: 45722 | B12: NSE | C12: Buy | D12: 1 | E12: 222.25 | F12: 222.25 | G12: ~ | H12: 0.22 | I12: 1.34 | J12: =Index!$C$2 -> 620.5 | K12: =IF(AND( C12="Buy", ISBLANK(T12), B12<>"DIV"), (1-Index!$F$2*2)*((J12*D12)-(E12*D12)), "") -> 392.6745 | L12: =IF(AND( C12="Buy", ISBLANK(T12), B12<>"DIV"), ((E12*D12)+K12), "") -> 614.9245 | M12: =IF(AND( C12="Buy", ISBLANK(T12), B12<>"DIV"), D12, "") -> 1 | N12: =IF(AND( C12="Buy", ISBLANK(T12), B12<>"DIV", NOW()-A12 < 365), (1-Index!$F$2*2)*((J12*D12)-(E12*D12)), "") -> 392.6745 | O12: =IF(AND( C12="Buy", ISBLANK(T12), B12<>"DIV", NOW()-A12 < 365), ((E12*D12)+N12), "") -> 614.9245 | P12: =IF(AND( C12="Buy", ISBLANK(T12), B12<>"DIV", NOW()-A12 < 365), D12, "") -> 1 | Q12: =IF(AND( C12="Buy", ISBLANK(T12), B12<>"DIV", NOW()-A12 > 365), (J12*D12)-(E12*D12)-(2*sum(H12:I12)), "") | R12: =IF(AND( C12="Buy", ISBLANK(T12), B12<>"DIV", NOW()-A12 > 365), ((E12*D12)+Q12), "") | S12: =IF(AND( C12="Buy", ISBLANK(T12), B12<>"DIV", NOW()-A12 > 365), D12, "") | Y12: =if(B12="DIV", F12,"")
A13: 45722 | B13: NSE | C13: Buy | D13: 1 | E13: 222.3 | F13: 222.3 | G13: ~ | H13: 0.22 | I13: 1.34 | J13: =Index!$C$2 -> 620.5 | K13: =IF(AND( C13="Buy", ISBLANK(T13), B13<>"DIV"), (1-Index!$F$2*2)*((J13*D13)-(E13*D13)), "") -> 392.6252 | L13: =IF(AND( C13="Buy", ISBLANK(T13), B13<>"DIV"), ((E13*D13)+K13), "") -> 614.9252 | M13: =IF(AND( C13="Buy", ISBLANK(T13), B13<>"DIV"), D13, "") -> 1 | N13: =IF(AND( C13="Buy", ISBLANK(T13), B13<>"DIV", NOW()-A13 < 365), (1-Index!$F$2*2)*((J13*D13)-(E13*D13)), "") -> 392.6252 | O13: =IF(AND( C13="Buy", ISBLANK(T13), B13<>"DIV", NOW()-A13 < 365), ((E13*D13)+N13), "") -> 614.9252 | P13: =IF(AND( C13="Buy", ISBLANK(T13), B13<>"DIV", NOW()-A13 < 365), D13, "") -> 1 | Q13: =IF(AND( C13="Buy", ISBLANK(T13), B13<>"DIV", NOW()-A13 > 365), (J13*D13)-(E13*D13)-(2*sum(H13:I13)), "") | R13: =IF(AND( C13="Buy", ISBLANK(T13), B13<>"DIV", NOW()-A13 > 365), ((E13*D13)+Q13), "") | S13: =IF(AND( C13="Buy", ISBLANK(T13), B13<>"DIV", NOW()-A13 > 365), D13, "") | Y13: =if(B13="DIV", F13,"")
A14: 45722 | B14: NSE | C14: Buy | D14: 10 | E14: 222.34 | F14: 2223.41 | G14: ~ | H14: 2.22 | I14: 13.39 | J14: =Index!$C$2 -> 620.5 | K14: =IF(AND( C14="Buy", ISBLANK(T14), B14<>"DIV"), (1-Index!$F$2*2)*((J14*D14)-(E14*D14)), "") -> 3925.8576 | L14: =IF(AND( C14="Buy", ISBLANK(T14), B14<>"DIV"), ((E14*D14)+K14), "") -> 6149.2576 | M14: =IF(AND( C14="Buy", ISBLANK(T14), B14<>"DIV"), D14, "") -> 10 | N14: =IF(AND( C14="Buy", ISBLANK(T14), B14<>"DIV", NOW()-A14 < 365), (1-Index!$F$2*2)*((J14*D14)-(E14*D14)), "") -> 3925.8576 | O14: =IF(AND( C14="Buy", ISBLANK(T14), B14<>"DIV", NOW()-A14 < 365), ((E14*D14)+N14), "") -> 6149.2576 | P14: =IF(AND( C14="Buy", ISBLANK(T14), B14<>"DIV", NOW()-A14 < 365), D14, "") -> 10 | Q14: =IF(AND( C14="Buy", ISBLANK(T14), B14<>"DIV", NOW()-A14 > 365), (J14*D14)-(E14*D14)-(2*sum(H14:I14)), "") | R14: =IF(AND( C14="Buy", ISBLANK(T14), B14<>"DIV", NOW()-A14 > 365), ((E14*D14)+Q14), "") | S14: =IF(AND( C14="Buy", ISBLANK(T14), B14<>"DIV", NOW()-A14 > 365), D14, "") | Y14: =if(B14="DIV", F14,"")
A15: 45722 | B15: NSE | C15: Buy | D15: 1 | E15: 222.29 | F15: 222.29 | G15: ~ | H15: 0.22 | I15: 1.34 | J15: =Index!$C$2 -> 620.5 | K15: =IF(AND( C15="Buy", ISBLANK(T15), B15<>"DIV"), (1-Index!$F$2*2)*((J15*D15)-(E15*D15)), "") -> 392.63506 | L15: =IF(AND( C15="Buy", ISBLANK(T15), B15<>"DIV"), ((E15*D15)+K15), "") -> 614.92506 | M15: =IF(AND( C15="Buy", ISBLANK(T15), B15<>"DIV"), D15, "") -> 1 | N15: =IF(AND( C15="Buy", ISBLANK(T15), B15<>"DIV", NOW()-A15 < 365), (1-Index!$F$2*2)*((J15*D15)-(E15*D15)), "") -> 392.63506 | O15: =IF(AND( C15="Buy", ISBLANK(T15), B15<>"DIV", NOW()-A15 < 365), ((E15*D15)+N15), "") -> 614.92506 | P15: =IF(AND( C15="Buy", ISBLANK(T15), B15<>"DIV", NOW()-A15 < 365), D15, "") -> 1 | Q15: =IF(AND( C15="Buy", ISBLANK(T15), B15<>"DIV", NOW()-A15 > 365), (J15*D15)-(E15*D15)-(2*sum(H15:I15)), "") | R15: =IF(AND( C15="Buy", ISBLANK(T15), B15<>"DIV", NOW()-A15 > 365), ((E15*D15)+Q15), "") | S15: =IF(AND( C15="Buy", ISBLANK(T15), B15<>"DIV", NOW()-A15 > 365), D15, "") | Y15: =if(B15="DIV", F15,"")
A16: 45722 | B16: NSE | C16: Buy | D16: 1 | E16: 222.29 | F16: 222.29 | G16: ~ | H16: 0.22 | I16: 1.34 | J16: =Index!$C$2 -> 620.5 | K16: =IF(AND( C16="Buy", ISBLANK(T16), B16<>"DIV"), (1-Index!$F$2*2)*((J16*D16)-(E16*D16)), "") -> 392.63506 | L16: =IF(AND( C16="Buy", ISBLANK(T16), B16<>"DIV"), ((E16*D16)+K16), "") -> 614.92506 | M16: =IF(AND( C16="Buy", ISBLANK(T16), B16<>"DIV"), D16, "") -> 1 | N16: =IF(AND( C16="Buy", ISBLANK(T16), B16<>"DIV", NOW()-A16 < 365), (1-Index!$F$2*2)*((J16*D16)-(E16*D16)), "") -> 392.63506 | O16: =IF(AND( C16="Buy", ISBLANK(T16), B16<>"DIV", NOW()-A16 < 365), ((E16*D16)+N16), "") -> 614.92506 | P16: =IF(AND( C16="Buy", ISBLANK(T16), B16<>"DIV", NOW()-A16 < 365), D16, "") -> 1 | Q16: =IF(AND( C16="Buy", ISBLANK(T16), B16<>"DIV", NOW()-A16 > 365), (J16*D16)-(E16*D16)-(2*sum(H16:I16)), "") | R16: =IF(AND( C16="Buy", ISBLANK(T16), B16<>"DIV", NOW()-A16 > 365), ((E16*D16)+Q16), "") | S16: =IF(AND( C16="Buy", ISBLANK(T16), B16<>"DIV", NOW()-A16 > 365), D16, "") | Y16: =if(B16="DIV", F16,"")
... A34: 45687 | B34: NSE | C34: Buy | D34: 31 | E34: 241.65 | F34: 7491.18 | G34: ~ | H34: 7.43 | I34: 45.3 | J34: =Index!$C$2 -> 620.5 | K34: =IF(AND( C34="Buy", ISBLANK(T34), B34<>"DIV"), (1-Index!$F$2*2)*((J34*D34)-(E34*D34)), "") -> 11579.929 | L34: =IF(AND( C34="Buy", ISBLANK(T34), B34<>"DIV"), ((E34*D34)+K34), "") -> 19071.079 | M34: =IF(AND( C34="Buy", ISBLANK(T34), B34<>"DIV"), D34, "") -> 31 | N34: =IF(AND( C34="Buy", ISBLANK(T34), B34<>"DIV", NOW()-A34 < 365), (1-Index!$F$2*2)*((J34*D34)-(E34*D34)), "") | O34: =IF(AND( C34="Buy", ISBLANK(T34), B34<>"DIV", NOW()-A34 < 365), ((E34*D34)+N34), "") | P34: =IF(AND( C34="Buy", ISBLANK(T34), B34<>"DIV", NOW()-A34 < 365), D34, "") | Q34: =IF(AND( C34="Buy", ISBLANK(T34), B34<>"DIV", NOW()-A34 > 365), (J34*D34)-(E34*D34)-(2*sum(H34:I34)), "") -> 11638.89 | R34: =IF(AND( C34="Buy", ISBLANK(T34), B34<>"DIV", NOW()-A34 > 365), ((E34*D34)+Q34), "") -> 19130.04 | S34: =IF(AND( C34="Buy", ISBLANK(T34), B34<>"DIV", NOW()-A34 > 365), D34, "") -> 31 | Y34: =if(B34="DIV", F34,"")
A35: 45583 | B35: NSE | C35: Sell | D35: 100 | E35: 346.92 | F35: 34692.48 | G35: ~ | H35: 34.72 | I35: 207.8
A36: 45565 | B36: NSE | C36: Sell | D36: 250 | E36: 326.02 | F36: 81505.75 | G36: ~ | H36: 82.16 | I36: 487.09
A37: 45446 | B37: DIV | C37: Buy | D37: 540 | E37: 2.5 | F37: 1350 | G37: Annual-Dividend of Rs.2.5000/- per share on Ex-Date: 03-JUN-2024 | H37: 0 | I37: 0 | J37: =Index!$C$2 -> 620.5 | K37: =IF(AND( C37="Buy", ISBLANK(T37), B37<>"DIV"), (1-Index!$F$2*2)*((J37*D37)-(E37*D37)), "") | L37: =IF(AND( C37="Buy", ISBLANK(T37), B37<>"DIV"), ((E37*D37)+K37), "") | M37: =IF(AND( C37="Buy", ISBLANK(T37), B37<>"DIV"), D37, "") | N37: =IF(AND( C37="Buy", ISBLANK(T37), B37<>"DIV", NOW()-A37 < 365), (1-Index!$F$2*2)*((J37*D37)-(E37*D37)), "") | O37: =IF(AND( C37="Buy", ISBLANK(T37), B37<>"DIV", NOW()-A37 < 365), ((E37*D37)+N37), "") | P37: =IF(AND( C37="Buy", ISBLANK(T37), B37<>"DIV", NOW()-A37 < 365), D37, "") | Q37: =IF(AND( C37="Buy", ISBLANK(T37), B37<>"DIV", NOW()-A37 > 365), (J37*D37)-(E37*D37)-(2*sum(H37:I37)), "") | R37: =IF(AND( C37="Buy", ISBLANK(T37), B37<>"DIV", NOW()-A37 > 365), ((E37*D37)+Q37), "") | S37: =IF(AND( C37="Buy", ISBLANK(T37), B37<>"DIV", NOW()-A37 > 365), D37, "") | Y37: =if(B37="DIV", F37,"") -> 1350 | Z37: SBI Securities
A38: 45446 | B38: DIV | C38: Buy | D38: 10 | E38: 2.5 | F38: 25 | G38: Annual-Dividend of Rs.2.5000/- per share on Ex-Date: 03-JUN-2024 | H38: 0 | I38: 0 | J38: =Index!$C$2 -> 620.5 | K38: =IF(AND( C38="Buy", ISBLANK(T38), B38<>"DIV"), (1-Index!$F$2*2)*((J38*D38)-(E38*D38)), "") | L38: =IF(AND( C38="Buy", ISBLANK(T38), B38<>"DIV"), ((E38*D38)+K38), "") | M38: =IF(AND( C38="Buy", ISBLANK(T38), B38<>"DIV"), D38, "") | N38: =IF(AND( C38="Buy", ISBLANK(T38), B38<>"DIV", NOW()-A38 < 365), (1-Index!$F$2*2)*((J38*D38)-(E38*D38)), "") | O38: =IF(AND( C38="Buy", ISBLANK(T38), B38<>"DIV", NOW()-A38 < 365), ((E38*D38)+N38), "") | P38: =IF(AND( C38="Buy", ISBLANK(T38), B38<>"DIV", NOW()-A38 < 365), D38, "") | Q38: =IF(AND( C38="Buy", ISBLANK(T38), B38<>"DIV", NOW()-A38 > 365), (J38*D38)-(E38*D38)-(2*sum(H38:I38)), "") | R38: =IF(AND( C38="Buy", ISBLANK(T38), B38<>"DIV", NOW()-A38 > 365), ((E38*D38)+Q38), "") | S38: =IF(AND( C38="Buy", ISBLANK(T38), B38<>"DIV", NOW()-A38 > 365), D38, "") | Y38: =if(B38="DIV", F38,"") -> 25 | Z38: SBI Securities
A39: 45352 | B39: NSE | C39: Buy | D39: 2 | E39: 250.46 | F39: 500.91 | G39: ~ | H39: 0.5 | I39: 3.01 | J39: =Index!$C$2 -> 620.5 | K39: =IF(AND( C39="Buy", ISBLANK(T39), B39<>"DIV"), (1-Index!$F$2*2)*((J39*D39)-(E39*D39)), "") -> 729.71888 | L39: =IF(AND( C39="Buy", ISBLANK(T39), B39<>"DIV"), ((E39*D39)+K39), "") -> 1230.6389 | M39: =IF(AND( C39="Buy", ISBLANK(T39), B39<>"DIV"), D39, "") -> 2 | N39: =IF(AND( C39="Buy", ISBLANK(T39), B39<>"DIV", NOW()-A39 < 365), (1-Index!$F$2*2)*((J39*D39)-(E39*D39)), "") | O39: =IF(AND( C39="Buy", ISBLANK(T39), B39<>"DIV", NOW()-A39 < 365), ((E39*D39)+N39), "") | P39: =IF(AND( C39="Buy", ISBLANK(T39), B39<>"DIV", NOW()-A39 < 365), D39, "") | Q39: =IF(AND( C39="Buy", ISBLANK(T39), B39<>"DIV", NOW()-A39 > 365), (J39*D39)-(E39*D39)-(2*sum(H39:I39)), "") -> 733.06 | R39: =IF(AND( C39="Buy", ISBLANK(T39), B39<>"DIV", NOW()-A39 > 365), ((E39*D39)+Q39), "") -> 1233.98 | S39: =IF(AND( C39="Buy", ISBLANK(T39), B39<>"DIV", NOW()-A39 > 365), D39, "") -> 2 | Y39: =if(B39="DIV", F39,"") | Z39: SBI Securities
A40: 45352 | B40: NSE | C40: Buy | D40: 20 | E40: 250.36 | F40: 5007.19 | G40: ~ | H40: 4.97 | I40: 30.22 | J40: =Index!$C$2 -> 620.5 | K40: =IF(AND( C40="Buy", ISBLANK(T40), B40<>"DIV"), (1-Index!$F$2*2)*((J40*D40)-(E40*D40)), "") -> 7299.1608 | L40: =IF(AND( C40="Buy", ISBLANK(T40), B40<>"DIV"), ((E40*D40)+K40), "") -> 12306.361 | M40: =IF(AND( C40="Buy", ISBLANK(T40), B40<>"DIV"), D40, "") -> 20 | N40: =IF(AND( C40="Buy", ISBLANK(T40), B40<>"DIV", NOW()-A40 < 365), (1-Index!$F$2*2)*((J40*D40)-(E40*D40)), "") | O40: =IF(AND( C40="Buy", ISBLANK(T40), B40<>"DIV", NOW()-A40 < 365), ((E40*D40)+N40), "") | P40: =IF(AND( C40="Buy", ISBLANK(T40), B40<>"DIV", NOW()-A40 < 365), D40, "") | Q40: =IF(AND( C40="Buy", ISBLANK(T40), B40<>"DIV", NOW()-A40 > 365), (J40*D40)-(E40*D40)-(2*sum(H40:I40)), "") -> 7332.42 | R40: =IF(AND( C40="Buy", ISBLANK(T40), B40<>"DIV", NOW()-A40 > 365), ((E40*D40)+Q40), "") -> 12339.62 | S40: =IF(AND( C40="Buy", ISBLANK(T40), B40<>"DIV", NOW()-A40 > 365), D40, "") -> 20 | Y40: =if(B40="DIV", F40,"") | Z40: SBI Securities
A41: 45352 | B41: NSE | C41: Buy | D41: 2 | E41: 250.46 | F41: 500.91 | G41: ~ | H41: 0.5 | I41: 3.01 | J41: =Index!$C$2 -> 620.5 | K41: =IF(AND( C41="Buy", ISBLANK(T41), B41<>"DIV"), (1-Index!$F$2*2)*((J41*D41)-(E41*D41)), "") -> 729.71888 | L41: =IF(AND( C41="Buy", ISBLANK(T41), B41<>"DIV"), ((E41*D41)+K41), "") -> 1230.6389 | M41: =IF(AND( C41="Buy", ISBLANK(T41), B41<>"DIV"), D41, "") -> 2 | N41: =IF(AND( C41="Buy", ISBLANK(T41), B41<>"DIV", NOW()-A41 < 365), (1-Index!$F$2*2)*((J41*D41)-(E41*D41)), "") | O41: =IF(AND( C41="Buy", ISBLANK(T41), B41<>"DIV", NOW()-A41 < 365), ((E41*D41)+N41), "") | P41: =IF(AND( C41="Buy", ISBLANK(T41), B41<>"DIV", NOW()-A41 < 365), D41, "") | Q41: =IF(AND( C41="Buy", ISBLANK(T41), B41<>"DIV", NOW()-A41 > 365), (J41*D41)-(E41*D41)-(2*sum(H41:I41)), "") -> 733.06 | R41: =IF(AND( C41="Buy", ISBLANK(T41), B41<>"DIV", NOW()-A41 > 365), ((E41*D41)+Q41), "") -> 1233.98 | S41: =IF(AND( C41="Buy", ISBLANK(T41), B41<>"DIV", NOW()-A41 > 365), D41, "") -> 2 | Y41: =if(B41="DIV", F41,"") | Z41: SBI Securities
A42: 45352 | B42: NSE | C42: Buy | D42: 3 | E42: 250.41 | F42: 751.22 | G42: ~ | H42: 0.75 | I42: 4.52 | J42: =Index!$C$2 -> 620.5 | K42: =IF(AND( C42="Buy", ISBLANK(T42), B42<>"DIV"), (1-Index!$F$2*2)*((J42*D42)-(E42*D42)), "") -> 1094.7262 | L42: =IF(AND( C42="Buy", ISBLANK(T42), B42<>"DIV"), ((E42*D42)+K42), "") -> 1845.9562 | M42: =IF(AND( C42="Buy", ISBLANK(T42), B42<>"DIV"), D42, "") -> 3 | N42: =IF(AND( C42="Buy", ISBLANK(T42), B42<>"DIV", NOW()-A42 < 365), (1-Index!$F$2*2)*((J42*D42)-(E42*D42)), "") | O42: =IF(AND( C42="Buy", ISBLANK(T42), B42<>"DIV", NOW()-A42 < 365), ((E42*D42)+N42), "") | P42: =IF(AND( C42="Buy", ISBLANK(T42), B42<>"DIV", NOW()-A42 < 365), D42, "") | Q42: =IF(AND( C42="Buy", ISBLANK(T42), B42<>"DIV", NOW()-A42 > 365), (J42*D42)-(E42*D42)-(2*sum(H42:I42)), "") -> 1099.73 | R42: =IF(AND( C42="Buy", ISBLANK(T42), B42<>"DIV", NOW()-A42 > 365), ((E42*D42)+Q42), "") -> 1850.96 | S42: =IF(AND( C42="Buy", ISBLANK(T42), B42<>"DIV", NOW()-A42 > 365), D42, "") -> 3 | Y42: =if(B42="DIV", F42,"") | Z42: SBI Securities
A43: 45352 | B43: NSE | C43: Buy | D43: 3 | E43: 250.36 | F43: 751.07 | G43: ~ | H43: 0.75 | I43: 4.52 | J43: =Index!$C$2 -> 620.5 | K43: =IF(AND( C43="Buy", ISBLANK(T43), B43<>"DIV"), (1-Index!$F$2*2)*((J43*D43)-(E43*D43)), "") -> 1094.8741 | L43: =IF(AND( C43="Buy", ISBLANK(T43), B43<>"DIV"), ((E43*D43)+K43), "") -> 1845.9541 | M43: =IF(AND( C43="Buy", ISBLANK(T43), B43<>"DIV"), D43, "") -> 3 | N43: =IF(AND( C43="Buy", ISBLANK(T43), B43<>"DIV", NOW()-A43 < 365), (1-Index!$F$2*2)*((J43*D43)-(E43*D43)), "") | O43: =IF(AND( C43="Buy", ISBLANK(T43), B43<>"DIV", NOW()-A43 < 365), ((E43*D43)+N43), "") | P43: =IF(AND( C43="Buy", ISBLANK(T43), B43<>"DIV", NOW()-A43 < 365), D43, "") | Q43: =IF(AND( C43="Buy", ISBLANK(T43), B43<>"DIV", NOW()-A43 > 365), (J43*D43)-(E43*D43)-(2*sum(H43:I43)), "") -> 1099.88 | R43: =IF(AND( C43="Buy", ISBLANK(T43), B43<>"DIV", NOW()-A43 > 365), ((E43*D43)+Q43), "") -> 1850.96 | S43: =IF(AND( C43="Buy", ISBLANK(T43), B43<>"DIV", NOW()-A43 > 365), D43, "") -> 3 | Y43: =if(B43="DIV", F43,"") | Z43: SBI Securities
A44: 45352 | B44: NSE | C44: Buy | D44: 20 | E44: 250.36 | F44: 5007.19 | G44: ~ | H44: 4.97 | I44: 30.22 | J44: =Index!$C$2 -> 620.5 | K44: =IF(AND( C44="Buy", ISBLANK(T44), B44<>"DIV"), (1-Index!$F$2*2)*((J44*D44)-(E44*D44)), "") -> 7299.1608 | L44: =IF(AND( C44="Buy", ISBLANK(T44), B44<>"DIV"), ((E44*D44)+K44), "") -> 12306.361 | M44: =IF(AND( C44="Buy", ISBLANK(T44), B44<>"DIV"), D44, "") -> 20 | N44: =IF(AND( C44="Buy", ISBLANK(T44), B44<>"DIV", NOW()-A44 < 365), (1-Index!$F$2*2)*((J44*D44)-(E44*D44)), "") | O44: =IF(AND( C44="Buy", ISBLANK(T44), B44<>"DIV", NOW()-A44 < 365), ((E44*D44)+N44), "") | P44: =IF(AND( C44="Buy", ISBLANK(T44), B44<>"DIV", NOW()-A44 < 365), D44, "") | Q44: =IF(AND( C44="Buy", ISBLANK(T44), B44<>"DIV", NOW()-A44 > 365), (J44*D44)-(E44*D44)-(2*sum(H44:I44)), "") -> 7332.42 | R44: =IF(AND( C44="Buy", ISBLANK(T44), B44<>"DIV", NOW()-A44 > 365), ((E44*D44)+Q44), "") -> 12339.62 | S44: =IF(AND( C44="Buy", ISBLANK(T44), B44<>"DIV", NOW()-A44 > 365), D44, "") -> 20 | Y44: =if(B44="DIV", F44,"") | Z44: SBI Securities
A45: 45349 | B45: NSE | C45: Buy | D45: 10 | E45: 247.49 | F45: 2474.93 | G45: ~ | H45: 2.45 | I45: 14.98 | J45: =Index!$C$2 -> 620.5 | K45: =IF(AND( C45="Buy", ISBLANK(T45), B45<>"DIV"), (1-Index!$F$2*2)*((J45*D45)-(E45*D45)), "") -> 3677.8786 | L45: =IF(AND( C45="Buy", ISBLANK(T45), B45<>"DIV"), ((E45*D45)+K45), "") -> 6152.7786 | M45: =IF(AND( C45="Buy", ISBLANK(T45), B45<>"DIV"), D45, "") -> 10 | N45: =IF(AND( C45="Buy", ISBLANK(T45), B45<>"DIV", NOW()-A45 < 365), (1-Index!$F$2*2)*((J45*D45)-(E45*D45)), "") | O45: =IF(AND( C45="Buy", ISBLANK(T45), B45<>"DIV", NOW()-A45 < 365), ((E45*D45)+N45), "") | P45: =IF(AND( C45="Buy", ISBLANK(T45), B45<>"DIV", NOW()-A45 < 365), D45, "") | Q45: =IF(AND( C45="Buy", ISBLANK(T45), B45<>"DIV", NOW()-A45 > 365), (J45*D45)-(E45*D45)-(2*sum(H45:I45)), "") -> 3695.24 | R45: =IF(AND( C45="Buy", ISBLANK(T45), B45<>"DIV", NOW()-A45 > 365), ((E45*D45)+Q45), "") -> 6170.14 | S45: =IF(AND( C45="Buy", ISBLANK(T45), B45<>"DIV", NOW()-A45 > 365), D45, "") -> 10 | Y45: =if(B45="DIV", F45,"") | Z45: SBI Securities
A46: 45282 | B46: NSE | C46: Buy | D46: 10 | E46: 251.87 | F46: 2518.74 | G46: ~ | H46: 2.5 | I46: 15.24 | J46: =Index!$C$2 -> 620.5 | K46: =IF(AND( C46="Buy", ISBLANK(T46), B46<>"DIV"), (1-Index!$F$2*2)*((J46*D46)-(E46*D46)), "") -> 3634.6918 | L46: =IF(AND( C46="Buy", ISBLANK(T46), B46<>"DIV"), ((E46*D46)+K46), "") -> 6153.3918 | M46: =IF(AND( C46="Buy", ISBLANK(T46), B46<>"DIV"), D46, "") -> 10 | N46: =IF(AND( C46="Buy", ISBLANK(T46), B46<>"DIV", NOW()-A46 < 365), (1-Index!$F$2*2)*((J46*D46)-(E46*D46)), "") | O46: =IF(AND( C46="Buy", ISBLANK(T46), B46<>"DIV", NOW()-A46 < 365), ((E46*D46)+N46), "") | P46: =IF(AND( C46="Buy", ISBLANK(T46), B46<>"DIV", NOW()-A46 < 365), D46, "") | Q46: =IF(AND( C46="Buy", ISBLANK(T46), B46<>"DIV", NOW()-A46 > 365), (J46*D46)-(E46*D46)-(2*sum(H46:I46)), "") -> 3650.82 | R46: =IF(AND( C46="Buy", ISBLANK(T46), B46<>"DIV", NOW()-A46 > 365), ((E46*D46)+Q46), "") -> 6169.52 | S46: =IF(AND( C46="Buy", ISBLANK(T46), B46<>"DIV", NOW()-A46 > 365), D46, "") -> 10 | Y46: =if(B46="DIV", F46,"") | Z46: SBI Securities
A47: 45278 | B47: NSE | C47: Buy | D47: 10 | E47: 257.01 | F47: 2570.13 | G47: ~ | H47: 2.55 | I47: 15.58 | J47: =Index!$C$2 -> 620.5 | K47: =IF(AND( C47="Buy", ISBLANK(T47), B47<>"DIV"), (1-Index!$F$2*2)*((J47*D47)-(E47*D47)), "") -> 3584.0114 | L47: =IF(AND( C47="Buy", ISBLANK(T47), B47<>"DIV"), ((E47*D47)+K47), "") -> 6154.1114 | M47: =IF(AND( C47="Buy", ISBLANK(T47), B47<>"DIV"), D47, "") -> 10 | N47: =IF(AND( C47="Buy", ISBLANK(T47), B47<>"DIV", NOW()-A47 < 365), (1-Index!$F$2*2)*((J47*D47)-(E47*D47)), "") | O47: =IF(AND( C47="Buy", ISBLANK(T47), B47<>"DIV", NOW()-A47 < 365), ((E47*D47)+N47), "") | P47: =IF(AND( C47="Buy", ISBLANK(T47), B47<>"DIV", NOW()-A47 < 365), D47, "") | Q47: =IF(AND( C47="Buy", ISBLANK(T47), B47<>"DIV", NOW()-A47 > 365), (J47*D47)-(E47*D47)-(2*sum(H47:I47)), "") -> 3598.64 | R47: =IF(AND( C47="Buy", ISBLANK(T47), B47<>"DIV", NOW()-A47 > 365), ((E47*D47)+Q47), "") -> 6168.74 | S47: =IF(AND( C47="Buy", ISBLANK(T47), B47<>"DIV", NOW()-A47 > 365), D47, "") -> 10 | Y47: =if(B47="DIV", F47,"") | Z47: SBI Securities
A48: 45225 | B48: NSE | C48: Buy | D48: 10 | E48: 211.9 | F48: 2118.95 | G48: ~ | H48: 2.12 | I48: 12.83 | J48: =Index!$C$2 -> 620.5 | K48: =IF(AND( C48="Buy", ISBLANK(T48), B48<>"DIV"), (1-Index!$F$2*2)*((J48*D48)-(E48*D48)), "") -> 4028.796 | L48: =IF(AND( C48="Buy", ISBLANK(T48), B48<>"DIV"), ((E48*D48)+K48), "") -> 6147.796 | M48: =IF(AND( C48="Buy", ISBLANK(T48), B48<>"DIV"), D48, "") -> 10 | N48: =IF(AND( C48="Buy", ISBLANK(T48), B48<>"DIV", NOW()-A48 < 365), (1-Index!$F$2*2)*((J48*D48)-(E48*D48)), "") | O48: =IF(AND( C48="Buy", ISBLANK(T48), B48<>"DIV", NOW()-A48 < 365), ((E48*D48)+N48), "") | P48: =IF(AND( C48="Buy", ISBLANK(T48), B48<>"DIV", NOW()-A48 < 365), D48, "") | Q48: =IF(AND( C48="Buy", ISBLANK(T48), B48<>"DIV", NOW()-A48 > 365), (J48*D48)-(E48*D48)-(2*sum(H48:I48)), "") -> 4056.1 | R48: =IF(AND( C48="Buy", ISBLANK(T48), B48<>"DIV", NOW()-A48 > 365), ((E48*D48)+Q48), "") -> 6175.1 | S48: =IF(AND( C48="Buy", ISBLANK(T48), B48<>"DIV", NOW()-A48 > 365), D48, "") -> 10 | Y48: =if(B48="DIV", F48,"") | Z48: SBI Securities
... A64: 44827 | B64: NSE | C64: Buy | D64: 3 | E64: 224.73 | F64: 674.18625 | G64: ~ | H64: 0.6525 | I64: 4.08375 | J64: =Index!$C$2 -> 620.5 | K64: =IF(AND( C64="Buy", ISBLANK(T64), B64<>"DIV"), (1-Index!$F$2*2)*((J64*D64)-(E64*D64)), "") -> 1170.6877 | L64: =IF(AND( C64="Buy", ISBLANK(T64), B64<>"DIV"), ((E64*D64)+K64), "") -> 1844.8777 | M64: =IF(AND( C64="Buy", ISBLANK(T64), B64<>"DIV"), D64, "") -> 3 | N64: =IF(AND( C64="Buy", ISBLANK(T64), B64<>"DIV", NOW()-A64 < 365), (1-Index!$F$2*2)*((J64*D64)-(E64*D64)), "") | O64: =IF(AND( C64="Buy", ISBLANK(T64), B64<>"DIV", NOW()-A64 < 365), ((E64*D64)+N64), "") | P64: =IF(AND( C64="Buy", ISBLANK(T64), B64<>"DIV", NOW()-A64 < 365), D64, "") | Q64: =IF(AND( C64="Buy", ISBLANK(T64), B64<>"DIV", NOW()-A64 > 365), (J64*D64)-(E64*D64)-(2*sum(H64:I64)), "") -> 1177.8375 | R64: =IF(AND( C64="Buy", ISBLANK(T64), B64<>"DIV", NOW()-A64 > 365), ((E64*D64)+Q64), "") -> 1852.0275 | S64: =IF(AND( C64="Buy", ISBLANK(T64), B64<>"DIV", NOW()-A64 > 365), D64, "") -> 3 | Y64: =if(B64="DIV", F64,"") | Z64: SBI Securities
A65: 44827 | B65: NSE | C65: Buy | D65: 5 | E65: 224.73 | F65: 1123.64 | G65: ~ | H65: 1.0875 | I65: 6.80625 | J65: =Index!$C$2 -> 620.5 | K65: =IF(AND( C65="Buy", ISBLANK(T65), B65<>"DIV"), (1-Index!$F$2*2)*((J65*D65)-(E65*D65)), "") | L65: =IF(AND( C65="Buy", ISBLANK(T65), B65<>"DIV"), ((E65*D65)+K65), "") | M65: =IF(AND( C65="Buy", ISBLANK(T65), B65<>"DIV"), D65, "") | N65: =IF(AND( C65="Buy", ISBLANK(T65), B65<>"DIV", NOW()-A65 < 365), (1-Index!$F$2*2)*((J65*D65)-(E65*D65)), "") | O65: =IF(AND( C65="Buy", ISBLANK(T65), B65<>"DIV", NOW()-A65 < 365), ((E65*D65)+N65), "") | P65: =IF(AND( C65="Buy", ISBLANK(T65), B65<>"DIV", NOW()-A65 < 365), D65, "") | Q65: =IF(AND( C65="Buy", ISBLANK(T65), B65<>"DIV", NOW()-A65 > 365), (J65*D65)-(E65*D65)-(2*sum(H65:I65)), "") | R65: =IF(AND( C65="Buy", ISBLANK(T65), B65<>"DIV", NOW()-A65 > 365), ((E65*D65)+Q65), "") | S65: =IF(AND( C65="Buy", ISBLANK(T65), B65<>"DIV", NOW()-A65 > 365), D65, "") | T65: 346.92 | U65: 45583 | V65: =D65 -> 5 | W65: =(1-Index!$F$2*2)*((T65*D65)-(E65*D65)) -> 602.3967 | X65: =((E65*D65)+W65) -> 1726.0467 | Y65: =if(B65="DIV", F65,"") | Z65: SBI Securities
A66: 44718 | B66: DIV | C66: Buy | D66: 345 | E66: 3 | F66: 1035 | G66: Annual-Dividend of Rs.3.0000/- per share on Ex-Date: 06-JUN-2022 | H66: 0 | I66: 0 | J66: =Index!$C$2 -> 620.5 | K66: =IF(AND( C66="Buy", ISBLANK(T66), B66<>"DIV"), (1-Index!$F$2*2)*((J66*D66)-(E66*D66)), "") | L66: =IF(AND( C66="Buy", ISBLANK(T66), B66<>"DIV"), ((E66*D66)+K66), "") | M66: =IF(AND( C66="Buy", ISBLANK(T66), B66<>"DIV"), D66, "") | N66: =IF(AND( C66="Buy", ISBLANK(T66), B66<>"DIV", NOW()-A66 < 365), (1-Index!$F$2*2)*((J66*D66)-(E66*D66)), "") | O66: =IF(AND( C66="Buy", ISBLANK(T66), B66<>"DIV", NOW()-A66 < 365), ((E66*D66)+N66), "") | P66: =IF(AND( C66="Buy", ISBLANK(T66), B66<>"DIV", NOW()-A66 < 365), D66, "") | Q66: =IF(AND( C66="Buy", ISBLANK(T66), B66<>"DIV", NOW()-A66 > 365), (J66*D66)-(E66*D66)-(2*sum(H66:I66)), "") | R66: =IF(AND( C66="Buy", ISBLANK(T66), B66<>"DIV", NOW()-A66 > 365), ((E66*D66)+Q66), "") | S66: =IF(AND( C66="Buy", ISBLANK(T66), B66<>"DIV", NOW()-A66 > 365), D66, "") | Y66: =if(B66="DIV", F66,"") -> 1035 | Z66: SBI Securities
A67: 44692 | B67: NSE | C67: Buy | D67: 6 | E67: 204.89 | F67: 1229.35 | G67: ~ | H67: 1.23 | I67: 7.42 | J67: =Index!$C$2 -> 620.5 | K67: =IF(AND( C67="Buy", ISBLANK(T67), B67<>"DIV"), (1-Index!$F$2*2)*((J67*D67)-(E67*D67)), "") | L67: =IF(AND( C67="Buy", ISBLANK(T67), B67<>"DIV"), ((E67*D67)+K67), "") | M67: =IF(AND( C67="Buy", ISBLANK(T67), B67<>"DIV"), D67, "") | N67: =IF(AND( C67="Buy", ISBLANK(T67), B67<>"DIV", NOW()-A67 < 365), (1-Index!$F$2*2)*((J67*D67)-(E67*D67)), "") | O67: =IF(AND( C67="Buy", ISBLANK(T67), B67<>"DIV", NOW()-A67 < 365), ((E67*D67)+N67), "") | P67: =IF(AND( C67="Buy", ISBLANK(T67), B67<>"DIV", NOW()-A67 < 365), D67, "") | Q67: =IF(AND( C67="Buy", ISBLANK(T67), B67<>"DIV", NOW()-A67 > 365), (J67*D67)-(E67*D67)-(2*sum(H67:I67)), "") | R67: =IF(AND( C67="Buy", ISBLANK(T67), B67<>"DIV", NOW()-A67 > 365), ((E67*D67)+Q67), "") | S67: =IF(AND( C67="Buy", ISBLANK(T67), B67<>"DIV", NOW()-A67 > 365), D67, "") | T67: 346.92 | U67: 45583 | V67: =D67 -> 6 | W67: =(1-Index!$F$2*2)*((T67*D67)-(E67*D67)) -> 840.24948 | X67: =((E67*D67)+W67) -> 2069.5895 | Y67: =if(B67="DIV", F67,"") | Z67: SBI Securities
A68: 44692 | B68: NSE | C68: Buy | D68: 4 | E68: 204.84 | F68: 819.37 | G68: ~ | H68: 0.82 | I68: 4.95 | J68: =Index!$C$2 -> 620.5 | K68: =IF(AND( C68="Buy", ISBLANK(T68), B68<>"DIV"), (1-Index!$F$2*2)*((J68*D68)-(E68*D68)), "") | L68: =IF(AND( C68="Buy", ISBLANK(T68), B68<>"DIV"), ((E68*D68)+K68), "") | M68: =IF(AND( C68="Buy", ISBLANK(T68), B68<>"DIV"), D68, "") | N68: =IF(AND( C68="Buy", ISBLANK(T68), B68<>"DIV", NOW()-A68 < 365), (1-Index!$F$2*2)*((J68*D68)-(E68*D68)), "") | O68: =IF(AND( C68="Buy", ISBLANK(T68), B68<>"DIV", NOW()-A68 < 365), ((E68*D68)+N68), "") | P68: =IF(AND( C68="Buy", ISBLANK(T68), B68<>"DIV", NOW()-A68 < 365), D68, "") | Q68: =IF(AND( C68="Buy", ISBLANK(T68), B68<>"DIV", NOW()-A68 > 365), (J68*D68)-(E68*D68)-(2*sum(H68:I68)), "") | R68: =IF(AND( C68="Buy", ISBLANK(T68), B68<>"DIV", NOW()-A68 > 365), ((E68*D68)+Q68), "") | S68: =IF(AND( C68="Buy", ISBLANK(T68), B68<>"DIV", NOW()-A68 > 365), D68, "") | T68: 346.92 | U68: 45583 | V68: =D68 -> 4 | W68: =(1-Index!$F$2*2)*((T68*D68)-(E68*D68)) -> 560.36352 | X68: =((E68*D68)+W68) -> 1379.7235 | Y68: =if(B68="DIV", F68,"") | Z68: SBI Securities
A69: 44692 | B69: NSE | C69: Buy | D69: 6 | E69: 204.84 | F69: 1229.05 | G69: ~ | H69: 1.23 | I69: 7.42 | J69: =Index!$C$2 -> 620.5 | K69: =IF(AND( C69="Buy", ISBLANK(T69), B69<>"DIV"), (1-Index!$F$2*2)*((J69*D69)-(E69*D69)), "") | L69: =IF(AND( C69="Buy", ISBLANK(T69), B69<>"DIV"), ((E69*D69)+K69), "") | M69: =IF(AND( C69="Buy", ISBLANK(T69), B69<>"DIV"), D69, "") | N69: =IF(AND( C69="Buy", ISBLANK(T69), B69<>"DIV", NOW()-A69 < 365), (1-Index!$F$2*2)*((J69*D69)-(E69*D69)), "") | O69: =IF(AND( C69="Buy", ISBLANK(T69), B69<>"DIV", NOW()-A69 < 365), ((E69*D69)+N69), "") | P69: =IF(AND( C69="Buy", ISBLANK(T69), B69<>"DIV", NOW()-A69 < 365), D69, "") | Q69: =IF(AND( C69="Buy", ISBLANK(T69), B69<>"DIV", NOW()-A69 > 365), (J69*D69)-(E69*D69)-(2*sum(H69:I69)), "") | R69: =IF(AND( C69="Buy", ISBLANK(T69), B69<>"DIV", NOW()-A69 > 365), ((E69*D69)+Q69), "") | S69: =IF(AND( C69="Buy", ISBLANK(T69), B69<>"DIV", NOW()-A69 > 365), D69, "") | T69: 326.02 | U69: 45565 | V69: =D69 -> 6 | W69: =(1-Index!$F$2*2)*((T69*D69)-(E69*D69)) -> 716.90088 | X69: =((E69*D69)+W69) -> 1945.9409 | Y69: =if(B69="DIV", F69,"") | Z69: SBI Securities
A70: 44692 | B70: NSE | C70: Buy | D70: 24 | E70: 204.89 | F70: 4917.43 | G70: ~ | H70: 4.92 | I70: 29.71 | J70: =Index!$C$2 -> 620.5 | K70: =IF(AND( C70="Buy", ISBLANK(T70), B70<>"DIV"), (1-Index!$F$2*2)*((J70*D70)-(E70*D70)), "") | L70: =IF(AND( C70="Buy", ISBLANK(T70), B70<>"DIV"), ((E70*D70)+K70), "") | M70: =IF(AND( C70="Buy", ISBLANK(T70), B70<>"DIV"), D70, "") | N70: =IF(AND( C70="Buy", ISBLANK(T70), B70<>"DIV", NOW()-A70 < 365), (1-Index!$F$2*2)*((J70*D70)-(E70*D70)), "") | O70: =IF(AND( C70="Buy", ISBLANK(T70), B70<>"DIV", NOW()-A70 < 365), ((E70*D70)+N70), "") | P70: =IF(AND( C70="Buy", ISBLANK(T70), B70<>"DIV", NOW()-A70 < 365), D70, "") | Q70: =IF(AND( C70="Buy", ISBLANK(T70), B70<>"DIV", NOW()-A70 > 365), (J70*D70)-(E70*D70)-(2*sum(H70:I70)), "") | R70: =IF(AND( C70="Buy", ISBLANK(T70), B70<>"DIV", NOW()-A70 > 365), ((E70*D70)+Q70), "") | S70: =IF(AND( C70="Buy", ISBLANK(T70), B70<>"DIV", NOW()-A70 > 365), D70, "") | T70: 346.92 | U70: 45583 | V70: =D70 -> 24 | W70: =(1-Index!$F$2*2)*((T70*D70)-(E70*D70)) -> 3360.9979 | X70: =((E70*D70)+W70) -> 8278.3579 | Y70: =if(B70="DIV", F70,"") | Z70: SBI Securities
A71: 44692 | B71: NSE | C71: Buy | D71: 7 | E71: 204.89 | F71: 1434.24 | G71: ~ | H71: 1.43 | I71: 8.66 | J71: =Index!$C$2 -> 620.5 | K71: =IF(AND( C71="Buy", ISBLANK(T71), B71<>"DIV"), (1-Index!$F$2*2)*((J71*D71)-(E71*D71)), "") | L71: =IF(AND( C71="Buy", ISBLANK(T71), B71<>"DIV"), ((E71*D71)+K71), "") | M71: =IF(AND( C71="Buy", ISBLANK(T71), B71<>"DIV"), D71, "") | N71: =IF(AND( C71="Buy", ISBLANK(T71), B71<>"DIV", NOW()-A71 < 365), (1-Index!$F$2*2)*((J71*D71)-(E71*D71)), "") | O71: =IF(AND( C71="Buy", ISBLANK(T71), B71<>"DIV", NOW()-A71 < 365), ((E71*D71)+N71), "") | P71: =IF(AND( C71="Buy", ISBLANK(T71), B71<>"DIV", NOW()-A71 < 365), D71, "") | Q71: =IF(AND( C71="Buy", ISBLANK(T71), B71<>"DIV", NOW()-A71 > 365), (J71*D71)-(E71*D71)-(2*sum(H71:I71)), "") | R71: =IF(AND( C71="Buy", ISBLANK(T71), B71<>"DIV", NOW()-A71 > 365), ((E71*D71)+Q71), "") | S71: =IF(AND( C71="Buy", ISBLANK(T71), B71<>"DIV", NOW()-A71 > 365), D71, "") | T71: 346.92 | U71: 45583 | V71: =D71 -> 7 | W71: =(1-Index!$F$2*2)*((T71*D71)-(E71*D71)) -> 980.29106 | X71: =((E71*D71)+W71) -> 2414.5211 | Y71: =if(B71="DIV", F71,"") | Z71: SBI Securities
A72: 44692 | B72: NSE | C72: Buy | D72: 11 | E72: 204.85 | F72: 2253.3 | G72: ~ | H72: 2.26 | I72: 13.64 | J72: =Index!$C$2 -> 620.5 | K72: =IF(AND( C72="Buy", ISBLANK(T72), B72<>"DIV"), (1-Index!$F$2*2)*((J72*D72)-(E72*D72)), "") | L72: =IF(AND( C72="Buy", ISBLANK(T72), B72<>"DIV"), ((E72*D72)+K72), "") | M72: =IF(AND( C72="Buy", ISBLANK(T72), B72<>"DIV"), D72, "") | N72: =IF(AND( C72="Buy", ISBLANK(T72), B72<>"DIV", NOW()-A72 < 365), (1-Index!$F$2*2)*((J72*D72)-(E72*D72)), "") | O72: =IF(AND( C72="Buy", ISBLANK(T72), B72<>"DIV", NOW()-A72 < 365), ((E72*D72)+N72), "") | P72: =IF(AND( C72="Buy", ISBLANK(T72), B72<>"DIV", NOW()-A72 < 365), D72, "") | Q72: =IF(AND( C72="Buy", ISBLANK(T72), B72<>"DIV", NOW()-A72 > 365), (J72*D72)-(E72*D72)-(2*sum(H72:I72)), "") | R72: =IF(AND( C72="Buy", ISBLANK(T72), B72<>"DIV", NOW()-A72 > 365), ((E72*D72)+Q72), "") | S72: =IF(AND( C72="Buy", ISBLANK(T72), B72<>"DIV", NOW()-A72 > 365), D72, "") | T72: 346.92 | U72: 45583 | V72: =D72 -> 11 | W72: =(1-Index!$F$2*2)*((T72*D72)-(E72*D72)) -> 1540.8912 | X72: =((E72*D72)+W72) -> 3794.2412 | Y72: =if(B72="DIV", F72,"") | Z72: SBI Securities
A73: 44692 | B73: NSE | C73: Buy | D73: 42 | E73: 204.84 | F73: 8603.46 | G73: ~ | H73: 8.61 | I73: 52.05 | J73: =Index!$C$2 -> 620.5 | K73: =IF(AND( C73="Buy", ISBLANK(T73), B73<>"DIV"), (1-Index!$F$2*2)*((J73*D73)-(E73*D73)), "") | L73: =IF(AND( C73="Buy", ISBLANK(T73), B73<>"DIV"), ((E73*D73)+K73), "") | M73: =IF(AND( C73="Buy", ISBLANK(T73), B73<>"DIV"), D73, "") | N73: =IF(AND( C73="Buy", ISBLANK(T73), B73<>"DIV", NOW()-A73 < 365), (1-Index!$F$2*2)*((J73*D73)-(E73*D73)), "") | O73: =IF(AND( C73="Buy", ISBLANK(T73), B73<>"DIV", NOW()-A73 < 365), ((E73*D73)+N73), "") | P73: =IF(AND( C73="Buy", ISBLANK(T73), B73<>"DIV", NOW()-A73 < 365), D73, "") | Q73: =IF(AND( C73="Buy", ISBLANK(T73), B73<>"DIV", NOW()-A73 > 365), (J73*D73)-(E73*D73)-(2*sum(H73:I73)), "") | R73: =IF(AND( C73="Buy", ISBLANK(T73), B73<>"DIV", NOW()-A73 > 365), ((E73*D73)+Q73), "") | S73: =IF(AND( C73="Buy", ISBLANK(T73), B73<>"DIV", NOW()-A73 > 365), D73, "") | T73: 346.92 | U73: 45583 | V73: =D73 -> 42 | W73: =(1-Index!$F$2*2)*((T73*D73)-(E73*D73)) -> 5883.817 | X73: =((E73*D73)+W73) -> 14487.097 | Y73: =if(B73="DIV", F73,"") | Z73: SBI Securities
...
