Workbook

Sheet Index
B2: Current Price | C2: =IFERROR(__xludf.DUMMYFUNCTION("GOOGLEFINANCE(""NSE:AVANTIFEED"", ""price"")"),1191.25) -> 1191.25
B4: UnRealised
B6: Gain | C6: =sum('Trading History'!J4:J1003) -> #REF! | E6: ST Gain | F6: =sum('Trading History'!O4:O1003) -> 0 | H6: LT Gain | I6: =sum('Trading History'!T4:T1003) -> #REF! | K6: Gain | L6: =sum('Trading History'!AB4:AB1003) -> 38577.883
B7: Units | C7: =sum('Trading History'!L4:L1003) -> 50 | E7: ST Units | F7: =sum('Trading History'!Q4:Q1003) -> 0 | H7: LT Units | I7: =sum('Trading History'!V4:V1003) -> 50 | K7: Units | L7: =sum('Trading History'!AA4:AA1003) -> 341
B8: Gross | C8: =sum('Trading History'!K4:K1003) -> #REF! | E8: ST Gross | F8: =sum('Trading History'!P4:P1003) -> 0 | H8: LT Gross | I8: =sum('Trading History'!U4:U1003) -> #REF! | K8: Gross | L8: =sum('Trading History'!AC4:AC1003) -> 179246.8
B9: Avg % | C9: =Index!C6/(Index!C7*Index!$C$2) -> #REF! | E9: ST Avg % | F9: =IFERROR(Index!F6/(Index!F7*Index!$C$2), 0) -> 0 | H9: LT Avg % | I9: =IFERROR(Index!I6/(Index!I7*Index!$C$2), 0) -> 0 | K9: Avg % | L9: =IFERROR(Index!L6/(Index!L7*AVERAGE('Trading History'!Y4:Y1003)),0) -> 0.21829844
B10: TPF | C10: =AVERAGE('Trading History'!M4:M1003) -> #REF! | E10: ST TPF | F10: =IFERROR(AVERAGE('Trading History'!R4:R1003), 0) -> 0 | H10: LT TPF | I10: =IFERROR(AVERAGE('Trading History'!W4:W1003), 0) -> 0 | K10: TPF | L10: =IFERROR(AVERAGE('Trading History'!AD4:AD1003), 0) -> 0.58361894
B11: UPF | C11: =AVERAGE('Trading History'!N4:N1003) -> #REF! | E11: ST UPF | F11: =IFERROR(AVERAGE('Trading History'!S4:S1003), 0) -> 0 | H11: LT UPF | I11: =IFERROR(AVERAGE('Trading History'!X4:X1003), 0) -> 0 | K11: Invested | L11: =Index!L8-Index!L6 -> 140668.91
B12: Invested | C12: =Index!C8-Index!C6 -> #REF! | E12: ST Invested | F12: =Index!F8-Index!F6 -> 0 | H12: LT Invested | I12: =Index!I8-Index!I6 -> #REF! | K12: Dividends | L12: =SUMIF('Trading History'!B4:B1003,"DIV",'Trading History'!AE:AE) -> 0

Sheet Trading History
J2: UnRealised | Y2: Realised
J3: Total | O3: Short Term | T3: Long Term
A4: DATE | B4: EXCH | C4: ACTION | D4: QTY | E4: PRICE | F4: COST | G4: REMARKS | H4: STT | I4: ADD CHRG | J4: Gain | K4: Gross | L4: Units | M4: TPF | N4: UPF | O4: Gain | P4: Gross | Q4: Units | R4: TPF | S4: UPF | T4: Gain | U4: Gross | V4: Units | W4: TPF | X4: UPF | Y4: Price | Z4: Date | AA4: Units | AB4: Gain | AC4: Gross | AD4: TPF | AE4: DIV | AF4: Broker
A5: 45282 | B5: NSE | C5: Buy | D5: 10 | E5: 399.296 | F5: 4021.34 | G5: ~ | H5: 3.99 | I5: 24.35 | J5: =IF(AND( C5="Buy", ISBLANK(Y5), B5<>"DIV"), (#REF!*D5)-(E5*D5), "") -> #REF! | K5: =IF(AND( C5="Buy", ISBLANK(Y5), B5<>"DIV"), #REF!*D5, "") -> #REF! | L5: =IF(AND( C5="Buy", ISBLANK(Y5), B5<>"DIV"), D5, "") -> 10 | M5: =IF(AND(B5<>"DIV", C5="Buy", ISBLANK(Y5)), J5/(NOW()-A5),"") -> #REF! | N5: =IF(AND(B5<>"DIV", C5="Buy", ISBLANK(Y5)), J5/D5,"") -> #REF! | O5: =IF(AND( C5="Buy", ISBLANK(Y5), B5<>"DIV", NOW()-A5 < 365), (#REF!*D5)-(E5*D5), "") | P5: =IF(AND( C5="Buy", ISBLANK(Y5), B5<>"DIV", NOW()-A5 < 365), #REF!*D5, "") | Q5: =IF(AND( C5="Buy", ISBLANK(Y5), B5<>"DIV", NOW()-A5 < 365), D5, "") | R5: =IF(AND(B5<>"DIV", C5="Buy", ISBLANK(Y5), NOW()-A5 < 365), J5/(NOW()-A5),"") | S5: =IF(AND(B5<>"DIV", C5="Buy", ISBLANK(Y5), NOW()-A5 < 365), J5/D5,"") | T5: =IF(AND( C5="Buy", ISBLANK(Y5), B5<>"DIV", NOW()-A5 > 365), (#REF!*D5)-(E5*D5), "") -> #REF! | U5: =IF(AND( C5="Buy", ISBLANK(Y5), B5<>"DIV", NOW()-A5 > 365), #REF!*D5, "") -> #REF! | V5: =IF(AND( C5="Buy", ISBLANK(Y5), B5<>"DIV", NOW()-A5 > 365), D5, "") -> 10 | W5: =IF(AND(B5<>"DIV", C5="Buy", ISBLANK(Y5), NOW()-A5 > 365), J5/(NOW()-A5),"") -> #REF! | X5: =IF(AND(B5<>"DIV", C5="Buy", ISBLANK(Y5), NOW()-A5 > 365), J5/D5,"") -> #REF! | AE5: =if(B5="DIV", F5,"") | AF5: SBI Securities
A6: 45278 | B6: NSE | C6: Buy | D6: 10 | E6: 396.805 | F6: 3996.05 | G6: ~ | H6: 3.96 | I6: 24.09 | J6: =IF(AND( C6="Buy", ISBLANK(Y6), B6<>"DIV"), (#REF!*D6)-(E6*D6), "") -> #REF! | K6: =IF(AND( C6="Buy", ISBLANK(Y6), B6<>"DIV"), #REF!*D6, "") -> #REF! | L6: =IF(AND( C6="Buy", ISBLANK(Y6), B6<>"DIV"), D6, "") -> 10 | M6: =IF(AND(B6<>"DIV", C6="Buy", ISBLANK(Y6)), J6/(NOW()-A6),"") -> #REF! | N6: =IF(AND(B6<>"DIV", C6="Buy", ISBLANK(Y6)), J6/D6,"") -> #REF! | O6: =IF(AND( C6="Buy", ISBLANK(Y6), B6<>"DIV", NOW()-A6 < 365), (#REF!*D6)-(E6*D6), "") | P6: =IF(AND( C6="Buy", ISBLANK(Y6), B6<>"DIV", NOW()-A6 < 365), #REF!*D6, "") | Q6: =IF(AND( C6="Buy", ISBLANK(Y6), B6<>"DIV", NOW()-A6 < 365), D6, "") | R6: =IF(AND(B6<>"DIV", C6="Buy", ISBLANK(Y6), NOW()-A6 < 365), J6/(NOW()-A6),"") | S6: =IF(AND(B6<>"DIV", C6="Buy", ISBLANK(Y6), NOW()-A6 < 365), J6/D6,"") | T6: =IF(AND( C6="Buy", ISBLANK(Y6), B6<>"DIV", NOW()-A6 > 365), (#REF!*D6)-(E6*D6), "") -> #REF! | U6: =IF(AND( C6="Buy", ISBLANK(Y6), B6<>"DIV", NOW()-A6 > 365), #REF!*D6, "") -> #REF! | V6: =IF(AND( C6="Buy", ISBLANK(Y6), B6<>"DIV", NOW()-A6 > 365), D6, "") -> 10 | W6: =IF(AND(B6<>"DIV", C6="Buy", ISBLANK(Y6), NOW()-A6 > 365), J6/(NOW()-A6),"") -> #REF! | X6: =IF(AND(B6<>"DIV", C6="Buy", ISBLANK(Y6), NOW()-A6 > 365), J6/D6,"") -> #REF! | AE6: =if(B6="DIV", F6,"") | AF6: SBI Securities
A7: 45258 | B7: NSE | C7: Buy | D7: 7 | E7: 396.4 | F7: 2794.47 | G7: ~ | H7: 2.77 | I7: 16.9 | J7: =IF(AND( C7="Buy", ISBLANK(Y7), B7<>"DIV"), (#REF!*D7)-(E7*D7), "") -> #REF! | K7: =IF(AND( C7="Buy", ISBLANK(Y7), B7<>"DIV"), #REF!*D7, "") -> #REF! | L7: =IF(AND( C7="Buy", ISBLANK(Y7), B7<>"DIV"), D7, "") -> 7 | M7: =IF(AND(B7<>"DIV", C7="Buy", ISBLANK(Y7)), J7/(NOW()-A7),"") -> #REF! | N7: =IF(AND(B7<>"DIV", C7="Buy", ISBLANK(Y7)), J7/D7,"") -> #REF! | O7: =IF(AND( C7="Buy", ISBLANK(Y7), B7<>"DIV", NOW()-A7 < 365), (#REF!*D7)-(E7*D7), "") | P7: =IF(AND( C7="Buy", ISBLANK(Y7), B7<>"DIV", NOW()-A7 < 365), #REF!*D7, "") | Q7: =IF(AND( C7="Buy", ISBLANK(Y7), B7<>"DIV", NOW()-A7 < 365), D7, "") | R7: =IF(AND(B7<>"DIV", C7="Buy", ISBLANK(Y7), NOW()-A7 < 365), J7/(NOW()-A7),"") | S7: =IF(AND(B7<>"DIV", C7="Buy", ISBLANK(Y7), NOW()-A7 < 365), J7/D7,"") | T7: =IF(AND( C7="Buy", ISBLANK(Y7), B7<>"DIV", NOW()-A7 > 365), (#REF!*D7)-(E7*D7), "") -> #REF! | U7: =IF(AND( C7="Buy", ISBLANK(Y7), B7<>"DIV", NOW()-A7 > 365), #REF!*D7, "") -> #REF! | V7: =IF(AND( C7="Buy", ISBLANK(Y7), B7<>"DIV", NOW()-A7 > 365), D7, "") -> 7 | W7: =IF(AND(B7<>"DIV", C7="Buy", ISBLANK(Y7), NOW()-A7 > 365), J7/(NOW()-A7),"") -> #REF! | X7: =IF(AND(B7<>"DIV", C7="Buy", ISBLANK(Y7), NOW()-A7 > 365), J7/D7,"") -> #REF! | AE7: =if(B7="DIV", F7,"") | AF7: SBI Securities
A8: 45225 | B8: NSE | C8: Buy | D8: 4 | E8: 389.605 | F8: 1569.46 | G8: ~ | H8: 1.57 | I8: 9.49 | J8: =IF(AND( C8="Buy", ISBLANK(Y8), B8<>"DIV"), (#REF!*D8)-(E8*D8), "") -> #REF! | K8: =IF(AND( C8="Buy", ISBLANK(Y8), B8<>"DIV"), #REF!*D8, "") -> #REF! | L8: =IF(AND( C8="Buy", ISBLANK(Y8), B8<>"DIV"), D8, "") -> 4 | M8: =IF(AND(B8<>"DIV", C8="Buy", ISBLANK(Y8)), J8/(NOW()-A8),"") -> #REF! | N8: =IF(AND(B8<>"DIV", C8="Buy", ISBLANK(Y8)), J8/D8,"") -> #REF! | O8: =IF(AND( C8="Buy", ISBLANK(Y8), B8<>"DIV", NOW()-A8 < 365), (#REF!*D8)-(E8*D8), "") | P8: =IF(AND( C8="Buy", ISBLANK(Y8), B8<>"DIV", NOW()-A8 < 365), #REF!*D8, "") | Q8: =IF(AND( C8="Buy", ISBLANK(Y8), B8<>"DIV", NOW()-A8 < 365), D8, "") | R8: =IF(AND(B8<>"DIV", C8="Buy", ISBLANK(Y8), NOW()-A8 < 365), J8/(NOW()-A8),"") | S8: =IF(AND(B8<>"DIV", C8="Buy", ISBLANK(Y8), NOW()-A8 < 365), J8/D8,"") | T8: =IF(AND( C8="Buy", ISBLANK(Y8), B8<>"DIV", NOW()-A8 > 365), (#REF!*D8)-(E8*D8), "") -> #REF! | U8: =IF(AND( C8="Buy", ISBLANK(Y8), B8<>"DIV", NOW()-A8 > 365), #REF!*D8, "") -> #REF! | V8: =IF(AND( C8="Buy", ISBLANK(Y8), B8<>"DIV", NOW()-A8 > 365), D8, "") -> 4 | W8: =IF(AND(B8<>"DIV", C8="Buy", ISBLANK(Y8), NOW()-A8 > 365), J8/(NOW()-A8),"") -> #REF! | X8: =IF(AND(B8<>"DIV", C8="Buy", ISBLANK(Y8), NOW()-A8 > 365), J8/D8,"") -> #REF! | AB8: =if(B8="DIV", F8,"") | AE8: =if(B8="DIV", F8,"") | AF8: SBI Securities
A9: 45183 | B9: NSE | C9: Sell | D9: 36 | E9: 456.38222 | F9: 16545.32 | G9: ~ | H9: 16.68 | I9: 98.8 | J9: =IF(AND( C9="Buy", ISBLANK(Y9), B9<>"DIV"), ((#REF!*D9)-(E9*D9)+I9), "") | K9: =IF(AND( C9="Buy", ISBLANK(Y9), B9<>"DIV"), #REF!*D9, "") | L9: =IF(AND( C9="Buy", ISBLANK(Y9), B9<>"DIV"), D9, "") | M9: =IF(AND(B9<>"DIV", C9="Buy", ISBLANK(Y9)), J9/(NOW()-A9),"") | N9: =IF(AND(B9<>"DIV", C9="Buy", ISBLANK(Y9)), J9/D9,"") | O9: =IF(AND( C9="Buy", ISBLANK(Y9), B9<>"DIV", NOW()-A9 < 365), (#REF!*D9)-(E9*D9), "") | P9: =IF(AND( C9="Buy", ISBLANK(Y9), B9<>"DIV", NOW()-A9 < 365), #REF!*D9, "") | Q9: =IF(AND( C9="Buy", ISBLANK(Y9), B9<>"DIV", NOW()-A9 < 365), D9, "") | R9: =IF(AND(B9<>"DIV", C9="Buy", ISBLANK(Y9), NOW()-A9 < 365), J9/(NOW()-A9),"") | S9: =IF(AND(B9<>"DIV", C9="Buy", ISBLANK(Y9), NOW()-A9 < 365), J9/D9,"") | T9: =IF(AND( C9="Buy", ISBLANK(Y9), B9<>"DIV", NOW()-A9 > 365), (#REF!*D9)-(E9*D9), "") | U9: =IF(AND( C9="Buy", ISBLANK(Y9), B9<>"DIV", NOW()-A9 > 365), #REF!*D9, "") | V9: =IF(AND( C9="Buy", ISBLANK(Y9), B9<>"DIV", NOW()-A9 > 365), D9, "") | W9: =IF(AND(B9<>"DIV", C9="Buy", ISBLANK(Y9), NOW()-A9 > 365), J9/(NOW()-A9),"") | X9: =IF(AND(B9<>"DIV", C9="Buy", ISBLANK(Y9), NOW()-A9 > 365), J9/D9,"") | AB9: =if(B9="DIV", F9,"") | AE9: =if(B9="DIV", F9,"") | AF9: SBI Securities
A10: 45181 | B10: BSE | C10: Buy | D10: 4 | E10: 430.9025 | F10: 1735.79 | G10: ~ | H10: 1.72 | I10: 10.47 | J10: =IF(AND( C10="Buy", ISBLANK(Y10), B10<>"DIV"), (#REF!*D10)-(E10*D10), "") -> #REF! | K10: =IF(AND( C10="Buy", ISBLANK(Y10), B10<>"DIV"), #REF!*D10, "") -> #REF! | L10: =IF(AND( C10="Buy", ISBLANK(Y10), B10<>"DIV"), D10, "") -> 4 | M10: =IF(AND(B10<>"DIV", C10="Buy", ISBLANK(Y10)), J10/(NOW()-A10),"") -> #REF! | N10: =IF(AND(B10<>"DIV", C10="Buy", ISBLANK(Y10)), J10/D10,"") -> #REF! | O10: =IF(AND( C10="Buy", ISBLANK(Y10), B10<>"DIV", NOW()-A10 < 365), (#REF!*D10)-(E10*D10), "") | P10: =IF(AND( C10="Buy", ISBLANK(Y10), B10<>"DIV", NOW()-A10 < 365), #REF!*D10, "") | Q10: =IF(AND( C10="Buy", ISBLANK(Y10), B10<>"DIV", NOW()-A10 < 365), D10, "") | R10: =IF(AND(B10<>"DIV", C10="Buy", ISBLANK(Y10), NOW()-A10 < 365), J10/(NOW()-A10),"") | S10: =IF(AND(B10<>"DIV", C10="Buy", ISBLANK(Y10), NOW()-A10 < 365), J10/D10,"") | T10: =IF(AND( C10="Buy", ISBLANK(Y10), B10<>"DIV", NOW()-A10 > 365), (#REF!*D10)-(E10*D10), "") -> #REF! | U10: =IF(AND( C10="Buy", ISBLANK(Y10), B10<>"DIV", NOW()-A10 > 365), #REF!*D10, "") -> #REF! | V10: =IF(AND( C10="Buy", ISBLANK(Y10), B10<>"DIV", NOW()-A10 > 365), D10, "") -> 4 | W10: =IF(AND(B10<>"DIV", C10="Buy", ISBLANK(Y10), NOW()-A10 > 365), J10/(NOW()-A10),"") -> #REF! | X10: =IF(AND(B10<>"DIV", C10="Buy", ISBLANK(Y10), NOW()-A10 > 365), J10/D10,"") -> #REF! | AB10: =if(B10="DIV", F10,"") | AE10: =if(B10="DIV", F10,"") | AF10: SBI Securities
A11: 45180 | B11: NSE | C11: Buy | D11: 10 | E11: 441.304 | F11: 4444.36 | G11: ~ | H11: 4.4 | I11: 26.96 | J11: =IF(AND( C11="Buy", ISBLANK(Y11), B11<>"DIV"), (#REF!*D11)-(E11*D11), "") -> #REF! | K11: =IF(AND( C11="Buy", ISBLANK(Y11), B11<>"DIV"), #REF!*D11, "") -> #REF! | L11: =IF(AND( C11="Buy", ISBLANK(Y11), B11<>"DIV"), D11, "") -> 10 | M11: =IF(AND(B11<>"DIV", C11="Buy", ISBLANK(Y11)), J11/(NOW()-A11),"") -> #REF! | N11: =IF(AND(B11<>"DIV", C11="Buy", ISBLANK(Y11)), J11/D11,"") -> #REF! | O11: =IF(AND( C11="Buy", ISBLANK(Y11), B11<>"DIV", NOW()-A11 < 365), (#REF!*D11)-(E11*D11), "") | P11: =IF(AND( C11="Buy", ISBLANK(Y11), B11<>"DIV", NOW()-A11 < 365), #REF!*D11, "") | Q11: =IF(AND( C11="Buy", ISBLANK(Y11), B11<>"DIV", NOW()-A11 < 365), D11, "") | R11: =IF(AND(B11<>"DIV", C11="Buy", ISBLANK(Y11), NOW()-A11 < 365), J11/(NOW()-A11),"") | S11: =IF(AND(B11<>"DIV", C11="Buy", ISBLANK(Y11), NOW()-A11 < 365), J11/D11,"") | T11: =IF(AND( C11="Buy", ISBLANK(Y11), B11<>"DIV", NOW()-A11 > 365), (#REF!*D11)-(E11*D11), "") -> #REF! | U11: =IF(AND( C11="Buy", ISBLANK(Y11), B11<>"DIV", NOW()-A11 > 365), #REF!*D11, "") -> #REF! | V11: =IF(AND( C11="Buy", ISBLANK(Y11), B11<>"DIV", NOW()-A11 > 365), D11, "") -> 10 | W11: =IF(AND(B11<>"DIV", C11="Buy", ISBLANK(Y11), NOW()-A11 > 365), J11/(NOW()-A11),"") -> #REF! | X11: =IF(AND(B11<>"DIV", C11="Buy", ISBLANK(Y11), NOW()-A11 > 365), J11/D11,"") -> #REF! | AE11: =if(B11="DIV", F11,"") | AF11: SBI Securities
A12: 45162 | B12: BSE | C12: Buy | D12: 5 | E12: 430 | F12: 2165.25 | G12: ~ | H12: 2.13 | I12: 13.12 | J12: =IF(AND( C12="Buy", ISBLANK(Y12), B12<>"DIV"), (#REF!*D12)-(E12*D12), "") -> #REF! | K12: =IF(AND( C12="Buy", ISBLANK(Y12), B12<>"DIV"), #REF!*D12, "") -> #REF! | L12: =IF(AND( C12="Buy", ISBLANK(Y12), B12<>"DIV"), D12, "") -> 5 | M12: =IF(AND(B12<>"DIV", C12="Buy", ISBLANK(Y12)), J12/(NOW()-A12),"") -> #REF! | N12: =IF(AND(B12<>"DIV", C12="Buy", ISBLANK(Y12)), J12/D12,"") -> #REF! | O12: =IF(AND( C12="Buy", ISBLANK(Y12), B12<>"DIV", NOW()-A12 < 365), (#REF!*D12)-(E12*D12), "") | P12: =IF(AND( C12="Buy", ISBLANK(Y12), B12<>"DIV", NOW()-A12 < 365), #REF!*D12, "") | Q12: =IF(AND( C12="Buy", ISBLANK(Y12), B12<>"DIV", NOW()-A12 < 365), D12, "") | R12: =IF(AND(B12<>"DIV", C12="Buy", ISBLANK(Y12), NOW()-A12 < 365), J12/(NOW()-A12),"") | S12: =IF(AND(B12<>"DIV", C12="Buy", ISBLANK(Y12), NOW()-A12 < 365), J12/D12,"") | T12: =IF(AND( C12="Buy", ISBLANK(Y12), B12<>"DIV", NOW()-A12 > 365), (#REF!*D12)-(E12*D12), "") -> #REF! | U12: =IF(AND( C12="Buy", ISBLANK(Y12), B12<>"DIV", NOW()-A12 > 365), #REF!*D12, "") -> #REF! | V12: =IF(AND( C12="Buy", ISBLANK(Y12), B12<>"DIV", NOW()-A12 > 365), D12, "") -> 5 | W12: =IF(AND(B12<>"DIV", C12="Buy", ISBLANK(Y12), NOW()-A12 > 365), J12/(NOW()-A12),"") -> #REF! | X12: =IF(AND(B12<>"DIV", C12="Buy", ISBLANK(Y12), NOW()-A12 > 365), J12/D12,"") -> #REF! | AE12: =if(B12="DIV", F12,"") | AF12: SBI Securities
A13: 45141 | B13: DIV | C13: Buy | D13: 26 | E13: 6.25 | F13: 162.5 | G13: Annual-Dividend of Rs.6.2500/- per share on Ex-Date: 03-AUG-2023 | H13: 0 | I13: 0 | J13: =IF(AND( C13="Buy", ISBLANK(Y13), B13<>"DIV"), ((#REF!*D13)-(E13*D13)+I13), "") | K13: =IF(AND( C13="Buy", ISBLANK(Y13), B13<>"DIV"), #REF!*D13, "") | L13: =IF(AND( C13="Buy", ISBLANK(Y13), B13<>"DIV"), D13, "") | M13: =IF(AND(B13<>"DIV", C13="Buy", ISBLANK(Y13)), J13/(NOW()-A13),"") | O13: =if(C13="DIV", G13,"") | P13: =if(D13="DIV", H13,"") | Q13: =if(E13="DIV", I13,"") | R13: =if(#REF!="DIV", J13,"") -> #REF! | S13: =if(F13="DIV", K13,"") | T13: =if(G13="DIV", L13,"") | U13: =if(H13="DIV", M13,"") | V13: =if(I13="DIV", N13,"") | W13: =if(J13="DIV", Y13,"") | X13: =if(K13="DIV", Z13,"") | AE13: =if(B13="DIV", F13,"") -> 162.5 | AF13: SBI Securities
A14: 45141 | B14: DIV | C14: Buy | D14: 10 | E14: 6.25 | F14: 62.5 | G14: Annual-Dividend of Rs.6.2500/- per share on Ex-Date: 03-AUG-2023 | H14: 0 | I14: 0 | J14: =IF(AND( C14="Buy", ISBLANK(Y14), B14<>"DIV"), ((#REF!*D14)-(E14*D14)+I14), "") | K14: =IF(AND( C14="Buy", ISBLANK(Y14), B14<>"DIV"), #REF!*D14, "") | L14: =IF(AND( C14="Buy", ISBLANK(Y14), B14<>"DIV"), D14, "") | M14: =IF(AND(B14<>"DIV", C14="Buy", ISBLANK(Y14)), J14/(NOW()-A14),"") | O14: =if(C14="DIV", G14,"") | P14: =if(D14="DIV", H14,"") | Q14: =if(E14="DIV", I14,"") | R14: =if(#REF!="DIV", J14,"") -> #REF! | S14: =if(F14="DIV", K14,"") | T14: =if(G14="DIV", L14,"") | U14: =if(H14="DIV", M14,"") | V14: =if(I14="DIV", N14,"") | W14: =if(J14="DIV", Y14,"") | X14: =if(K14="DIV", Z14,"") | AE14: =if(B14="DIV", F14,"") -> 62.5 | AF14: SBI Securities
A15: 45131 | B15: NSE | C15: Buy | D15: 4 | E15: 401.95 | F15: 1619.16 | G15: ~ | H15: 1.6 | I15: 9.76 | J15: =IF(AND( C15="Buy", ISBLANK(Y15), B15<>"DIV"), ((#REF!*D15)-(E15*D15)+I15), "") | K15: =IF(AND( C15="Buy", ISBLANK(Y15), B15<>"DIV"), #REF!*D15, "") | L15: =IF(AND( C15="Buy", ISBLANK(Y15), B15<>"DIV"), D15, "") | M15: =IF(AND(B15<>"DIV", C15="Buy", ISBLANK(Y15)), J15/(NOW()-A15),"") | O15: =if(C15="DIV", G15,"") | P15: =if(D15="DIV", H15,"") | Q15: =if(E15="DIV", I15,"") | R15: =if(#REF!="DIV", J15,"") -> #REF! | S15: =if(F15="DIV", K15,"") | T15: =if(G15="DIV", L15,"") | U15: =if(H15="DIV", M15,"") | V15: =if(I15="DIV", N15,"") | W15: =if(J15="DIV", Y15,"") | X15: =if(K15="DIV", Z15,"") | Y15: 456.38222 | Z15: 45183 | AA15: =D15 -> 4 | AB15: =(Y15-E15)*D15-H15-I15 -> 206.36889 | AC15: =Y15*D15 -> 1825.5289 | AD15: =AB15/(NOW()-Z15) -> 0.233863 | AE15: =if(B15="DIV", F15,"") | AF15: SBI Securities
A16: 45131 | B16: NSE | C16: Buy | D16: 2 | E16: 401.955 | F16: 809.59 | G16: ~ | H16: 0.8 | I16: 4.89 | J16: =IF(AND( C16="Buy", ISBLANK(Y16), B16<>"DIV"), ((#REF!*D16)-(E16*D16)+I16), "") | K16: =IF(AND( C16="Buy", ISBLANK(Y16), B16<>"DIV"), #REF!*D16, "") | L16: =IF(AND( C16="Buy", ISBLANK(Y16), B16<>"DIV"), D16, "") | M16: =IF(AND(B16<>"DIV", C16="Buy", ISBLANK(Y16)), J16/(NOW()-A16),"") | O16: =if(C16="DIV", G16,"") | P16: =if(D16="DIV", H16,"") | Q16: =if(E16="DIV", I16,"") | R16: =if(#REF!="DIV", J16,"") -> #REF! | S16: =if(F16="DIV", K16,"") | T16: =if(G16="DIV", L16,"") | U16: =if(H16="DIV", M16,"") | V16: =if(I16="DIV", N16,"") | W16: =if(J16="DIV", Y16,"") | X16: =if(K16="DIV", Z16,"") | Y16: 456.38222 | Z16: 45183 | AA16: =D16 -> 2 | AB16: =(Y16-E16)*D16-H16-I16 -> 103.16444 | AC16: =Y16*D16 -> 912.76444 | AD16: =AB16/(NOW()-Z16) -> 0.11690884 | AE16: =if(B16="DIV", F16,"") | AF16: SBI Securities
A17: 45034 | B17: BSE | C17: Buy | D17: 8 | E17: 361.3 | F17: 2910.96 | G17: ~ | H17: 2.9 | I17: 17.66 | J17: =IF(AND( C17="Buy", ISBLANK(Y17), B17<>"DIV"), ((#REF!*D17)-(E17*D17)+I17), "") | K17: =IF(AND( C17="Buy", ISBLANK(Y17), B17<>"DIV"), #REF!*D17, "") | L17: =IF(AND( C17="Buy", ISBLANK(Y17), B17<>"DIV"), D17, "") | M17: =IF(AND(B17<>"DIV", C17="Buy", ISBLANK(Y17)), J17/(NOW()-A17),"") | O17: =if(C17="DIV", G17,"") | P17: =if(D17="DIV", H17,"") | Q17: =if(E17="DIV", I17,"") | R17: =if(#REF!="DIV", J17,"") -> #REF! | S17: =if(F17="DIV", K17,"") | T17: =if(G17="DIV", L17,"") | U17: =if(H17="DIV", M17,"") | V17: =if(I17="DIV", N17,"") | W17: =if(J17="DIV", Y17,"") | X17: =if(K17="DIV", Z17,"") | Y17: 456.38222 | Z17: 45183 | AA17: =D17 -> 8 | AB17: =(Y17-E17)*D17-H17-I17 -> 740.09778 | AC17: =Y17*D17 -> 3651.0578 | AD17: =AB17/(NOW()-Z17) -> 0.83869952 | AE17: =if(B17="DIV", F17,"") | AF17: SBI Securities
A18: 45034 | B18: BSE | C18: Buy | D18: 2 | E18: 361.45 | F18: 728.06 | G18: ~ | H18: 0.72 | I18: 4.44 | J18: =IF(AND( C18="Buy", ISBLANK(Y18), B18<>"DIV"), ((#REF!*D18)-(E18*D18)+I18), "") | K18: =IF(AND( C18="Buy", ISBLANK(Y18), B18<>"DIV"), #REF!*D18, "") | L18: =IF(AND( C18="Buy", ISBLANK(Y18), B18<>"DIV"), D18, "") | M18: =IF(AND(B18<>"DIV", C18="Buy", ISBLANK(Y18)), J18/(NOW()-A18),"") | O18: =if(C18="DIV", G18,"") | P18: =if(D18="DIV", H18,"") | Q18: =if(E18="DIV", I18,"") | R18: =if(#REF!="DIV", J18,"") -> #REF! | S18: =if(F18="DIV", K18,"") | T18: =if(G18="DIV", L18,"") | U18: =if(H18="DIV", M18,"") | V18: =if(I18="DIV", N18,"") | W18: =if(J18="DIV", Y18,"") | X18: =if(K18="DIV", Z18,"") | Y18: 456.38222 | Z18: 45183 | AA18: =D18 -> 2 | AB18: =(Y18-E18)*D18-H18-I18 -> 184.70444 | AC18: =Y18*D18 -> 912.76444 | AD18: =AB18/(NOW()-Z18) -> 0.20931225 | AE18: =if(B18="DIV", F18,"") | AF18: SBI Securities
A19: 44953 | B19: NSE | C19: Buy | D19: 1 | E19: 376.05 | F19: 378.72 | G19: ~ | H19: 0.38 | I19: 2.29 | J19: =IF(AND( C19="Buy", ISBLANK(Y19), B19<>"DIV"), ((#REF!*D19)-(E19*D19)+I19), "") | K19: =IF(AND( C19="Buy", ISBLANK(Y19), B19<>"DIV"), #REF!*D19, "") | L19: =IF(AND( C19="Buy", ISBLANK(Y19), B19<>"DIV"), D19, "") | M19: =IF(AND(B19<>"DIV", C19="Buy", ISBLANK(Y19)), J19/(NOW()-A19),"") | O19: =if(C19="DIV", G19,"") | P19: =if(D19="DIV", H19,"") | Q19: =if(E19="DIV", I19,"") | R19: =if(#REF!="DIV", J19,"") -> #REF! | S19: =if(F19="DIV", K19,"") | T19: =if(G19="DIV", L19,"") | U19: =if(H19="DIV", M19,"") | V19: =if(I19="DIV", N19,"") | W19: =if(J19="DIV", Y19,"") | X19: =if(K19="DIV", Z19,"") | Y19: 456.38222 | Z19: 45183 | AA19: =D19 -> 1 | AB19: =(Y19-E19)*D19-H19-I19 -> 77.662222 | AC19: =Y19*D19 -> 456.38222 | AD19: =AB19/(NOW()-Z19) -> 0.088009005 | AE19: =if(B19="DIV", F19,"") | AF19: SBI Securities
A20: 44953 | B20: NSE | C20: Buy | D20: 9 | E20: 376.04667 | F20: 3408.42 | G20: ~ | H20: 3.34 | I20: 20.63 | J20: =IF(AND( C20="Buy", ISBLANK(Y20), B20<>"DIV"), ((#REF!*D20)-(E20*D20)+I20), "") | K20: =IF(AND( C20="Buy", ISBLANK(Y20), B20<>"DIV"), #REF!*D20, "") | L20: =IF(AND( C20="Buy", ISBLANK(Y20), B20<>"DIV"), D20, "") | M20: =IF(AND(B20<>"DIV", C20="Buy", ISBLANK(Y20)), J20/(NOW()-A20),"") | O20: =if(C20="DIV", G20,"") | P20: =if(D20="DIV", H20,"") | Q20: =if(E20="DIV", I20,"") | R20: =if(#REF!="DIV", J20,"") -> #REF! | S20: =if(F20="DIV", K20,"") | T20: =if(G20="DIV", L20,"") | U20: =if(H20="DIV", M20,"") | V20: =if(I20="DIV", N20,"") | W20: =if(J20="DIV", Y20,"") | X20: =if(K20="DIV", Z20,"") | Y20: 456.38222 | Z20: 45183 | AA20: =D20 -> 9 | AB20: =(Y20-E20)*D20-H20-I20 -> 699.04999 | AC20: =Y20*D20 -> 4107.44 | AD20: =AB20/(NOW()-Z20) -> 0.79218303 | AE20: =if(B20="DIV", F20,"") | AF20: SBI Securities
A21: 44950 | B21: NSE | C21: Buy | D21: 10 | E21: 388.005 | F21: 3907.45 | G21: ~ | H21: 3.86 | I21: 23.59 | J21: =IF(AND( C21="Buy", ISBLANK(Y21), B21<>"DIV"), ((#REF!*D21)-(E21*D21)+I21), "") | K21: =IF(AND( C21="Buy", ISBLANK(Y21), B21<>"DIV"), #REF!*D21, "") | L21: =IF(AND( C21="Buy", ISBLANK(Y21), B21<>"DIV"), D21, "") | M21: =IF(AND(B21<>"DIV", C21="Buy", ISBLANK(Y21)), J21/(NOW()-A21),"") | O21: =if(C21="DIV", G21,"") | P21: =if(D21="DIV", H21,"") | Q21: =if(E21="DIV", I21,"") | R21: =if(#REF!="DIV", J21,"") -> #REF! | S21: =if(F21="DIV", K21,"") | T21: =if(G21="DIV", L21,"") | U21: =if(H21="DIV", M21,"") | V21: =if(I21="DIV", N21,"") | W21: =if(J21="DIV", Y21,"") | X21: =if(K21="DIV", Z21,"") | Y21: 456.38222 | Z21: 45183 | AA21: =D21 -> 10 | AB21: =(Y21-E21)*D21-H21-I21 -> 656.32222 | AC21: =Y21*D21 -> 4563.8222 | AD21: =AB21/(NOW()-Z21) -> 0.74376272 | AE21: =if(B21="DIV", F21,"") | AF21: SBI Securities
A22: 44232 | B22: NSE | C22: Sell | D22: 55 | E22: 508.53182 | F22: 28165.9 | H22: 28.33 | I22: 168.47 | J22: =IF(AND( C22="Buy", ISBLANK(Y22), B22<>"DIV"), ((#REF!*D22)-(E22*D22)+I22), "") | K22: =IF(AND( C22="Buy", ISBLANK(Y22), B22<>"DIV"), #REF!*D22, "") | L22: =IF(AND( C22="Buy", ISBLANK(Y22), B22<>"DIV"), D22, "") | M22: =IF(AND(B22<>"DIV", C22="Buy", ISBLANK(Y22)), J22/(NOW()-A22),"") | O22: =if(C22="DIV", G22,"") | P22: =if(D22="DIV", H22,"") | Q22: =if(E22="DIV", I22,"") | R22: =if(#REF!="DIV", J22,"") -> #REF! | S22: =if(F22="DIV", K22,"") | T22: =if(G22="DIV", L22,"") | U22: =if(H22="DIV", M22,"") | V22: =if(I22="DIV", N22,"") | W22: =if(J22="DIV", Y22,"") | X22: =if(K22="DIV", Z22,"") | AE22: =if(B22="DIV", F22,"") | AF22: SBI Securities
A23: 44228 | B23: NSE | C23: Sell | D23: 50 | E23: 514.3094 | F23: 25896.47 | H23: 26.08 | I23: 154.95 | J23: =IF(AND( C23="Buy", ISBLANK(Y23), B23<>"DIV"), ((#REF!*D23)-(E23*D23)+I23), "") | K23: =IF(AND( C23="Buy", ISBLANK(Y23), B23<>"DIV"), #REF!*D23, "") | L23: =IF(AND( C23="Buy", ISBLANK(Y23), B23<>"DIV"), D23, "") | M23: =IF(AND(B23<>"DIV", C23="Buy", ISBLANK(Y23)), J23/(NOW()-A23),"") | O23: =if(C23="DIV", G23,"") | P23: =if(D23="DIV", H23,"") | Q23: =if(E23="DIV", I23,"") | R23: =if(#REF!="DIV", J23,"") -> #REF! | S23: =if(F23="DIV", K23,"") | T23: =if(G23="DIV", L23,"") | U23: =if(H23="DIV", M23,"") | V23: =if(I23="DIV", N23,"") | W23: =if(J23="DIV", Y23,"") | X23: =if(K23="DIV", Z23,"") | AE23: =if(B23="DIV", F23,"") | AF23: SBI Securities
A24: 44152 | B24: NSE | C24: Buy | D24: 5 | E24: 484.596 | F24: 2439.72 | H24: 1.97 | I24: 14.75 | J24: =IF(AND( C24="Buy", ISBLANK(Y24), B24<>"DIV"), ((#REF!*D24)-(E24*D24)+I24), "") | K24: =IF(AND( C24="Buy", ISBLANK(Y24), B24<>"DIV"), #REF!*D24, "") | L24: =IF(AND( C24="Buy", ISBLANK(Y24), B24<>"DIV"), D24, "") | M24: =IF(AND(B24<>"DIV", C24="Buy", ISBLANK(Y24)), J24/(NOW()-A24),"") | O24: =if(C24="DIV", G24,"") | P24: =if(D24="DIV", H24,"") | Q24: =if(E24="DIV", I24,"") | R24: =if(#REF!="DIV", J24,"") -> #REF! | S24: =if(F24="DIV", K24,"") | T24: =if(G24="DIV", L24,"") | U24: =if(H24="DIV", M24,"") | V24: =if(I24="DIV", N24,"") | W24: =if(J24="DIV", Y24,"") | X24: =if(K24="DIV", Z24,"") | Y24: 508.53182 | Z24: 44232 | AA24: =D24 -> 5 | AB24: =(Y24-E24)*D24-H24-I24 -> 102.95909 | AC24: =Y24*D24 -> 2542.6591 | AD24: =AB24/(NOW()-Z24) -> 0.056156391 | AE24: =if(B24="DIV", F24,"") | AF24: SBI Securities
A25: 44089 | B25: NSE | C25: Sell | D25: 20 | E25: 532.7895 | F25: 10731.39 | H25: 10.56 | I25: 65.05 | J25: =IF(AND( C25="Buy", ISBLANK(Y25), B25<>"DIV"), ((#REF!*D25)-(E25*D25)+I25), "") | K25: =IF(AND( C25="Buy", ISBLANK(Y25), B25<>"DIV"), #REF!*D25, "") | L25: =IF(AND( C25="Buy", ISBLANK(Y25), B25<>"DIV"), D25, "") | M25: =IF(AND(B25<>"DIV", C25="Buy", ISBLANK(Y25)), J25/(NOW()-A25),"") | O25: =if(C25="DIV", G25,"") | P25: =if(D25="DIV", H25,"") | Q25: =if(E25="DIV", I25,"") | R25: =if(#REF!="DIV", J25,"") -> #REF! | S25: =if(F25="DIV", K25,"") | T25: =if(G25="DIV", L25,"") | U25: =if(H25="DIV", M25,"") | V25: =if(I25="DIV", N25,"") | W25: =if(J25="DIV", Y25,"") | X25: =if(K25="DIV", Z25,"") | AE25: =if(B25="DIV", F25,"") | AF25: SBI Securities
A26: 44063 | B26: DIV | C26: Buy | D26: 120 | E26: 0.09 | F26: 11.1 | G26: Dividend of Rs.0.0925/- per share on 20-AUG-2020 Final-Dividend of Rs.0.1000/- per share on Ex-Date: 20-AUG-2020 | H26: 0 | I26: 0 | J26: =IF(AND( C26="Buy", ISBLANK(Y26), B26<>"DIV"), ((#REF!*D26)-(E26*D26)+I26), "") | K26: =IF(AND( C26="Buy", ISBLANK(Y26), B26<>"DIV"), #REF!*D26, "") | L26: =IF(AND( C26="Buy", ISBLANK(Y26), B26<>"DIV"), D26, "") | M26: =IF(AND(B26<>"DIV", C26="Buy", ISBLANK(Y26)), J26/(NOW()-A26),"") | O26: =if(C26="DIV", G26,"") | P26: =if(D26="DIV", H26,"") | Q26: =if(E26="DIV", I26,"") | R26: =if(#REF!="DIV", J26,"") -> #REF! | S26: =if(F26="DIV", K26,"") | T26: =if(G26="DIV", L26,"") | U26: =if(H26="DIV", M26,"") | V26: =if(I26="DIV", N26,"") | W26: =if(J26="DIV", Y26,"") | X26: =if(K26="DIV", Z26,"") | AE26: =if(B26="DIV", F26,"") -> 11.1 | AF26: SBI Securities
A27: 44043 | B27: NSE | C27: Buy | D27: 10 | E27: 450.099 | F27: 4533.01 | H27: 4.57 | I27: 27.44 | J27: =IF(AND( C27="Buy", ISBLANK(Y27), B27<>"DIV"), ((#REF!*D27)-(E27*D27)+I27), "") | K27: =IF(AND( C27="Buy", ISBLANK(Y27), B27<>"DIV"), #REF!*D27, "") | L27: =IF(AND( C27="Buy", ISBLANK(Y27), B27<>"DIV"), D27, "") | M27: =IF(AND(B27<>"DIV", C27="Buy", ISBLANK(Y27)), J27/(NOW()-A27),"") | O27: =if(C27="DIV", G27,"") | P27: =if(D27="DIV", H27,"") | Q27: =if(E27="DIV", I27,"") | R27: =if(#REF!="DIV", J27,"") -> #REF! | S27: =if(F27="DIV", K27,"") | T27: =if(G27="DIV", L27,"") | U27: =if(H27="DIV", M27,"") | V27: =if(I27="DIV", N27,"") | W27: =if(J27="DIV", Y27,"") | X27: =if(K27="DIV", Z27,"") | Y27: 508.53182 | Z27: 44232 | AA27: =D27 -> 10 | AB27: =(Y27-E27)*D27-H27-I27 -> 552.31818 | AC27: =Y27*D27 -> 5085.3182 | AD27: =AB27/(NOW()-Z27) -> 0.30124776 | AE27: =if(B27="DIV", F27,"") | AF27: SBI Securities
A28: 44036 | B28: NSE | C28: Buy | D28: 5 | E28: 442.196 | F28: 2226.52 | H28: 2.23 | I28: 13.29 | J28: =IF(AND( C28="Buy", ISBLANK(Y28), B28<>"DIV"), ((#REF!*D28)-(E28*D28)+I28), "") | K28: =IF(AND( C28="Buy", ISBLANK(Y28), B28<>"DIV"), #REF!*D28, "") | L28: =IF(AND( C28="Buy", ISBLANK(Y28), B28<>"DIV"), D28, "") | M28: =IF(AND(B28<>"DIV", C28="Buy", ISBLANK(Y28)), J28/(NOW()-A28),"") | O28: =if(C28="DIV", G28,"") | P28: =if(D28="DIV", H28,"") | Q28: =if(E28="DIV", I28,"") | R28: =if(#REF!="DIV", J28,"") -> #REF! | S28: =if(F28="DIV", K28,"") | T28: =if(G28="DIV", L28,"") | U28: =if(H28="DIV", M28,"") | V28: =if(I28="DIV", N28,"") | W28: =if(J28="DIV", Y28,"") | X28: =if(K28="DIV", Z28,"") | Y28: 508.53182 | Z28: 44232 | AA28: =D28 -> 5 | AB28: =(Y28-E28)*D28-H28-I28 -> 316.15909 | AC28: =Y28*D28 -> 2542.6591 | AD28: =AB28/(NOW()-Z28) -> 0.17244085 | AE28: =if(B28="DIV", F28,"") | AF28: SBI Securities
A29: 43966 | B29: NSE | C29: Buy | D29: 5 | E29: 423.05 | F29: 2125.85 | H29: 0 | I29: 10.6 | J29: =IF(AND( C29="Buy", ISBLANK(Y29), B29<>"DIV"), ((#REF!*D29)-(E29*D29)+I29), "") | K29: =IF(AND( C29="Buy", ISBLANK(Y29), B29<>"DIV"), #REF!*D29, "") | L29: =IF(AND( C29="Buy", ISBLANK(Y29), B29<>"DIV"), D29, "") | M29: =IF(AND(B29<>"DIV", C29="Buy", ISBLANK(Y29)), J29/(NOW()-A29),"") | O29: =if(C29="DIV", G29,"") | P29: =if(D29="DIV", H29,"") | Q29: =if(E29="DIV", I29,"") | R29: =if(#REF!="DIV", J29,"") -> #REF! | S29: =if(F29="DIV", K29,"") | T29: =if(G29="DIV", L29,"") | U29: =if(H29="DIV", M29,"") | V29: =if(I29="DIV", N29,"") | W29: =if(J29="DIV", Y29,"") | X29: =if(K29="DIV", Z29,"") | Y29: 508.53182 | Z29: 44232 | AA29: =D29 -> 5 | AB29: =(Y29-E29)*D29-H29-I29 -> 416.80909 | AC29: =Y29*D29 -> 2542.6591 | AD29: =AB29/(NOW()-Z29) -> 0.22733781 | AE29: =if(B29="DIV", F29,"") | AF29: SBI Securities
A30: 43959 | B30: NSE | C30: Buy | D30: 10 | E30: 404.65 | F30: 4066.7 | H30: 0 | I30: 20.2 | J30: =IF(AND( C30="Buy", ISBLANK(Y30), B30<>"DIV"), ((#REF!*D30)-(E30*D30)+I30), "") | K30: =IF(AND( C30="Buy", ISBLANK(Y30), B30<>"DIV"), #REF!*D30, "") | L30: =IF(AND( C30="Buy", ISBLANK(Y30), B30<>"DIV"), D30, "") | M30: =IF(AND(B30<>"DIV", C30="Buy", ISBLANK(Y30)), J30/(NOW()-A30),"") | O30: =if(C30="DIV", G30,"") | P30: =if(D30="DIV", H30,"") | Q30: =if(E30="DIV", I30,"") | R30: =if(#REF!="DIV", J30,"") -> #REF! | S30: =if(F30="DIV", K30,"") | T30: =if(G30="DIV", L30,"") | U30: =if(H30="DIV", M30,"") | V30: =if(I30="DIV", N30,"") | W30: =if(J30="DIV", Y30,"") | X30: =if(K30="DIV", Z30,"") | Y30: 508.53182 | Z30: 44232 | AA30: =D30 -> 10 | AB30: =(Y30-E30)*D30-H30-I30 -> 1018.6182 | AC30: =Y30*D30 -> 5085.3182 | AD30: =AB30/(NOW()-Z30) -> 0.55557912 | AE30: =if(B30="DIV", F30,"") | AF30: SBI Securities
A31: 43956 | B31: NSE | C31: Buy | D31: 10 | E31: 406.4 | F31: 4084.3 | H31: 0 | I31: 20.3 | J31: =IF(AND( C31="Buy", ISBLANK(Y31), B31<>"DIV"), ((#REF!*D31)-(E31*D31)+I31), "") | K31: =IF(AND( C31="Buy", ISBLANK(Y31), B31<>"DIV"), #REF!*D31, "") | L31: =IF(AND( C31="Buy", ISBLANK(Y31), B31<>"DIV"), D31, "") | M31: =IF(AND(B31<>"DIV", C31="Buy", ISBLANK(Y31)), J31/(NOW()-A31),"") | O31: =if(C31="DIV", G31,"") | P31: =if(D31="DIV", H31,"") | Q31: =if(E31="DIV", I31,"") | R31: =if(#REF!="DIV", J31,"") -> #REF! | S31: =if(F31="DIV", K31,"") | T31: =if(G31="DIV", L31,"") | U31: =if(H31="DIV", M31,"") | V31: =if(I31="DIV", N31,"") | W31: =if(J31="DIV", Y31,"") | X31: =if(K31="DIV", Z31,"") | Y31: 508.53182 | Z31: 44232 | AA31: =D31 -> 10 | AB31: =(Y31-E31)*D31-H31-I31 -> 1001.0182 | AC31: =Y31*D31 -> 5085.3182 | AD31: =AB31/(NOW()-Z31) -> 0.54597965 | AE31: =if(B31="DIV", F31,"") | AF31: SBI Securities
A32: 43944 | B32: NSE | C32: Buy | D32: 10 | E32: 406.9 | F32: 4089.3 | H32: 0 | I32: 20.3 | J32: =IF(AND( C32="Buy", ISBLANK(Y32), B32<>"DIV"), ((#REF!*D32)-(E32*D32)+I32), "") | K32: =IF(AND( C32="Buy", ISBLANK(Y32), B32<>"DIV"), #REF!*D32, "") | L32: =IF(AND( C32="Buy", ISBLANK(Y32), B32<>"DIV"), D32, "") | M32: =IF(AND(B32<>"DIV", C32="Buy", ISBLANK(Y32)), J32/(NOW()-A32),"") | O32: =if(C32="DIV", G32,"") | P32: =if(D32="DIV", H32,"") | Q32: =if(E32="DIV", I32,"") | R32: =if(#REF!="DIV", J32,"") -> #REF! | S32: =if(F32="DIV", K32,"") | T32: =if(G32="DIV", L32,"") | U32: =if(H32="DIV", M32,"") | V32: =if(I32="DIV", N32,"") | W32: =if(J32="DIV", Y32,"") | X32: =if(K32="DIV", Z32,"") | Y32: 508.53182 | Z32: 44232 | AA32: =D32 -> 10 | AB32: =(Y32-E32)*D32-H32-I32 -> 996.01818 | AC32: =Y32*D32 -> 5085.3182 | AD32: =AB32/(NOW()-Z32) -> 0.54325253 | AE32: =if(B32="DIV", F32,"") | AF32: SBI Securities
A33: 43921 | B33: NSE | C33: Buy | D33: 10 | E33: 289.645 | F33: 2916.95 | H33: 2.92 | I33: 17.53 | J33: =IF(AND( C33="Buy", ISBLANK(Y33), B33<>"DIV"), ((#REF!*D33)-(E33*D33)+I33), "") | K33: =IF(AND( C33="Buy", ISBLANK(Y33), B33<>"DIV"), #REF!*D33, "") | L33: =IF(AND( C33="Buy", ISBLANK(Y33), B33<>"DIV"), D33, "") | M33: =IF(AND(B33<>"DIV", C33="Buy", ISBLANK(Y33)), J33/(NOW()-A33),"") | O33: =if(C33="DIV", G33,"") | P33: =if(D33="DIV", H33,"") | Q33: =if(E33="DIV", I33,"") | R33: =if(#REF!="DIV", J33,"") -> #REF! | S33: =if(F33="DIV", K33,"") | T33: =if(G33="DIV", L33,"") | U33: =if(H33="DIV", M33,"") | V33: =if(I33="DIV", N33,"") | W33: =if(J33="DIV", Y33,"") | X33: =if(K33="DIV", Z33,"") | Y33: 514.3094 | Z33: 44228 | AA33: =D33 -> 10 | AB33: =(Y33-E33)*D33-H33-I33 -> 2226.194 | AC33: =Y33*D33 -> 5143.094 | AD33: =AB33/(NOW()-Z33) -> 1.211577 | AE33: =if(B33="DIV", F33,"") | AF33: SBI Securities
A34: 43909 | B34: NSE | C34: Buy | D34: 10 | E34: 285.763 | F34: 2877.67 | H34: 2.78 | I34: 17.29 | J34: =IF(AND( C34="Buy", ISBLANK(Y34), B34<>"DIV"), ((#REF!*D34)-(E34*D34)+I34), "") | K34: =IF(AND( C34="Buy", ISBLANK(Y34), B34<>"DIV"), #REF!*D34, "") | L34: =IF(AND( C34="Buy", ISBLANK(Y34), B34<>"DIV"), D34, "") | M34: =IF(AND(B34<>"DIV", C34="Buy", ISBLANK(Y34)), J34/(NOW()-A34),"") | O34: =if(C34="DIV", G34,"") | P34: =if(D34="DIV", H34,"") | Q34: =if(E34="DIV", I34,"") | R34: =if(#REF!="DIV", J34,"") -> #REF! | S34: =if(F34="DIV", K34,"") | T34: =if(G34="DIV", L34,"") | U34: =if(H34="DIV", M34,"") | V34: =if(I34="DIV", N34,"") | W34: =if(J34="DIV", Y34,"") | X34: =if(K34="DIV", Z34,"") | Y34: 514.3094 | Z34: 44228 | AA34: =D34 -> 10 | AB34: =(Y34-E34)*D34-H34-I34 -> 2265.394 | AC34: =Y34*D34 -> 5143.094 | AD34: =AB34/(NOW()-Z34) -> 1.2329111 | AE34: =if(B34="DIV", F34,"") | AF34: SBI Securities
A35: 43906 | B35: NSE | C35: Buy | D35: 10 | E35: 308.099 | F35: 3102.71 | H35: 3.18 | I35: 18.53 | J35: =IF(AND( C35="Buy", ISBLANK(Y35), B35<>"DIV"), ((#REF!*D35)-(E35*D35)+I35), "") | K35: =IF(AND( C35="Buy", ISBLANK(Y35), B35<>"DIV"), #REF!*D35, "") | L35: =IF(AND( C35="Buy", ISBLANK(Y35), B35<>"DIV"), D35, "") | M35: =IF(AND(B35<>"DIV", C35="Buy", ISBLANK(Y35)), J35/(NOW()-A35),"") | O35: =if(C35="DIV", G35,"") | P35: =if(D35="DIV", H35,"") | Q35: =if(E35="DIV", I35,"") | R35: =if(#REF!="DIV", J35,"") -> #REF! | S35: =if(F35="DIV", K35,"") | T35: =if(G35="DIV", L35,"") | U35: =if(H35="DIV", M35,"") | V35: =if(I35="DIV", N35,"") | W35: =if(J35="DIV", Y35,"") | X35: =if(K35="DIV", Z35,"") | Y35: 514.3094 | Z35: 44228 | AA35: =D35 -> 10 | AB35: =(Y35-E35)*D35-H35-I35 -> 2040.394 | AC35: =Y35*D35 -> 5143.094 | AD35: =AB35/(NOW()-Z35) -> 1.1104578 | AE35: =if(B35="DIV", F35,"") | AF35: SBI Securities
A36: 43901 | B36: NSE | C36: Buy | D36: 10 | E36: 362.954 | F36: 3654.96 | H36: 3.63 | I36: 21.83 | J36: =IF(AND( C36="Buy", ISBLANK(Y36), B36<>"DIV"), ((#REF!*D36)-(E36*D36)+I36), "") | K36: =IF(AND( C36="Buy", ISBLANK(Y36), B36<>"DIV"), #REF!*D36, "") | L36: =IF(AND( C36="Buy", ISBLANK(Y36), B36<>"DIV"), D36, "") | M36: =IF(AND(B36<>"DIV", C36="Buy", ISBLANK(Y36)), J36/(NOW()-A36),"") | O36: =if(C36="DIV", G36,"") | P36: =if(D36="DIV", H36,"") | Q36: =if(E36="DIV", I36,"") | R36: =if(#REF!="DIV", J36,"") -> #REF! | S36: =if(F36="DIV", K36,"") | T36: =if(G36="DIV", L36,"") | U36: =if(H36="DIV", M36,"") | V36: =if(I36="DIV", N36,"") | W36: =if(J36="DIV", Y36,"") | X36: =if(K36="DIV", Z36,"") | Y36: 514.3094 | Z36: 44228 | AA36: =D36 -> 10 | AB36: =(Y36-E36)*D36-H36-I36 -> 1488.094 | AC36: =Y36*D36 -> 5143.094 | AD36: =AB36/(NOW()-Z36) -> 0.80987574 | AE36: =if(B36="DIV", F36,"") | AF36: SBI Securities
A37: 43896 | B37: NSE | C37: Buy | D37: 10 | E37: 393.833 | F37: 3965.97 | H37: 3.99 | I37: 23.68 | J37: =IF(AND( C37="Buy", ISBLANK(Y37), B37<>"DIV"), ((#REF!*D37)-(E37*D37)+I37), "") | K37: =IF(AND( C37="Buy", ISBLANK(Y37), B37<>"DIV"), #REF!*D37, "") | L37: =IF(AND( C37="Buy", ISBLANK(Y37), B37<>"DIV"), D37, "") | M37: =IF(AND(B37<>"DIV", C37="Buy", ISBLANK(Y37)), J37/(NOW()-A37),"") | O37: =if(C37="DIV", G37,"") | P37: =if(D37="DIV", H37,"") | Q37: =if(E37="DIV", I37,"") | R37: =if(#REF!="DIV", J37,"") -> #REF! | S37: =if(F37="DIV", K37,"") | T37: =if(G37="DIV", L37,"") | U37: =if(H37="DIV", M37,"") | V37: =if(I37="DIV", N37,"") | W37: =if(J37="DIV", Y37,"") | X37: =if(K37="DIV", Z37,"") | Y37: 514.3094 | Z37: 44228 | AA37: =D37 -> 10 | AB37: =(Y37-E37)*D37-H37-I37 -> 1177.094 | AC37: =Y37*D37 -> 5143.094 | AD37: =AB37/(NOW()-Z37) -> 0.64061805 | AE37: =if(B37="DIV", F37,"") | AF37: SBI Securities
A38: 43895 | B38: NSE | C38: Buy | D38: 10 | E38: 418.004 | F38: 4209.36 | H38: 4.16 | I38: 25.2 | J38: =IF(AND( C38="Buy", ISBLANK(Y38), B38<>"DIV"), ((#REF!*D38)-(E38*D38)+I38), "") | K38: =IF(AND( C38="Buy", ISBLANK(Y38), B38<>"DIV"), #REF!*D38, "") | L38: =IF(AND( C38="Buy", ISBLANK(Y38), B38<>"DIV"), D38, "") | M38: =IF(AND(B38<>"DIV", C38="Buy", ISBLANK(Y38)), J38/(NOW()-A38),"") | O38: =if(C38="DIV", G38,"") | P38: =if(D38="DIV", H38,"") | Q38: =if(E38="DIV", I38,"") | R38: =if(#REF!="DIV", J38,"") -> #REF! | S38: =if(F38="DIV", K38,"") | T38: =if(G38="DIV", L38,"") | U38: =if(H38="DIV", M38,"") | V38: =if(I38="DIV", N38,"") | W38: =if(J38="DIV", Y38,"") | X38: =if(K38="DIV", Z38,"") | Y38: 532.7895 | Z38: 44089 | AA38: =D38 -> 10 | AB38: =(Y38-E38)*D38-H38-I38 -> 1118.495 | AC38: =Y38*D38 -> 5327.895 | AD38: =AB38/(NOW()-Z38) -> 0.56591541 | AE38: =if(B38="DIV", F38,"") | AF38: SBI Securities
A39: 43895 | B39: DIV | C39: Buy | D39: 10 | E39: 5 | F39: 50 | G39: Interim-Dividend of Rs.5.0000/- per share on Ex-Date: 05-MAR-2020 | H39: 0 | I39: 0 | J39: =IF(AND( C39="Buy", ISBLANK(Y39), B39<>"DIV"), ((#REF!*D39)-(E39*D39)+I39), "") | K39: =IF(AND( C39="Buy", ISBLANK(Y39), B39<>"DIV"), #REF!*D39, "") | L39: =IF(AND( C39="Buy", ISBLANK(Y39), B39<>"DIV"), D39, "") | M39: =IF(AND(B39<>"DIV", C39="Buy", ISBLANK(Y39)), J39/(NOW()-A39),"") | O39: =if(C39="DIV", G39,"") | P39: =if(D39="DIV", H39,"") | Q39: =if(E39="DIV", I39,"") | R39: =if(#REF!="DIV", J39,"") -> #REF! | S39: =if(F39="DIV", K39,"") | T39: =if(G39="DIV", L39,"") | U39: =if(H39="DIV", M39,"") | V39: =if(I39="DIV", N39,"") | W39: =if(J39="DIV", Y39,"") | X39: =if(K39="DIV", Z39,"") | AE39: =if(B39="DIV", F39,"") -> 50 | AF39: SBI Securities
A40: 43892 | B40: NSE | C40: Buy | D40: 5 | E40: 478.046 | F40: 2407.02 | H40: 2.39 | I40: 14.38 | J40: =IF(AND( C40="Buy", ISBLANK(Y40), B40<>"DIV"), ((#REF!*D40)-(E40*D40)+I40), "") | K40: =IF(AND( C40="Buy", ISBLANK(Y40), B40<>"DIV"), #REF!*D40, "") | L40: =IF(AND( C40="Buy", ISBLANK(Y40), B40<>"DIV"), D40, "") | M40: =IF(AND(B40<>"DIV", C40="Buy", ISBLANK(Y40)), J40/(NOW()-A40),"") | O40: =if(C40="DIV", G40,"") | P40: =if(D40="DIV", H40,"") | Q40: =if(E40="DIV", I40,"") | R40: =if(#REF!="DIV", J40,"") -> #REF! | S40: =if(F40="DIV", K40,"") | T40: =if(G40="DIV", L40,"") | U40: =if(H40="DIV", M40,"") | V40: =if(I40="DIV", N40,"") | W40: =if(J40="DIV", Y40,"") | X40: =if(K40="DIV", Z40,"") | Y40: 532.7895 | Z40: 44089 | AA40: =D40 -> 5 | AB40: =(Y40-E40)*D40-H40-I40 -> 256.9475 | AC40: =Y40*D40 -> 2663.9475 | AD40: =AB40/(NOW()-Z40) -> 0.13000554 | AE40: =if(B40="DIV", F40,"") | AF40: SBI Securities
A41: 43831 | B41: NSE | C41: Sell | D41: 25 | E41: 592.6104 | F41: 14920.76 | H41: 15.11 | I41: 90.38 | J41: =IF(AND( C41="Buy", ISBLANK(#REF!), B41<>"DIV"), ((#REF!*D41)-(E41*D41)+I41), "") | K41: =IF(AND( C41="Buy", ISBLANK(#REF!), B41<>"DIV"), #REF!*D41, "") | L41: =IF(AND( C41="Buy", ISBLANK(#REF!), B41<>"DIV"), D41, "") | M41: =IF(AND(B41<>"DIV", C41="Buy", ISBLANK(Y41)), J41/(NOW()-A41),"") | O41: =if(C41="DIV", G41,"") | P41: =if(D41="DIV", H41,"") | Q41: =if(E41="DIV", I41,"") | R41: =if(#REF!="DIV", J41,"") -> #REF! | S41: =if(F41="DIV", K41,"") | T41: =if(G41="DIV", L41,"") | U41: =if(H41="DIV", M41,"") | V41: =if(I41="DIV", N41,"") | W41: =if(J41="DIV", Y41,"") | X41: =if(K41="DIV", Z41,"") | AE41: =if(B41="DIV", F41,"") | AF41: SBI Securities
...
