Workbook

Sheet Trading History
K2: UnRealised | W2: Realised
K3: Total | O3: Short Term | S3: Long Term
A4: DATE | B4: EXCH | C4: ACTION | D4: QTY | E4: PRICE | F4: COST | G4: REMARKS | H4: STT | I4: ADD CHRG | J4: Current Price | K4: Gain % | L4: Gain | M4: Gross | N4: Units | O4: Gain % | P4: Gain | Q4: Gross | R4: Units | S4: Gain % | T4: Gain | U4: Gross | V4: Units | W4: Price | X4: Date | Y4: Gain % | Z4: Gain | AA4: Gross | AB4: Units | AC4: DIV | AD4: Broker
A5: 46063 | B5: NSE | C5: Sell | D5: 20 | E5: 1129.6785 | F5: 22593.57 | G5: CN#252611730667 | H5: 22.73 | I5: 135.15
A6: 46062 | B6: NSE | C6: Sell | D6: 50 | E6: 1076.4808 | F6: 53824.04 | G6: CN#252611665409 | H6: 54.13 | I6: 321.83
A7: 46059 | B7: NSE | C7: Sell | D7: 10 | E7: 1008.15 | F7: 10081.5 | G7: ~
A8: 46059 | B8: BSE | C8: Sell | D8: 10 | E8: 1008.15 | F8: 10081.5 | G8: ~
A9: 46059 | B9: NSE | C9: Sell | D9: 5 | E9: 1008.15 | F9: 5040.75 | G9: ~
A10: 46059 | B10: NSE | C10: Sell | D10: 5 | E10: 1008.15 | F10: 5040.75 | G10: ~
A11: 46059 | B11: BSE | C11: Sell | D11: 10 | E11: 1008.15 | F11: 10081.5 | G11: ~
A12: 46059 | B12: NSE | C12: Sell | D12: 1 | E12: 1008.15 | F12: 1008.15 | G12: ~
A13: 46059 | B13: NSE | C13: Sell | D13: 1 | E13: 1108.25 | F13: 1108.25 | G13: ~
A14: 46059 | B14: NSE | C14: Sell | D14: 8 | E14: 1108.25 | F14: 8866 | G14: ~
A15: 46049 | B15: NSE | C15: Buy | D15: 3 | E15: 777.55 | F15: 2349.2 | G15: ~ | H15: 2.33 | I15: 14.22
A16: 46049 | B16: NSE | C16: Buy | D16: 2 | E16: 777.55 | F16: 1566.12 | G16: ~ | H16: 1.56 | I16: 9.46
A17: 46034 | B17: NSE | C17: Buy | D17: 5 | E17: 794.9 | F17: 4002.64 | G17: ~ | H17: 3.98 | I17: 24.16
A18: 46030 | B18: NSE | C18: Buy | D18: 5 | E18: 807.2 | F18: 4064.61 | G18: ~ | H18: 4.02 | I18: 24.59
A19: 46002 | B19: BSE | C19: Buy | D19: 4 | E19: 809.55 | F19: 3261.19 | G19: ~ | H19: 3.25 | I19: 19.74
A20: 46002 | B20: BSE | C20: Buy | D20: 1 | E20: 809.5 | F20: 815.23 | G20: ~ | H20: 0.81 | I20: 4.92
A21: 45961 | B21: NSE | C21: Buy | D21: 3 | E21: 703.85 | F21: 2126.52 | G21: ~ | H21: 2.1 | I21: 12.87
A22: 45961 | B22: NSE | C22: Buy | D22: 2 | E22: 703.8 | F22: 1417.56 | G22: ~ | H22: 1.41 | I22: 8.55
A23: 45959 | B23: BSE | C23: Buy | D23: 1 | E23: 717.8 | F23: 722.89 | G23: ~ | H23: 0.72 | I23: 4.37
A24: 45959 | B24: BSE | C24: Buy | D24: 4 | E24: 717.95 | F24: 2892.14 | G24: ~ | H24: 2.86 | I24: 17.48
A25: 45957 | B25: NSE | C25: Buy | D25: 5 | E25: 719.5 | F25: 3623.02 | G25: ~ | H25: 3.61 | I25: 21.91
A26: 45954 | B26: NSE | C26: Buy | D26: 5 | E26: 723.9 | F26: 3645.15 | G26: ~ | H26: 3.62 | I26: 22.03
... A28: 45953 | B28: NSE | C28: Buy | D28: 1 | E28: 730.85 | F28: 736.02 | G28: ~ | H28: 0.73 | I28: 4.44
A29: 45950 | B29: NSE | C29: Buy | D29: 1 | E29: 672.55 | F29: 677.3 | G29: ~ | H29: 0.67 | I29: 4.08 | W29: 1008.15 | X29: 46059 | Y29: 0.485155 | Z29: 330.9 | AA29: 1003.45 | AB29: 1
A30: 45950 | B30: NSE | C30: Buy | D30: 9 | E30: 672.55 | F30: 6095.84 | G30: ~ | H30: 6.05 | I30: 36.84 | W30: 1008.15 | X30: 46059 | Y30: 0.485135 | Z30: 2978.11 | AA30: 9031.06 | AB30: 9
A31: 45947 | B31: BSE | C31: Buy | D31: 7 | E31: 690.85 | F31: 4870.24 | G31: ~ | H31: 4.85 | I31: 29.44 | W31: 1008.15 | X31: 46059 | Y31: 0.446526 | Z31: 2190 | AA31: 7025.95 | AB31: 7
A32: 45947 | B32: BSE | C32: Buy | D32: 3 | E32: 690.8 | F32: 2087.09 | G32: ~ | H32: 2.07 | I32: 12.62 | W32: 1008.15 | X32: 46059 | Y32: 0.446631 | Z32: 938.72 | AA32: 3011.12 | AB32: 3
A33: 45924 | B33: NSE | C33: Buy | D33: 10 | E33: 678.95 | F33: 6837.55 | G33: ~ | H33: 6.76 | I33: 41.29 | W33: 1008.15 | X33: 46059 | Y33: 0.235703 | Z33: 1622.96 | AA33: 5017.71 | AB33: 5
A34: 45903 | B34: BSE | C34: Buy | D34: 10 | E34: 677.75 | F34: 6825.62 | G34: ~ | H34: 6.8 | I34: 41.32 | W34: 1008.15 | X34: 46059 | Y34: 0.23697 | Z34: 1628.87 | AA34: 5017.62 | AB34: 5
A35: 45897 | B35: NSE | C35: Buy | D35: 5 | E35: 625.8 | F35: 3151.23 | G35: ~ | H35: 3.13 | I35: 19.1 | W35: 1008.15 | X35: 46059 | Y35: 0.593986 | Z35: 1884.99 | AA35: 5013.99 | AB35: 5
A36: 45876 | B36: DIV | C36: Buy | D36: 25 | E36: 9 | F36: 225 | G36: Annual-Dividend of Rs.9.0000/- per share on Ex-Date: 07-AUG-2025 Annual-Dividend of Rs.9.0000/- per share on Ex-Date: 07-AUG-2025 | H36: 0 | I36: 0
A37: 45873 | B37: NSE | C37: Buy | D37: 5 | E37: 665.2 | F37: 3349.66 | G37: ~ | H37: 3.37 | I37: 20.29 | W37: 1008.15 | X37: 46059 | Y37: 0.501209 | Z37: 1690.74 | AA37: 5016.74 | AB37: 5
A38: 45855 | B38: BSE | C38: Buy | D38: 10 | E38: 741.22 | F38: 7412.23 | G38: ~ | H38: 7.36 | I38: 44.87 | J38: =Index!$C$2 | K38: =IF(AND( C19="Buy", ISBLANK(W19), B19<>"DIV"), L19/SUM(F19:I19), "") | L38: =IF(AND( C19="Buy", ISBLANK(W19), B19<>"DIV"), (1-Index!$F$2*2)*((J19*D19)-(E19*D19)), "") | M38: =IF(AND( C19="Buy", ISBLANK(W19), B19<>"DIV"), ((E19*D19)+L19), "") | N38: =IF(AND( C19="Buy", ISBLANK(W19), B19<>"DIV"), D19, "") | O38: =IF(AND( C19="Buy", ISBLANK(W19), B19<>"DIV", NOW()-A19 < 365), P19/SUM(F19:I19), "") | P38: =IF(AND( C19="Buy", ISBLANK(W19), B19<>"DIV", NOW()-A19 < 365), (1-Index!$F$2*2)*((J19*D19)-(E19*D19)), "") | Q38: =IF(AND( C19="Buy", ISBLANK(W19), B19<>"DIV", NOW()-A19 < 365), ((E19*D19)+P19), "") | R38: =IF(AND( C19="Buy", ISBLANK(W19), B19<>"DIV", NOW()-A19 < 365), D19, "") | S38: =IF(AND( C19="Buy", ISBLANK(W19), B19<>"DIV", NOW()-A19 > 365), T19/SUM(F19:I19), "") | T38: =IF(AND( C19="Buy", ISBLANK(W19), B19<>"DIV", NOW()-A19 > 365), (1-Index!$F$2*2)*((J19*D19)-(E19*D19)), "") | U38: =IF(AND( C19="Buy", ISBLANK(W19), B19<>"DIV", NOW()-A19 > 365), ((E19*D19)+T19), "") | V38: =IF(AND( C19="Buy", ISBLANK(W19), B19<>"DIV", NOW()-A19 > 365), D19, "") | W38: 1008.15 | X38: 46059 | Y38: 0.035259 | Z38: 263.19 | AA38: 1004.41 | AB38: 1 | AC38: =IF(B19="DIV", F19,"")
A39: 45812 | B39: NSE | C39: Buy | D39: 1 | E39: 774.3 | F39: 774.3 | G39: ~ | H39: 0.77 | I39: 4.68 | J39: =Index!$C$2 | K39: =IF(AND( C20="Buy", ISBLANK(W20), B20<>"DIV"), L20/SUM(F20:I20), "") | L39: =IF(AND( C20="Buy", ISBLANK(W20), B20<>"DIV"), (1-Index!$F$2*2)*((J20*D20)-(E20*D20)), "") | M39: =IF(AND( C20="Buy", ISBLANK(W20), B20<>"DIV"), ((E20*D20)+L20), "") | N39: =IF(AND( C20="Buy", ISBLANK(W20), B20<>"DIV"), D20, "") | O39: =IF(AND( C20="Buy", ISBLANK(W20), B20<>"DIV", NOW()-A20 < 365), P20/SUM(F20:I20), "") | P39: =IF(AND( C20="Buy", ISBLANK(W20), B20<>"DIV", NOW()-A20 < 365), (1-Index!$F$2*2)*((J20*D20)-(E20*D20)), "") | Q39: =IF(AND( C20="Buy", ISBLANK(W20), B20<>"DIV", NOW()-A20 < 365), ((E20*D20)+P20), "") | R39: =IF(AND( C20="Buy", ISBLANK(W20), B20<>"DIV", NOW()-A20 < 365), D20, "") | S39: =IF(AND( C20="Buy", ISBLANK(W20), B20<>"DIV", NOW()-A20 > 365), T20/SUM(F20:I20), "") | T39: =IF(AND( C20="Buy", ISBLANK(W20), B20<>"DIV", NOW()-A20 > 365), (1-Index!$F$2*2)*((J20*D20)-(E20*D20)), "") | U39: =IF(AND( C20="Buy", ISBLANK(W20), B20<>"DIV", NOW()-A20 > 365), ((E20*D20)+T20), "") | V39: =IF(AND( C20="Buy", ISBLANK(W20), B20<>"DIV", NOW()-A20 > 365), D20, "") | W39: 1108.25 | X39: 46059 | Y39: 0.422276 | Z39: 329.27 | AA39: 1103.57 | AB39: 1 | AC39: =IF(B20="DIV", F20,"")
A40: 45812 | B40: NSE | C40: Buy | D40: 8 | E40: 774.3 | F40: 6194.39 | G40: ~ | H40: 6.2 | I40: 37.39 | J40: =Index!$C$2 | K40: =IF(AND( C21="Buy", ISBLANK(W21), B21<>"DIV"), L21/SUM(F21:I21), "") | L40: =IF(AND( C21="Buy", ISBLANK(W21), B21<>"DIV"), (1-Index!$F$2*2)*((J21*D21)-(E21*D21)), "") | M40: =IF(AND( C21="Buy", ISBLANK(W21), B21<>"DIV"), ((E21*D21)+L21), "") | N40: =IF(AND( C21="Buy", ISBLANK(W21), B21<>"DIV"), D21, "") | O40: =IF(AND( C21="Buy", ISBLANK(W21), B21<>"DIV", NOW()-A21 < 365), P21/SUM(F21:I21), "") | P40: =IF(AND( C21="Buy", ISBLANK(W21), B21<>"DIV", NOW()-A21 < 365), (1-Index!$F$2*2)*((J21*D21)-(E21*D21)), "") | Q40: =IF(AND( C21="Buy", ISBLANK(W21), B21<>"DIV", NOW()-A21 < 365), ((E21*D21)+P21), "") | R40: =IF(AND( C21="Buy", ISBLANK(W21), B21<>"DIV", NOW()-A21 < 365), D21, "") | S40: =IF(AND( C21="Buy", ISBLANK(W21), B21<>"DIV", NOW()-A21 > 365), T21/SUM(F21:I21), "") | T40: =IF(AND( C21="Buy", ISBLANK(W21), B21<>"DIV", NOW()-A21 > 365), (1-Index!$F$2*2)*((J21*D21)-(E21*D21)), "") | U40: =IF(AND( C21="Buy", ISBLANK(W21), B21<>"DIV", NOW()-A21 > 365), ((E21*D21)+T21), "") | V40: =IF(AND( C21="Buy", ISBLANK(W21), B21<>"DIV", NOW()-A21 > 365), D21, "") | W40: 1108.25 | X40: 46059 | Y40: 0.369498 | Z40: 2304.92 | AA40: 7725.02 | AB40: 7 | AC40: =IF(B21="DIV", F21,"")
A41: 45812 | B41: NSE | C41: Buy | D41: 1 | E41: 774.3 | F41: 774.3 | G41: ~ | H41: 0.77 | I41: 4.68 | J41: =Index!$C$2 | K41: =IF(AND( C22="Buy", ISBLANK(W22), B22<>"DIV"), L22/SUM(F22:I22), "") | L41: =IF(AND( C22="Buy", ISBLANK(W22), B22<>"DIV"), (1-Index!$F$2*2)*((J22*D22)-(E22*D22)), "") | M41: =IF(AND( C22="Buy", ISBLANK(W22), B22<>"DIV"), ((E22*D22)+L22), "") | N41: =IF(AND( C22="Buy", ISBLANK(W22), B22<>"DIV"), D22, "") | O41: =IF(AND( C22="Buy", ISBLANK(W22), B22<>"DIV", NOW()-A22 < 365), P22/SUM(F22:I22), "") | P41: =IF(AND( C22="Buy", ISBLANK(W22), B22<>"DIV", NOW()-A22 < 365), (1-Index!$F$2*2)*((J22*D22)-(E22*D22)), "") | Q41: =IF(AND( C22="Buy", ISBLANK(W22), B22<>"DIV", NOW()-A22 < 365), ((E22*D22)+P22), "") | R41: =IF(AND( C22="Buy", ISBLANK(W22), B22<>"DIV", NOW()-A22 < 365), D22, "") | S41: =IF(AND( C22="Buy", ISBLANK(W22), B22<>"DIV", NOW()-A22 > 365), T22/SUM(F22:I22), "") | T41: =IF(AND( C22="Buy", ISBLANK(W22), B22<>"DIV", NOW()-A22 > 365), (1-Index!$F$2*2)*((J22*D22)-(E22*D22)), "") | U41: =IF(AND( C22="Buy", ISBLANK(W22), B22<>"DIV", NOW()-A22 > 365), ((E22*D22)+T22), "") | V41: =IF(AND( C22="Buy", ISBLANK(W22), B22<>"DIV", NOW()-A22 > 365), D22, "") | W41: 1108.25 | X41: 46059 | Y41: 0.422276 | Z41: 329.27 | AA41: 1103.57 | AB41: 1 | AC41: =IF(B22="DIV", F22,"")
A42: 45306 | B42: NSE | C42: Sell | D42: 10 | E42: 554.28 | F42: 5542.84 | G42: ~ | H42: 6 | I42: 33.16 | J42: =Index!$C$2 | K42: =IF(AND( C23="Buy", ISBLANK(W23), B23<>"DIV"), L23/SUM(F23:I23), "") | L42: =IF(AND( C23="Buy", ISBLANK(W23), B23<>"DIV"), (1-Index!$F$2*2)*((J23*D23)-(E23*D23)), "") | M42: =IF(AND( C23="Buy", ISBLANK(W23), B23<>"DIV"), ((E23*D23)+L23), "") | N42: =IF(AND( C23="Buy", ISBLANK(W23), B23<>"DIV"), D23, "") | O42: =IF(AND( C23="Buy", ISBLANK(W23), B23<>"DIV", NOW()-A23 < 365), P23/SUM(F23:I23), "") | P42: =IF(AND( C23="Buy", ISBLANK(W23), B23<>"DIV", NOW()-A23 < 365), (1-Index!$F$2*2)*((J23*D23)-(E23*D23)), "") | Q42: =IF(AND( C23="Buy", ISBLANK(W23), B23<>"DIV", NOW()-A23 < 365), ((E23*D23)+P23), "") | R42: =IF(AND( C23="Buy", ISBLANK(W23), B23<>"DIV", NOW()-A23 < 365), D23, "") | S42: =IF(AND( C23="Buy", ISBLANK(W23), B23<>"DIV", NOW()-A23 > 365), T23/SUM(F23:I23), "") | T42: =IF(AND( C23="Buy", ISBLANK(W23), B23<>"DIV", NOW()-A23 > 365), (1-Index!$F$2*2)*((J23*D23)-(E23*D23)), "") | U42: =IF(AND( C23="Buy", ISBLANK(W23), B23<>"DIV", NOW()-A23 > 365), ((E23*D23)+T23), "") | V42: =IF(AND( C23="Buy", ISBLANK(W23), B23<>"DIV", NOW()-A23 > 365), D23, "") | Y42: =IF(AND( C23="Buy", W23<>"", AA23<>"", B23<>"DIV"), Z23/SUM(F23:I23), "") | AC42: =IF(B23="DIV", F23,"")
...

Sheet Index
B1: Code | C1: NSE:AVANTIFEED
B2: Current Price | C2: 1081.2 | E2: Commission | F2: 0.007
B3: 52 Week High | C3: 1116.5
B4: 52 Week Low | C4: 601.55
B6: UnRealised
A8: All | B8: Units | C8: =SUM('Trading History'!$N$4:$N998) | E8: ST Units | F8: =IFERROR(SUM('Trading History'!$R$4:$R998), 0) | H8: LT Units | I8: =SUM('Trading History'!$V$4:$V998) | K8: Units | L8: =SUM('Trading History'!$AB$4:$AB998)
B9: Avg % | C9: =IFERROR(Index!C10/(Index!C8*Index!$C$2), 0) | E9: ST Avg % | F9: =IFERROR(Index!F10/(Index!F8*Index!$C$2), 0) | H9: LT Avg % | I9: =IFERROR(Index!I10/(Index!I8*Index!$C$2), 0) | K9: Avg % | L9: =IFERROR(Index!L10/(Index!L8*Index!$C$2), 0)
B10: Gain | C10: =SUM('Trading History'!$L$4:$L998) | E10: ST Gain | F10: =SUM('Trading History'!$P$4:$P998) | H10: LT Gain | I10: =SUM('Trading History'!$T$4:$T998) | K10: Gain | L10: =SUM('Trading History'!$Z$4:$Z998)
B11: Invested | C11: =Index!C12-Index!C10 | E11: ST Invested | F11: =Index!F12-Index!F10 | H11: LT Invested | I11: =Index!I12-Index!I10 | K11: Invested | L11: =Index!L12-Index!L10
B12: Gross | C12: =SUM('Trading History'!$M$4:$M998) | E12: ST Gross | F12: =SUM('Trading History'!$Q$4:$Q998) | H12: LT Gross | I12: =SUM('Trading History'!$U$4:$U998) | K12: Gross | L12: =SUM('Trading History'!$AA$4:$AA998)
K13: Dividends | L13: =SUMIF('Trading History'!$B27:$B998,"DIV",'Trading History'!$AC$4:$AC998)
A15: 0.5 | B15: Units | C15: =SUMIFS('Trading History'!$N$4:$N998, 'Trading History'!$K$4:$K998, _xludf.CONCAT(">", $A15)) | E15: ST Units | F15: =IFERROR(SUMIFS('Trading History'!$R$4:$R998, 'Trading History'!$O$4:$O998, _xludf.CONCAT(">", $A15)), 0) | H15: LT Units | I15: =SUMIFS('Trading History'!$V$4:$V998, 'Trading History'!$S$4:$S998, _xludf.CONCAT(">", $A15)) | K15: Units | L15: =SUMIFS('Trading History'!$AB$4:$AB998, 'Trading History'!$Y$4:$Y998, _xludf.CONCAT(">", $A15))
B16: Avg % | C16: =IFERROR(Index!C17/(Index!C15*Index!$C$2), 0) | E16: ST Avg % | F16: =IFERROR(Index!F17/(Index!F15*Index!$C$2), 0) | H16: LT Avg % | I16: =IFERROR(Index!I17/(Index!I15*Index!$C$2), 0) | K16: Avg % | L16: =IFERROR(Index!L17/(Index!L15*Index!$C$2), 0)
B17: Gain | C17: =SUMIFS('Trading History'!$L$4:$L998, 'Trading History'!$K$4:$K998, _xludf.CONCAT(">", $A15)) | E17: ST Gain | F17: =SUMIFS('Trading History'!$P$4:$P998, 'Trading History'!$O$4:$O998, _xludf.CONCAT(">", $A15)) | H17: LT Gain | I17: =SUMIFS('Trading History'!$T$4:$T998, 'Trading History'!$S$4:$S998, _xludf.CONCAT(">", $A15)) | K17: Gain | L17: =SUMIFS('Trading History'!$Z$4:$Z998, 'Trading History'!$Y$4:$Y998, _xludf.CONCAT(">", $A15))
B18: Invested | C18: =Index!C19-Index!C17 | E18: ST Invested | F18: =Index!F19-Index!F17 | H18: LT Invested | I18: =Index!I19-Index!I17 | K18: Invested | L18: =Index!L19-Index!L17
B19: Gross | C19: =SUMIFS('Trading History'!$M$4:$M998, 'Trading History'!$K$4:$K998, _xludf.CONCAT(">", $A15)) | E19: ST Gross | F19: =SUMIFS('Trading History'!$Q$4:$Q998, 'Trading History'!$O$4:$O998, _xludf.CONCAT(">", $A15)) | H19: LT Gross | I19: =SUMIFS('Trading History'!$U$4:$U998, 'Trading History'!$S$4:$S998, _xludf.CONCAT(">", $A15)) | K19: Gross | L19: =SUMIFS('Trading History'!$AA$4:$AA998, 'Trading History'!$Y$4:$Y998, _xludf.CONCAT(">", $A15))
A22: 0.45 | B22: Units | C22: =SUMIFS('Trading History'!$N$4:$N998, 'Trading History'!$K$4:$K998, _xludf.CONCAT(">", $A22)) | E22: ST Units | F22: =IFERROR(SUMIFS('Trading History'!$R$4:$R998, 'Trading History'!$O$4:$O998, _xludf.CONCAT(">", $A22)), 0) | H22: LT Units | I22: =SUMIFS('Trading History'!$V$4:$V998, 'Trading History'!$S$4:$S998, _xludf.CONCAT(">", $A22)) | K22: Units | L22: =SUMIFS('Trading History'!$AB$4:$AB998, 'Trading History'!$Y$4:$Y998, _xludf.CONCAT(">", $A22))
B23: Avg % | C23: =IFERROR(Index!C24/(Index!C22*Index!$C$2), 0) | E23: ST Avg % | F23: =IFERROR(Index!F24/(Index!F22*Index!$C$2), 0) | H23: LT Avg % | I23: =IFERROR(Index!I24/(Index!I22*Index!$C$2), 0) | K23: Avg % | L23: =IFERROR(Index!L24/(Index!L22*Index!$C$2), 0)
B24: Gain | C24: =SUMIFS('Trading History'!$L$4:$L998, 'Trading History'!$K$4:$K998, _xludf.CONCAT(">", $A22)) | E24: ST Gain | F24: =SUMIFS('Trading History'!$P$4:$P998, 'Trading History'!$O$4:$O998, _xludf.CONCAT(">", $A22)) | H24: LT Gain | I24: =SUMIFS('Trading History'!$T$4:$T998, 'Trading History'!$S$4:$S998, _xludf.CONCAT(">", $A22)) | K24: Gain | L24: =SUMIFS('Trading History'!$Z$4:$Z998, 'Trading History'!$Y$4:$Y998, _xludf.CONCAT(">", $A22))
B25: Invested | C25: =Index!C26-Index!C24 | E25: ST Invested | F25: =Index!F26-Index!F24 | H25: LT Invested | I25: =Index!I26-Index!I24 | K25: Invested | L25: =Index!L26-Index!L24
B26: Gross | C26: =SUMIFS('Trading History'!$M$4:$M998, 'Trading History'!$K$4:$K998, _xludf.CONCAT(">", $A22)) | E26: ST Gross | F26: =SUMIFS('Trading History'!$Q$4:$Q998, 'Trading History'!$O$4:$O998, _xludf.CONCAT(">", $A22)) | H26: LT Gross | I26: =SUMIFS('Trading History'!$U$4:$U998, 'Trading History'!$S$4:$S998, _xludf.CONCAT(">", $A22)) | K26: Gross | L26: =SUMIFS('Trading History'!$AA$4:$AA998, 'Trading History'!$Y$4:$Y998, _xludf.CONCAT(">", $A22))
A29: 0.4 | B29: Units | C29: =SUMIFS('Trading History'!$N$4:$N998, 'Trading History'!$K$4:$K998, _xludf.CONCAT(">", $A29)) | E29: ST Units | F29: =IFERROR(SUMIFS('Trading History'!$R$4:$R998, 'Trading History'!$O$4:$O998, _xludf.CONCAT(">", $A29)), 0) | H29: LT Units | I29: =SUMIFS('Trading History'!$V$4:$V998, 'Trading History'!$S$4:$S998, _xludf.CONCAT(">", $A29)) | K29: Units | L29: =SUMIFS('Trading History'!$AB$4:$AB998, 'Trading History'!$Y$4:$Y998, _xludf.CONCAT(">", $A29))
B30: Avg % | C30: =IFERROR(Index!C31/(Index!C29*Index!$C$2), 0) | E30: ST Avg % | F30: =IFERROR(Index!F31/(Index!F29*Index!$C$2), 0) | H30: LT Avg % | I30: =IFERROR(Index!I31/(Index!I29*Index!$C$2), 0) | K30: Avg % | L30: =IFERROR(Index!L31/(Index!L29*Index!$C$2), 0)
B31: Gain | C31: =SUMIFS('Trading History'!$L$4:$L998, 'Trading History'!$K$4:$K998, _xludf.CONCAT(">", $A29)) | E31: ST Gain | F31: =SUMIFS('Trading History'!$P$4:$P998, 'Trading History'!$O$4:$O998, _xludf.CONCAT(">", $A29)) | H31: LT Gain | I31: =SUMIFS('Trading History'!$T$4:$T998, 'Trading History'!$S$4:$S998, _xludf.CONCAT(">", $A29)) | K31: Gain | L31: =SUMIFS('Trading History'!$Z$4:$Z998, 'Trading History'!$Y$4:$Y998, _xludf.CONCAT(">", $A29))
B32: Invested | C32: =Index!C33-Index!C31 | E32: ST Invested | F32: =Index!F33-Index!F31 | H32: LT Invested | I32: =Index!I33-Index!I31 | K32: Invested | L32: =Index!L33-Index!L31
B33: Gross | C33: =SUMIFS('Trading History'!$M$4:$M998, 'Trading History'!$K$4:$K998, _xludf.CONCAT(">", $A29)) | E33: ST Gross | F33: =SUMIFS('Trading History'!$Q$4:$Q998, 'Trading History'!$O$4:$O998, _xludf.CONCAT(">", $A29)) | H33: LT Gross | I33: =SUMIFS('Trading History'!$U$4:$U998, 'Trading History'!$S$4:$S998, _xludf.CONCAT(">", $A29)) | K33: Gross | L33: =SUMIFS('Trading History'!$AA$4:$AA998, 'Trading History'!$Y$4:$Y998, _xludf.CONCAT(">", $A29))
A36: 0.35 | B36: Units | C36: =SUMIFS('Trading History'!$N$4:$N998, 'Trading History'!$K$4:$K998, _xludf.CONCAT(">", $A36)) | E36: ST Units | F36: =IFERROR(SUMIFS('Trading History'!$R$4:$R998, 'Trading History'!$O$4:$O998, _xludf.CONCAT(">", $A36)), 0) | H36: LT Units | I36: =SUMIFS('Trading History'!$V$4:$V998, 'Trading History'!$S$4:$S998, _xludf.CONCAT(">", $A36)) | K36: Units | L36: =SUMIFS('Trading History'!$AB$4:$AB998, 'Trading History'!$Y$4:$Y998, _xludf.CONCAT(">", $A36))
B37: Avg % | C37: =IFERROR(Index!C38/(Index!C36*Index!$C$2), 0) | E37: ST Avg % | F37: =IFERROR(Index!F38/(Index!F36*Index!$C$2), 0) | H37: LT Avg % | I37: =IFERROR(Index!I38/(Index!I36*Index!$C$2), 0) | K37: Avg % | L37: =IFERROR(Index!L38/(Index!L36*Index!$C$2), 0)
B38: Gain | C38: =SUMIFS('Trading History'!$L$4:$L998, 'Trading History'!$K$4:$K998, _xludf.CONCAT(">", $A36)) | E38: ST Gain | F38: =SUMIFS('Trading History'!$P$4:$P998, 'Trading History'!$O$4:$O998, _xludf.CONCAT(">", $A36)) | H38: LT Gain | I38: =SUMIFS('Trading History'!$T$4:$T998, 'Trading History'!$S$4:$S998, _xludf.CONCAT(">", $A36)) | K38: Gain | L38: =SUMIFS('Trading History'!$Z$4:$Z998, 'Trading History'!$Y$4:$Y998, _xludf.CONCAT(">", $A36))
B39: Invested | C39: =Index!C40-Index!C38 | E39: ST Invested | F39: =Index!F40-Index!F38 | H39: LT Invested | I39: =Index!I40-Index!I38 | K39: Invested | L39: =Index!L40-Index!L38
B40: Gross | C40: =SUMIFS('Trading History'!$M$4:$M998, 'Trading History'!$K$4:$K998, _xludf.CONCAT(">", $A36)) | E40: ST Gross | F40: =SUMIFS('Trading History'!$Q$4:$Q998, 'Trading History'!$O$4:$O998, _xludf.CONCAT(">", $A36)) | H40: LT Gross | I40: =SUMIFS('Trading History'!$U$4:$U998, 'Trading History'!$S$4:$S998, _xludf.CONCAT(">", $A36)) | K40: Gross | L40: =SUMIFS('Trading History'!$AA$4:$AA998, 'Trading History'!$Y$4:$Y998, _xludf.CONCAT(">", $A36))
A43: 0.3 | B43: Units | C43: =SUMIFS('Trading History'!$N$4:$N998, 'Trading History'!$K$4:$K998, _xludf.CONCAT(">", $A43)) | E43: ST Units | F43: =IFERROR(SUMIFS('Trading History'!$R$4:$R998, 'Trading History'!$O$4:$O998, _xludf.CONCAT(">", $A43)), 0) | H43: LT Units | I43: =SUMIFS('Trading History'!$V$4:$V998, 'Trading History'!$S$4:$S998, _xludf.CONCAT(">", $A43)) | K43: Units | L43: =SUMIFS('Trading History'!$AB$4:$AB998, 'Trading History'!$Y$4:$Y998, _xludf.CONCAT(">", $A43))
B44: Avg % | C44: =IFERROR(Index!C45/(Index!C43*Index!$C$2), 0) | E44: ST Avg % | F44: =IFERROR(Index!F45/(Index!F43*Index!$C$2), 0) | H44: LT Avg % | I44: =IFERROR(Index!I45/(Index!I43*Index!$C$2), 0) | K44: Avg % | L44: =IFERROR(Index!L45/(Index!L43*Index!$C$2), 0)
B45: Gain | C45: =SUMIFS('Trading History'!$L$4:$L998, 'Trading History'!$K$4:$K998, _xludf.CONCAT(">", $A43)) | E45: ST Gain | F45: =SUMIFS('Trading History'!$P$4:$P998, 'Trading History'!$O$4:$O998, _xludf.CONCAT(">", $A43)) | H45: LT Gain | I45: =SUMIFS('Trading History'!$T$4:$T998, 'Trading History'!$S$4:$S998, _xludf.CONCAT(">", $A43)) | K45: Gain | L45: =SUMIFS('Trading History'!$Z$4:$Z998, 'Trading History'!$Y$4:$Y998, _xludf.CONCAT(">", $A43))
B46: Invested | C46: =Index!C47-Index!C45 | E46: ST Invested | F46: =Index!F47-Index!F45 | H46: LT Invested | I46: =Index!I47-Index!I45 | K46: Invested | L46: =Index!L47-Index!L45
B47: Gross | C47: =SUMIFS('Trading History'!$M$4:$M998, 'Trading History'!$K$4:$K998, _xludf.CONCAT(">", $A43)) | E47: ST Gross | F47: =SUMIFS('Trading History'!$Q$4:$Q998, 'Trading History'!$O$4:$O998, _xludf.CONCAT(">", $A43)) | H47: LT Gross | I47: =SUMIFS('Trading History'!$U$4:$U998, 'Trading History'!$S$4:$S998, _xludf.CONCAT(">", $A43)) | K47: Gross | L47: =SUMIFS('Trading History'!$AA$4:$AA998, 'Trading History'!$Y$4:$Y998, _xludf.CONCAT(">", $A43))
A50: 0.25 | B50: Units | C50: =SUMIFS('Trading History'!$N$4:$N998, 'Trading History'!$K$4:$K998, _xludf.CONCAT(">", $A50)) | E50: ST Units | F50: =IFERROR(SUMIFS('Trading History'!$R$4:$R998, 'Trading History'!$O$4:$O998, _xludf.CONCAT(">", $A50)), 0) | H50: LT Units | I50: =SUMIFS('Trading History'!$V$4:$V998, 'Trading History'!$S$4:$S998, _xludf.CONCAT(">", $A50)) | K50: Units | L50: =SUMIFS('Trading History'!$AB$4:$AB998, 'Trading History'!$Y$4:$Y998, _xludf.CONCAT(">", $A50))
B51: Avg % | C51: =IFERROR(Index!C52/(Index!C50*Index!$C$2), 0) | E51: ST Avg % | F51: =IFERROR(Index!F52/(Index!F50*Index!$C$2), 0) | H51: LT Avg % | I51: =IFERROR(Index!I52/(Index!I50*Index!$C$2), 0) | K51: Avg % | L51: =IFERROR(Index!L52/(Index!L50*Index!$C$2), 0)
B52: Gain | C52: =SUMIFS('Trading History'!$L$4:$L998, 'Trading History'!$K$4:$K998, _xludf.CONCAT(">", $A50)) | E52: ST Gain | F52: =SUMIFS('Trading History'!$P$4:$P998, 'Trading History'!$O$4:$O998, _xludf.CONCAT(">", $A50)) | H52: LT Gain | I52: =SUMIFS('Trading History'!$T$4:$T998, 'Trading History'!$S$4:$S998, _xludf.CONCAT(">", $A50)) | K52: Gain | L52: =SUMIFS('Trading History'!$Z$4:$Z998, 'Trading History'!$Y$4:$Y998, _xludf.CONCAT(">", $A50))
B53: Invested | C53: =Index!C54-Index!C52 | E53: ST Invested | F53: =Index!F54-Index!F52 | H53: LT Invested | I53: =Index!I54-Index!I52 | K53: Invested | L53: =Index!L54-Index!L52
...
