Workbook

Sheet Index
B1: Code | C1: BOM:540936
B2: Current Price | C2: =IFERROR(__xludf.DUMMYFUNCTION("GOOGLEFINANCE($C$1, ""price"")"),3.58) | E2: Commission | F2: 0.007
B3: 52 Week High | C3: =IFERROR(__xludf.DUMMYFUNCTION("GOOGLEFINANCE($C$1, ""high52"")"),5.35)
B4: 52 Week Low | C4: =IFERROR(__xludf.DUMMYFUNCTION("GOOGLEFINANCE($C$1, ""low52"")"),3.01)
B6: UnRealised
A8: All | B8: Units | C8: =SUM('Trading History'!$N$4:$N1039) | E8: ST Units | F8: =IFERROR(SUM('Trading History'!$R$4:$R1039), 0) | H8: LT Units | I8: =SUM('Trading History'!$V$4:$V1039) | K8: Units | L8: =SUM('Trading History'!$AB$4:$AB1039)
B9: Avg % | C9: =IFERROR(Index!C10/(Index!C8*Index!$C$2), 0) | E9: ST Avg % | F9: =IFERROR(Index!F10/(Index!F8*Index!$C$2), 0) | H9: LT Avg % | I9: =IFERROR(Index!I10/(Index!I8*Index!$C$2), 0) | K9: Avg % | L9: =IFERROR(Index!L10/(Index!L8*Index!$C$2), 0)
B10: Gain | C10: =SUM('Trading History'!$L$4:$L1039) | E10: ST Gain | F10: =SUM('Trading History'!$P$4:$P1039) | H10: LT Gain | I10: =SUM('Trading History'!$T$4:$T1039) | K10: Gain | L10: =SUM('Trading History'!$Z$4:$Z1039)
B11: Invested | C11: =Index!C12-Index!C10 | E11: ST Invested | F11: =Index!F12-Index!F10 | H11: LT Invested | I11: =Index!I12-Index!I10 | K11: Invested | L11: =Index!L12-Index!L10
B12: Gross | C12: =SUM('Trading History'!$M$4:$M1039) | E12: ST Gross | F12: =SUM('Trading History'!$Q$4:$Q1039) | H12: LT Gross | I12: =SUM('Trading History'!$U$4:$U1039) | K12: Gross | L12: =SUM('Trading History'!$AA$4:$AA1039)
K13: Dividends | L13: =SUMIF('Trading History'!$B12:$B1039,"DIV",'Trading History'!$AC$4:$AC1039)
A15: 0.5 | B15: Units | C15: =SUMIFS('Trading History'!$N$4:$N1039, 'Trading History'!$K$4:$K1039, CONCAT(">", $A15)) | E15: ST Units | F15: =IFERROR(SUMIFS('Trading History'!$R$4:$R1039, 'Trading History'!$O$4:$O1039, CONCAT(">", $A15)), 0) | H15: LT Units | I15: =SUMIFS('Trading History'!$V$4:$V1039, 'Trading History'!$S$4:$S1039, CONCAT(">", $A15)) | K15: Units | L15: =SUMIFS('Trading History'!$AB$4:$AB1039, 'Trading History'!$Y$4:$Y1039, CONCAT(">", $A15))
B16: Avg % | C16: =IFERROR(Index!C17/(Index!C15*Index!$C$2), 0) | E16: ST Avg % | F16: =IFERROR(Index!F17/(Index!F15*Index!$C$2), 0) | H16: LT Avg % | I16: =IFERROR(Index!I17/(Index!I15*Index!$C$2), 0) | K16: Avg % | L16: =IFERROR(Index!L17/(Index!L15*Index!$C$2), 0)
B17: Gain | C17: =SUMIFS('Trading History'!$L$4:$L1039, 'Trading History'!$K$4:$K1039, CONCAT(">", $A15)) | E17: ST Gain | F17: =SUMIFS('Trading History'!$P$4:$P1039, 'Trading History'!$O$4:$O1039, CONCAT(">", $A15)) | H17: LT Gain | I17: =SUMIFS('Trading History'!$T$4:$T1039, 'Trading History'!$S$4:$S1039, CONCAT(">", $A15)) | K17: Gain | L17: =SUMIFS('Trading History'!$Z$4:$Z1039, 'Trading History'!$Y$4:$Y1039, CONCAT(">", $A15))
B18: Invested | C18: =Index!C19-Index!C17 | E18: ST Invested | F18: =Index!F19-Index!F17 | H18: LT Invested | I18: =Index!I19-Index!I17 | K18: Invested | L18: =Index!L19-Index!L17
B19: Gross | C19: =SUMIFS('Trading History'!$M$4:$M1039, 'Trading History'!$K$4:$K1039, CONCAT(">", $A15)) | E19: ST Gross | F19: =SUMIFS('Trading History'!$Q$4:$Q1039, 'Trading History'!$O$4:$O1039, CONCAT(">", $A15)) | H19: LT Gross | I19: =SUMIFS('Trading History'!$U$4:$U1039, 'Trading History'!$S$4:$S1039, CONCAT(">", $A15)) | K19: Gross | L19: =SUMIFS('Trading History'!$AA$4:$AA1039, 'Trading History'!$Y$4:$Y1039, CONCAT(">", $A15))
A22: 0.45 | B22: Units | C22: =SUMIFS('Trading History'!$N$4:$N1039, 'Trading History'!$K$4:$K1039, CONCAT(">", $A22)) | E22: ST Units | F22: =IFERROR(SUMIFS('Trading History'!$R$4:$R1039, 'Trading History'!$O$4:$O1039, CONCAT(">", $A22)), 0) | H22: LT Units | I22: =SUMIFS('Trading History'!$V$4:$V1039, 'Trading History'!$S$4:$S1039, CONCAT(">", $A22)) | K22: Units | L22: =SUMIFS('Trading History'!$AB$4:$AB1039, 'Trading History'!$Y$4:$Y1039, CONCAT(">", $A22))
B23: Avg % | C23: =IFERROR(Index!C24/(Index!C22*Index!$C$2), 0) | E23: ST Avg % | F23: =IFERROR(Index!F24/(Index!F22*Index!$C$2), 0) | H23: LT Avg % | I23: =IFERROR(Index!I24/(Index!I22*Index!$C$2), 0) | K23: Avg % | L23: =IFERROR(Index!L24/(Index!L22*Index!$C$2), 0)
B24: Gain | C24: =SUMIFS('Trading History'!$L$4:$L1039, 'Trading History'!$K$4:$K1039, CONCAT(">", $A22)) | E24: ST Gain | F24: =SUMIFS('Trading History'!$P$4:$P1039, 'Trading History'!$O$4:$O1039, CONCAT(">", $A22)) | H24: LT Gain | I24: =SUMIFS('Trading History'!$T$4:$T1039, 'Trading History'!$S$4:$S1039, CONCAT(">", $A22)) | K24: Gain | L24: =SUMIFS('Trading History'!$Z$4:$Z1039, 'Trading History'!$Y$4:$Y1039, CONCAT(">", $A22))
B25: Invested | C25: =Index!C26-Index!C24 | E25: ST Invested | F25: =Index!F26-Index!F24 | H25: LT Invested | I25: =Index!I26-Index!I24 | K25: Invested | L25: =Index!L26-Index!L24
B26: Gross | C26: =SUMIFS('Trading History'!$M$4:$M1039, 'Trading History'!$K$4:$K1039, CONCAT(">", $A22)) | E26: ST Gross | F26: =SUMIFS('Trading History'!$Q$4:$Q1039, 'Trading History'!$O$4:$O1039, CONCAT(">", $A22)) | H26: LT Gross | I26: =SUMIFS('Trading History'!$U$4:$U1039, 'Trading History'!$S$4:$S1039, CONCAT(">", $A22)) | K26: Gross | L26: =SUMIFS('Trading History'!$AA$4:$AA1039, 'Trading History'!$Y$4:$Y1039, CONCAT(">", $A22))
A29: 0.4 | B29: Units | C29: =SUMIFS('Trading History'!$N$4:$N1039, 'Trading History'!$K$4:$K1039, CONCAT(">", $A29)) | E29: ST Units | F29: =IFERROR(SUMIFS('Trading History'!$R$4:$R1039, 'Trading History'!$O$4:$O1039, CONCAT(">", $A29)), 0) | H29: LT Units | I29: =SUMIFS('Trading History'!$V$4:$V1039, 'Trading History'!$S$4:$S1039, CONCAT(">", $A29)) | K29: Units | L29: =SUMIFS('Trading History'!$AB$4:$AB1039, 'Trading History'!$Y$4:$Y1039, CONCAT(">", $A29))
B30: Avg % | C30: =IFERROR(Index!C31/(Index!C29*Index!$C$2), 0) | E30: ST Avg % | F30: =IFERROR(Index!F31/(Index!F29*Index!$C$2), 0) | H30: LT Avg % | I30: =IFERROR(Index!I31/(Index!I29*Index!$C$2), 0) | K30: Avg % | L30: =IFERROR(Index!L31/(Index!L29*Index!$C$2), 0)
B31: Gain | C31: =SUMIFS('Trading History'!$L$4:$L1039, 'Trading History'!$K$4:$K1039, CONCAT(">", $A29)) | E31: ST Gain | F31: =SUMIFS('Trading History'!$P$4:$P1039, 'Trading History'!$O$4:$O1039, CONCAT(">", $A29)) | H31: LT Gain | I31: =SUMIFS('Trading History'!$T$4:$T1039, 'Trading History'!$S$4:$S1039, CONCAT(">", $A29)) | K31: Gain | L31: =SUMIFS('Trading History'!$Z$4:$Z1039, 'Trading History'!$Y$4:$Y1039, CONCAT(">", $A29))
B32: Invested | C32: =Index!C33-Index!C31 | E32: ST Invested | F32: =Index!F33-Index!F31 | H32: LT Invested | I32: =Index!I33-Index!I31 | K32: Invested | L32: =Index!L33-Index!L31
B33: Gross | C33: =SUMIFS('Trading History'!$M$4:$M1039, 'Trading History'!$K$4:$K1039, CONCAT(">", $A29)) | E33: ST Gross | F33: =SUMIFS('Trading History'!$Q$4:$Q1039, 'Trading History'!$O$4:$O1039, CONCAT(">", $A29)) | H33: LT Gross | I33: =SUMIFS('Trading History'!$U$4:$U1039, 'Trading History'!$S$4:$S1039, CONCAT(">", $A29)) | K33: Gross | L33: =SUMIFS('Trading History'!$AA$4:$AA1039, 'Trading History'!$Y$4:$Y1039, CONCAT(">", $A29))
A36: 0.35 | B36: Units | C36: =SUMIFS('Trading History'!$N$4:$N1039, 'Trading History'!$K$4:$K1039, CONCAT(">", $A36)) | E36: ST Units | F36: =IFERROR(SUMIFS('Trading History'!$R$4:$R1039, 'Trading History'!$O$4:$O1039, CONCAT(">", $A36)), 0) | H36: LT Units | I36: =SUMIFS('Trading History'!$V$4:$V1039, 'Trading History'!$S$4:$S1039, CONCAT(">", $A36)) | K36: Units | L36: =SUMIFS('Trading History'!$AB$4:$AB1039, 'Trading History'!$Y$4:$Y1039, CONCAT(">", $A36))
B37: Avg % | C37: =IFERROR(Index!C38/(Index!C36*Index!$C$2), 0) | E37: ST Avg % | F37: =IFERROR(Index!F38/(Index!F36*Index!$C$2), 0) | H37: LT Avg % | I37: =IFERROR(Index!I38/(Index!I36*Index!$C$2), 0) | K37: Avg % | L37: =IFERROR(Index!L38/(Index!L36*Index!$C$2), 0)
B38: Gain | C38: =SUMIFS('Trading History'!$L$4:$L1039, 'Trading History'!$K$4:$K1039, CONCAT(">", $A36)) | E38: ST Gain | F38: =SUMIFS('Trading History'!$P$4:$P1039, 'Trading History'!$O$4:$O1039, CONCAT(">", $A36)) | H38: LT Gain | I38: =SUMIFS('Trading History'!$T$4:$T1039, 'Trading History'!$S$4:$S1039, CONCAT(">", $A36)) | K38: Gain | L38: =SUMIFS('Trading History'!$Z$4:$Z1039, 'Trading History'!$Y$4:$Y1039, CONCAT(">", $A36))
B39: Invested | C39: =Index!C40-Index!C38 | E39: ST Invested | F39: =Index!F40-Index!F38 | H39: LT Invested | I39: =Index!I40-Index!I38 | K39: Invested | L39: =Index!L40-Index!L38
B40: Gross | C40: =SUMIFS('Trading History'!$M$4:$M1039, 'Trading History'!$K$4:$K1039, CONCAT(">", $A36)) | E40: ST Gross | F40: =SUMIFS('Trading History'!$Q$4:$Q1039, 'Trading History'!$O$4:$O1039, CONCAT(">", $A36)) | H40: LT Gross | I40: =SUMIFS('Trading History'!$U$4:$U1039, 'Trading History'!$S$4:$S1039, CONCAT(">", $A36)) | K40: Gross | L40: =SUMIFS('Trading History'!$AA$4:$AA1039, 'Trading History'!$Y$4:$Y1039, CONCAT(">", $A36))
A43: 0.3 | B43: Units | C43: =SUMIFS('Trading History'!$N$4:$N1039, 'Trading History'!$K$4:$K1039, CONCAT(">", $A43)) | E43: ST Units | F43: =IFERROR(SUMIFS('Trading History'!$R$4:$R1039, 'Trading History'!$O$4:$O1039, CONCAT(">", $A43)), 0) | H43: LT Units | I43: =SUMIFS('Trading History'!$V$4:$V1039, 'Trading History'!$S$4:$S1039, CONCAT(">", $A43)) | K43: Units | L43: =SUMIFS('Trading History'!$AB$4:$AB1039, 'Trading History'!$Y$4:$Y1039, CONCAT(">", $A43))
B44: Avg % | C44: =IFERROR(Index!C45/(Index!C43*Index!$C$2), 0) | E44: ST Avg % | F44: =IFERROR(Index!F45/(Index!F43*Index!$C$2), 0) | H44: LT Avg % | I44: =IFERROR(Index!I45/(Index!I43*Index!$C$2), 0) | K44: Avg % | L44: =IFERROR(Index!L45/(Index!L43*Index!$C$2), 0)
B45: Gain | C45: =SUMIFS('Trading History'!$L$4:$L1039, 'Trading History'!$K$4:$K1039, CONCAT(">", $A43)) | E45: ST Gain | F45: =SUMIFS('Trading History'!$P$4:$P1039, 'Trading History'!$O$4:$O1039, CONCAT(">", $A43)) | H45: LT Gain | I45: =SUMIFS('Trading History'!$T$4:$T1039, 'Trading History'!$S$4:$S1039, CONCAT(">", $A43)) | K45: Gain | L45: =SUMIFS('Trading History'!$Z$4:$Z1039, 'Trading History'!$Y$4:$Y1039, CONCAT(">", $A43))
B46: Invested | C46: =Index!C47-Index!C45 | E46: ST Invested | F46: =Index!F47-Index!F45 | H46: LT Invested | I46: =Index!I47-Index!I45 | K46: Invested | L46: =Index!L47-Index!L45
B47: Gross | C47: =SUMIFS('Trading History'!$M$4:$M1039, 'Trading History'!$K$4:$K1039, CONCAT(">", $A43)) | E47: ST Gross | F47: =SUMIFS('Trading History'!$Q$4:$Q1039, 'Trading History'!$O$4:$O1039, CONCAT(">", $A43)) | H47: LT Gross | I47: =SUMIFS('Trading History'!$U$4:$U1039, 'Trading History'!$S$4:$S1039, CONCAT(">", $A43)) | K47: Gross | L47: =SUMIFS('Trading History'!$AA$4:$AA1039, 'Trading History'!$Y$4:$Y1039, CONCAT(">", $A43))
A50: 0.25 | B50: Units | C50: =SUMIFS('Trading History'!$N$4:$N1039, 'Trading History'!$K$4:$K1039, CONCAT(">", $A50)) | E50: ST Units | F50: =IFERROR(SUMIFS('Trading History'!$R$4:$R1039, 'Trading History'!$O$4:$O1039, CONCAT(">", $A50)), 0) | H50: LT Units | I50: =SUMIFS('Trading History'!$V$4:$V1039, 'Trading History'!$S$4:$S1039, CONCAT(">", $A50)) | K50: Units | L50: =SUMIFS('Trading History'!$AB$4:$AB1039, 'Trading History'!$Y$4:$Y1039, CONCAT(">", $A50))
B51: Avg % | C51: =IFERROR(Index!C52/(Index!C50*Index!$C$2), 0) | E51: ST Avg % | F51: =IFERROR(Index!F52/(Index!F50*Index!$C$2), 0) | H51: LT Avg % | I51: =IFERROR(Index!I52/(Index!I50*Index!$C$2), 0) | K51: Avg % | L51: =IFERROR(Index!L52/(Index!L50*Index!$C$2), 0)
B52: Gain | C52: =SUMIFS('Trading History'!$L$4:$L1039, 'Trading History'!$K$4:$K1039, CONCAT(">", $A50)) | E52: ST Gain | F52: =SUMIFS('Trading History'!$P$4:$P1039, 'Trading History'!$O$4:$O1039, CONCAT(">", $A50)) | H52: LT Gain | I52: =SUMIFS('Trading History'!$T$4:$T1039, 'Trading History'!$S$4:$S1039, CONCAT(">", $A50)) | K52: Gain | L52: =SUMIFS('Trading History'!$Z$4:$Z1039, 'Trading History'!$Y$4:$Y1039, CONCAT(">", $A50))
B53: Invested | C53: =Index!C54-Index!C52 | E53: ST Invested | F53: =Index!F54-Index!F52 | H53: LT Invested | I53: =Index!I54-Index!I52 | K53: Invested | L53: =Index!L54-Index!L52
...

Sheet Trading History
K2: UnRealised | W2: Realised
K3: Total | O3: Short Term | S3: Long Term
A4: DATE | B4: EXCH | C4: ACTION | D4: QTY | E4: PRICE | F4: COST | G4: REMARKS | H4: STT | I4: ADD CHRG | J4: Current Price | K4: Gain % | L4: Gain | M4: Gross | N4: Units | O4: Gain % | P4: Gain | Q4: Gross | R4: Units | S4: Gain % | T4: Gain | U4: Gross | V4: Units | W4: Price | X4: Date | Y4: Gain % | Z4: Gain | AA4: Gross | AB4: Units | AC4: DIV | AD4: Broker
A5: 46065 | B5: BSE | C5: Sell | D5: 100 | E5: 3.57 | F5: 357 | G5: ~
A6: 44950 | B6: BSE | C6: Buy | D6: 100 | E6: 20.0482 | F6: 2019.18 | G6: ~ | H6: 2 | I6: 12.18 | J6: =Index!$C$2 | K6: =IF(AND( C5="Buy", ISBLANK(W5), B5<>"DIV"), L5/sum(F5:I5), "") | L6: =IF(AND( C5="Buy", ISBLANK(W5), B5<>"DIV"), (1-Index!$F$2*2)*((J5*D5)-(E5*D5)), "") | M6: =IF(AND( C5="Buy", ISBLANK(W5), B5<>"DIV"), ((E5*D5)+L5), "") | N6: =IF(AND( C5="Buy", ISBLANK(W5), B5<>"DIV"), D5, "") | O6: =IF(AND( C5="Buy", ISBLANK(W5), B5<>"DIV", NOW()-A5 < 365), P5/sum(F5:I5), "") | P6: =IF(AND( C5="Buy", ISBLANK(W5), B5<>"DIV", NOW()-A5 < 365), (1-Index!$F$2*2)*((J5*D5)-(E5*D5)), "") | Q6: =IF(AND( C5="Buy", ISBLANK(W5), B5<>"DIV", NOW()-A5 < 365), ((E5*D5)+P5), "") | R6: =IF(AND( C5="Buy", ISBLANK(W5), B5<>"DIV", NOW()-A5 < 365), D5, "") | S6: =IF(AND( C5="Buy", ISBLANK(W5), B5<>"DIV", NOW()-A5 > 365), T5/sum(F5:I5), "") | T6: =IF(AND( C5="Buy", ISBLANK(W5), B5<>"DIV", NOW()-A5 > 365), (1-Index!$F$2*2)*((J5*D5)-(E5*D5)), "") | U6: =IF(AND( C5="Buy", ISBLANK(W5), B5<>"DIV", NOW()-A5 > 365), ((E5*D5)+T5), "") | V6: =IF(AND( C5="Buy", ISBLANK(W5), B5<>"DIV", NOW()-A5 > 365), D5, "") | W6: 3.57 | X6: 46065 | Y6: -0.799047 | Z6: -1624.75 | AA6: 380.07 | AB6: 100 | AC6: =if(B5="DIV", F5,"") | AD6: SBI Securities
