Workbook

Sheet Trading History
K2: UnRealised | W2: Realised
K3: Total | O3: Short Term | S3: Long Term
A4: DATE | B4: EXCH | C4: ACTION | D4: QTY | E4: PRICE | F4: COST | G4: REMARKS | H4: STT | I4: ADD CHRG | J4: Current Price | K4: Gain % | L4: Gain | M4: Gross | N4: Units | O4: Gain % | P4: Gain | Q4: Gross | R4: Units | S4: Gain % | T4: Gain | U4: Gross | V4: Units | W4: Price | X4: Date | Y4: Gain % | Z4: Gain | AA4: Gross | AB4: Units | AC4: DIV | AD4: Broker
A5: 46057 | B5: NSE | C5: Buy | D5: 10 | E5: 471.15 | F5: 4744.94 | G5: ~ | H5: 4.72 | I5: 28.72
A6: 46049 | B6: NSE | C6: Buy | D6: 1 | E6: 505.2 | F6: 508.8 | G6: ~ | H6: 0.51 | I6: 3.09
A7: 46049 | B7: NSE | C7: Buy | D7: 9 | E7: 505.2 | F7: 4579.07 | G7: ~ | H7: 4.55 | I7: 27.72
A8: 46044 | B8: NSE | C8: Buy | D8: 5 | E8: 600.85 | F8: 3025.53 | G8: ~ | H8: 3.01 | I8: 18.27
A9: 46034 | B9: NSE | C9: Buy | D9: 5 | E9: 626.75 | F9: 3155.95 | G9: ~ | H9: 3.14 | I9: 19.06
A10: 46015 | B10: BSE | C10: Buy | D10: 5 | E10: 656.3 | F10: 3304.76 | G10: ~ | H10: 3.26 | I10: 20
A11: 46014 | B11: BSE | C11: Buy | D11: 5 | E11: 659.35 | F11: 3320.14 | G11: ~ | H11: 3.29 | I11: 20.1
A12: 45993 | B12: BSE | C12: Buy | D12: 1 | E12: 638.9 | F12: 643.43 | G12: ~ | H12: 0.64 | I12: 3.89
A13: 45993 | B13: BSE | C13: Buy | D13: 4 | E13: 638.95 | F13: 2573.92 | G13: ~ | H13: 2.57 | I13: 15.55
A14: 45989 | B14: BSE | C14: Buy | D14: 5 | E14: 646.8 | F14: 3256.92 | G14: ~ | H14: 3.22 | I14: 19.7
A15: 45982 | B15: NSE | C15: Buy | D15: 5 | E15: 638.5 | F15: 3215.11 | G15: ~ | H15: 3.19 | I15: 19.42
A16: 45981 | B16: NSE | C16: Buy | D16: 5 | E16: 634.35 | F16: 3194.23 | G16: ~ | H16: 3.15 | I16: 19.33
... A33: 45897 | B33: BSE | C33: Buy | D33: 5 | E33: 641.2 | F33: 3228.8 | G33: ~ | H33: 3.21 | I33: 19.59
A34: 45950 | B34: BSE | C34: Buy | D34: 10 | E34: 648.57 | F34: =D5*E5 | G34: ~ | J34: =Index!$C$2 | K34: =IF(AND( C5="Buy", ISBLANK(W5), B5<>"DIV"), L5/sum(F5:I5), "") | L34: =IF(AND( C5="Buy", ISBLANK(W5), B5<>"DIV"), (1-Index!$F$2*2)*((J5*D5)-(E5*D5)), "") | M34: =IF(AND( C5="Buy", ISBLANK(W5), B5<>"DIV"), ((E5*D5)+L5), "") | N34: =IF(AND( C5="Buy", ISBLANK(W5), B5<>"DIV"), D5, "") | O34: =IF(AND( C5="Buy", ISBLANK(W5), B5<>"DIV", NOW()-A5 < 365), P5/sum(F5:I5), "") | P34: =IF(AND( C5="Buy", ISBLANK(W5), B5<>"DIV", NOW()-A5 < 365), (1-Index!$F$2*2)*((J5*D5)-(E5*D5)), "") | Q34: =IF(AND( C5="Buy", ISBLANK(W5), B5<>"DIV", NOW()-A5 < 365), ((E5*D5)+P5), "") | R34: =IF(AND( C5="Buy", ISBLANK(W5), B5<>"DIV", NOW()-A5 < 365), D5, "") | S34: =IF(AND( C5="Buy", ISBLANK(W5), B5<>"DIV", NOW()-A5 > 365), T5/sum(F5:I5), "") | T34: =IF(AND( C5="Buy", ISBLANK(W5), B5<>"DIV", NOW()-A5 > 365), (1-Index!$F$2*2)*((J5*D5)-(E5*D5)), "") | U34: =IF(AND( C5="Buy", ISBLANK(W5), B5<>"DIV", NOW()-A5 > 365), ((E5*D5)+T5), "") | V34: =IF(AND( C5="Buy", ISBLANK(W5), B5<>"DIV", NOW()-A5 > 365), D5, "") | Y34: =IF(AND( C5="Buy", W5<>"", AA5<>"", B5<>"DIV"), Z5/sum(F5:I5), "") | AC34: =if(B5="DIV", F5,"")
A35: 45947 | B35: BSE | C35: Buy | D35: 10 | E35: 640.51 | F35: =D6*E6 | G35: ~ | J35: =Index!$C$2 | K35: =IF(AND( C6="Buy", ISBLANK(W6), B6<>"DIV"), L6/sum(F6:I6), "") | L35: =IF(AND( C6="Buy", ISBLANK(W6), B6<>"DIV"), (1-Index!$F$2*2)*((J6*D6)-(E6*D6)), "") | M35: =IF(AND( C6="Buy", ISBLANK(W6), B6<>"DIV"), ((E6*D6)+L6), "") | N35: =IF(AND( C6="Buy", ISBLANK(W6), B6<>"DIV"), D6, "") | O35: =IF(AND( C6="Buy", ISBLANK(W6), B6<>"DIV", NOW()-A6 < 365), P6/sum(F6:I6), "") | P35: =IF(AND( C6="Buy", ISBLANK(W6), B6<>"DIV", NOW()-A6 < 365), (1-Index!$F$2*2)*((J6*D6)-(E6*D6)), "") | Q35: =IF(AND( C6="Buy", ISBLANK(W6), B6<>"DIV", NOW()-A6 < 365), ((E6*D6)+P6), "") | R35: =IF(AND( C6="Buy", ISBLANK(W6), B6<>"DIV", NOW()-A6 < 365), D6, "") | S35: =IF(AND( C6="Buy", ISBLANK(W6), B6<>"DIV", NOW()-A6 > 365), T6/sum(F6:I6), "") | T35: =IF(AND( C6="Buy", ISBLANK(W6), B6<>"DIV", NOW()-A6 > 365), (1-Index!$F$2*2)*((J6*D6)-(E6*D6)), "") | U35: =IF(AND( C6="Buy", ISBLANK(W6), B6<>"DIV", NOW()-A6 > 365), ((E6*D6)+T6), "") | V35: =IF(AND( C6="Buy", ISBLANK(W6), B6<>"DIV", NOW()-A6 > 365), D6, "") | Y35: =IF(AND( C6="Buy", W6<>"", AA6<>"", B6<>"DIV"), Z6/sum(F6:I6), "") | AC35: =if(B6="DIV", F6,"")
A36: 45897 | B36: BSE | C36: Buy | D36: 5 | E36: 645.76 | F36: 3228.8 | G36: ~ | H36: 3.21 | I36: 19.59 | J36: =Index!$C$2 | K36: =IF(AND( C7="Buy", ISBLANK(W7), B7<>"DIV"), L7/sum(F7:I7), "") | L36: =IF(AND( C7="Buy", ISBLANK(W7), B7<>"DIV"), (1-Index!$F$2*2)*((J7*D7)-(E7*D7)), "") | M36: =IF(AND( C7="Buy", ISBLANK(W7), B7<>"DIV"), ((E7*D7)+L7), "") | N36: =IF(AND( C7="Buy", ISBLANK(W7), B7<>"DIV"), D7, "") | O36: =IF(AND( C7="Buy", ISBLANK(W7), B7<>"DIV", NOW()-A7 < 365), P7/sum(F7:I7), "") | P36: =IF(AND( C7="Buy", ISBLANK(W7), B7<>"DIV", NOW()-A7 < 365), (1-Index!$F$2*2)*((J7*D7)-(E7*D7)), "") | Q36: =IF(AND( C7="Buy", ISBLANK(W7), B7<>"DIV", NOW()-A7 < 365), ((E7*D7)+P7), "") | R36: =IF(AND( C7="Buy", ISBLANK(W7), B7<>"DIV", NOW()-A7 < 365), D7, "") | S36: =IF(AND( C7="Buy", ISBLANK(W7), B7<>"DIV", NOW()-A7 > 365), T7/sum(F7:I7), "") | T36: =IF(AND( C7="Buy", ISBLANK(W7), B7<>"DIV", NOW()-A7 > 365), (1-Index!$F$2*2)*((J7*D7)-(E7*D7)), "") | U36: =IF(AND( C7="Buy", ISBLANK(W7), B7<>"DIV", NOW()-A7 > 365), ((E7*D7)+T7), "") | V36: =IF(AND( C7="Buy", ISBLANK(W7), B7<>"DIV", NOW()-A7 > 365), D7, "") | Y36: =IF(AND( C7="Buy", W7<>"", AA7<>"", B7<>"DIV"), Z7/sum(F7:I7), "") | AC36: =if(B7="DIV", F7,"")
A37: 45855 | B37: BSE | C37: Buy | D37: 5 | E37: 680 | F37: 3399.98 | G37: ~ | H37: 3.38 | I37: 20.6 | J37: =Index!$C$2 | K37: =IF(AND( C8="Buy", ISBLANK(W8), B8<>"DIV"), L8/sum(F8:I8), "") | L37: =IF(AND( C8="Buy", ISBLANK(W8), B8<>"DIV"), (1-Index!$F$2*2)*((J8*D8)-(E8*D8)), "") | M37: =IF(AND( C8="Buy", ISBLANK(W8), B8<>"DIV"), ((E8*D8)+L8), "") | N37: =IF(AND( C8="Buy", ISBLANK(W8), B8<>"DIV"), D8, "") | O37: =IF(AND( C8="Buy", ISBLANK(W8), B8<>"DIV", NOW()-A8 < 365), P8/sum(F8:I8), "") | P37: =IF(AND( C8="Buy", ISBLANK(W8), B8<>"DIV", NOW()-A8 < 365), (1-Index!$F$2*2)*((J8*D8)-(E8*D8)), "") | Q37: =IF(AND( C8="Buy", ISBLANK(W8), B8<>"DIV", NOW()-A8 < 365), ((E8*D8)+P8), "") | R37: =IF(AND( C8="Buy", ISBLANK(W8), B8<>"DIV", NOW()-A8 < 365), D8, "") | S37: =IF(AND( C8="Buy", ISBLANK(W8), B8<>"DIV", NOW()-A8 > 365), T8/sum(F8:I8), "") | T37: =IF(AND( C8="Buy", ISBLANK(W8), B8<>"DIV", NOW()-A8 > 365), (1-Index!$F$2*2)*((J8*D8)-(E8*D8)), "") | U37: =IF(AND( C8="Buy", ISBLANK(W8), B8<>"DIV", NOW()-A8 > 365), ((E8*D8)+T8), "") | V37: =IF(AND( C8="Buy", ISBLANK(W8), B8<>"DIV", NOW()-A8 > 365), D8, "") | Y37: =IF(AND( C8="Buy", W8<>"", AA8<>"", B8<>"DIV"), Z8/sum(F8:I8), "") | AC37: =if(B8="DIV", F8,"")
A38: 45835 | B38: DIV | C38: Buy | D38: 10 | E38: 1.25 | F38: 12.5 | G38: Annual-Dividend of Rs.1.2500/- per share on Ex-Date: 27-JUN-2025 | H38: 0 | I38: 0 | J38: =Index!$C$2 | K38: =IF(AND( C9="Buy", ISBLANK(W9), B9<>"DIV"), L9/sum(F9:I9), "") | L38: =IF(AND( C9="Buy", ISBLANK(W9), B9<>"DIV"), (1-Index!$F$2*2)*((J9*D9)-(E9*D9)), "") | M38: =IF(AND( C9="Buy", ISBLANK(W9), B9<>"DIV"), ((E9*D9)+L9), "") | N38: =IF(AND( C9="Buy", ISBLANK(W9), B9<>"DIV"), D9, "") | O38: =IF(AND( C9="Buy", ISBLANK(W9), B9<>"DIV", NOW()-A9 < 365), P9/sum(F9:I9), "") | P38: =IF(AND( C9="Buy", ISBLANK(W9), B9<>"DIV", NOW()-A9 < 365), (1-Index!$F$2*2)*((J9*D9)-(E9*D9)), "") | Q38: =IF(AND( C9="Buy", ISBLANK(W9), B9<>"DIV", NOW()-A9 < 365), ((E9*D9)+P9), "") | R38: =IF(AND( C9="Buy", ISBLANK(W9), B9<>"DIV", NOW()-A9 < 365), D9, "") | S38: =IF(AND( C9="Buy", ISBLANK(W9), B9<>"DIV", NOW()-A9 > 365), T9/sum(F9:I9), "") | T38: =IF(AND( C9="Buy", ISBLANK(W9), B9<>"DIV", NOW()-A9 > 365), (1-Index!$F$2*2)*((J9*D9)-(E9*D9)), "") | U38: =IF(AND( C9="Buy", ISBLANK(W9), B9<>"DIV", NOW()-A9 > 365), ((E9*D9)+T9), "") | V38: =IF(AND( C9="Buy", ISBLANK(W9), B9<>"DIV", NOW()-A9 > 365), D9, "") | Y38: =IF(AND( C9="Buy", W9<>"", AA9<>"", B9<>"DIV"), Z9/sum(F9:I9), "") | AC38: =if(B9="DIV", F9,"")
A39: 45722 | B39: NSE | C39: Buy | D39: 1 | E39: 683.97 | F39: 683.97 | G39: ~ | H39: 0.68 | I39: 4.14 | J39: =Index!$C$2 | K39: =IF(AND( C10="Buy", ISBLANK(W10), B10<>"DIV"), L10/sum(F10:I10), "") | L39: =IF(AND( C10="Buy", ISBLANK(W10), B10<>"DIV"), (1-Index!$F$2*2)*((J10*D10)-(E10*D10)), "") | M39: =IF(AND( C10="Buy", ISBLANK(W10), B10<>"DIV"), ((E10*D10)+L10), "") | N39: =IF(AND( C10="Buy", ISBLANK(W10), B10<>"DIV"), D10, "") | O39: =IF(AND( C10="Buy", ISBLANK(W10), B10<>"DIV", NOW()-A10 < 365), P10/sum(F10:I10), "") | P39: =IF(AND( C10="Buy", ISBLANK(W10), B10<>"DIV", NOW()-A10 < 365), (1-Index!$F$2*2)*((J10*D10)-(E10*D10)), "") | Q39: =IF(AND( C10="Buy", ISBLANK(W10), B10<>"DIV", NOW()-A10 < 365), ((E10*D10)+P10), "") | R39: =IF(AND( C10="Buy", ISBLANK(W10), B10<>"DIV", NOW()-A10 < 365), D10, "") | S39: =IF(AND( C10="Buy", ISBLANK(W10), B10<>"DIV", NOW()-A10 > 365), T10/sum(F10:I10), "") | T39: =IF(AND( C10="Buy", ISBLANK(W10), B10<>"DIV", NOW()-A10 > 365), (1-Index!$F$2*2)*((J10*D10)-(E10*D10)), "") | U39: =IF(AND( C10="Buy", ISBLANK(W10), B10<>"DIV", NOW()-A10 > 365), ((E10*D10)+T10), "") | V39: =IF(AND( C10="Buy", ISBLANK(W10), B10<>"DIV", NOW()-A10 > 365), D10, "") | Y39: =IF(AND( C10="Buy", W10<>"", AA10<>"", B10<>"DIV"), Z10/sum(F10:I10), "") | AC39: =if(B10="DIV", F10,"")
A40: 45722 | B40: NSE | C40: Buy | D40: 2 | E40: 683.97 | F40: 1367.94 | G40: ~ | H40: 1.37 | I40: 8.27 | J40: =Index!$C$2 | K40: =IF(AND( C11="Buy", ISBLANK(W11), B11<>"DIV"), L11/sum(F11:I11), "") | L40: =IF(AND( C11="Buy", ISBLANK(W11), B11<>"DIV"), (1-Index!$F$2*2)*((J11*D11)-(E11*D11)), "") | M40: =IF(AND( C11="Buy", ISBLANK(W11), B11<>"DIV"), ((E11*D11)+L11), "") | N40: =IF(AND( C11="Buy", ISBLANK(W11), B11<>"DIV"), D11, "") | O40: =IF(AND( C11="Buy", ISBLANK(W11), B11<>"DIV", NOW()-A11 < 365), P11/sum(F11:I11), "") | P40: =IF(AND( C11="Buy", ISBLANK(W11), B11<>"DIV", NOW()-A11 < 365), (1-Index!$F$2*2)*((J11*D11)-(E11*D11)), "") | Q40: =IF(AND( C11="Buy", ISBLANK(W11), B11<>"DIV", NOW()-A11 < 365), ((E11*D11)+P11), "") | R40: =IF(AND( C11="Buy", ISBLANK(W11), B11<>"DIV", NOW()-A11 < 365), D11, "") | S40: =IF(AND( C11="Buy", ISBLANK(W11), B11<>"DIV", NOW()-A11 > 365), T11/sum(F11:I11), "") | T40: =IF(AND( C11="Buy", ISBLANK(W11), B11<>"DIV", NOW()-A11 > 365), (1-Index!$F$2*2)*((J11*D11)-(E11*D11)), "") | U40: =IF(AND( C11="Buy", ISBLANK(W11), B11<>"DIV", NOW()-A11 > 365), ((E11*D11)+T11), "") | V40: =IF(AND( C11="Buy", ISBLANK(W11), B11<>"DIV", NOW()-A11 > 365), D11, "") | Y40: =IF(AND( C11="Buy", W11<>"", AA11<>"", B11<>"DIV"), Z11/sum(F11:I11), "") | AC40: =if(B11="DIV", F11,"")
A41: 45716 | B41: NSE | C41: Buy | D41: 5 | E41: 664.02 | F41: 3320.12 | G41: ~ | H41: 3.29 | I41: 20.08 | J41: =Index!$C$2 | K41: =IF(AND( C12="Buy", ISBLANK(W12), B12<>"DIV"), L12/sum(F12:I12), "") | L41: =IF(AND( C12="Buy", ISBLANK(W12), B12<>"DIV"), (1-Index!$F$2*2)*((J12*D12)-(E12*D12)), "") | M41: =IF(AND( C12="Buy", ISBLANK(W12), B12<>"DIV"), ((E12*D12)+L12), "") | N41: =IF(AND( C12="Buy", ISBLANK(W12), B12<>"DIV"), D12, "") | O41: =IF(AND( C12="Buy", ISBLANK(W12), B12<>"DIV", NOW()-A12 < 365), P12/sum(F12:I12), "") | P41: =IF(AND( C12="Buy", ISBLANK(W12), B12<>"DIV", NOW()-A12 < 365), (1-Index!$F$2*2)*((J12*D12)-(E12*D12)), "") | Q41: =IF(AND( C12="Buy", ISBLANK(W12), B12<>"DIV", NOW()-A12 < 365), ((E12*D12)+P12), "") | R41: =IF(AND( C12="Buy", ISBLANK(W12), B12<>"DIV", NOW()-A12 < 365), D12, "") | S41: =IF(AND( C12="Buy", ISBLANK(W12), B12<>"DIV", NOW()-A12 > 365), T12/sum(F12:I12), "") | T41: =IF(AND( C12="Buy", ISBLANK(W12), B12<>"DIV", NOW()-A12 > 365), (1-Index!$F$2*2)*((J12*D12)-(E12*D12)), "") | U41: =IF(AND( C12="Buy", ISBLANK(W12), B12<>"DIV", NOW()-A12 > 365), ((E12*D12)+T12), "") | V41: =IF(AND( C12="Buy", ISBLANK(W12), B12<>"DIV", NOW()-A12 > 365), D12, "") | Y41: =IF(AND( C12="Buy", W12<>"", AA12<>"", B12<>"DIV"), Z12/sum(F12:I12), "") | AC41: =if(B12="DIV", F12,"")
A42: 45694 | B42: NSE | C42: Buy | D42: 2 | E42: 751.83 | F42: 1503.66 | G42: ~ | H42: 1.49 | I42: 9.07 | J42: =Index!$C$2 | K42: =IF(AND( C13="Buy", ISBLANK(W13), B13<>"DIV"), L13/sum(F13:I13), "") | L42: =IF(AND( C13="Buy", ISBLANK(W13), B13<>"DIV"), (1-Index!$F$2*2)*((J13*D13)-(E13*D13)), "") | M42: =IF(AND( C13="Buy", ISBLANK(W13), B13<>"DIV"), ((E13*D13)+L13), "") | N42: =IF(AND( C13="Buy", ISBLANK(W13), B13<>"DIV"), D13, "") | O42: =IF(AND( C13="Buy", ISBLANK(W13), B13<>"DIV", NOW()-A13 < 365), P13/sum(F13:I13), "") | P42: =IF(AND( C13="Buy", ISBLANK(W13), B13<>"DIV", NOW()-A13 < 365), (1-Index!$F$2*2)*((J13*D13)-(E13*D13)), "") | Q42: =IF(AND( C13="Buy", ISBLANK(W13), B13<>"DIV", NOW()-A13 < 365), ((E13*D13)+P13), "") | R42: =IF(AND( C13="Buy", ISBLANK(W13), B13<>"DIV", NOW()-A13 < 365), D13, "") | S42: =IF(AND( C13="Buy", ISBLANK(W13), B13<>"DIV", NOW()-A13 > 365), T13/sum(F13:I13), "") | T42: =IF(AND( C13="Buy", ISBLANK(W13), B13<>"DIV", NOW()-A13 > 365), (1-Index!$F$2*2)*((J13*D13)-(E13*D13)), "") | U42: =IF(AND( C13="Buy", ISBLANK(W13), B13<>"DIV", NOW()-A13 > 365), ((E13*D13)+T13), "") | V42: =IF(AND( C13="Buy", ISBLANK(W13), B13<>"DIV", NOW()-A13 > 365), D13, "") | Y42: =IF(AND( C13="Buy", W13<>"", AA13<>"", B13<>"DIV"), Z13/sum(F13:I13), "") | AC42: =if(B13="DIV", F13,"")
A43: 44084 | B43: NSE | C43: Sell | D43: 50 | E43: 481.64 | F43: 24081.77 | G43: ~ | H43: 22.15 | I43: 146.08 | J43: =Index!$C$2 | K43: =IF(AND( C14="Buy", ISBLANK(W14), B14<>"DIV"), L14/sum(F14:I14), "") | L43: =IF(AND( C14="Buy", ISBLANK(W14), B14<>"DIV"), (1-Index!$F$2*2)*((J14*D14)-(E14*D14)), "") | M43: =IF(AND( C14="Buy", ISBLANK(W14), B14<>"DIV"), ((E14*D14)+L14), "") | N43: =IF(AND( C14="Buy", ISBLANK(W14), B14<>"DIV"), D14, "") | O43: =IF(AND( C14="Buy", ISBLANK(W14), B14<>"DIV", NOW()-A14 < 365), P14/sum(F14:I14), "") | P43: =IF(AND( C14="Buy", ISBLANK(W14), B14<>"DIV", NOW()-A14 < 365), (1-Index!$F$2*2)*((J14*D14)-(E14*D14)), "") | Q43: =IF(AND( C14="Buy", ISBLANK(W14), B14<>"DIV", NOW()-A14 < 365), ((E14*D14)+P14), "") | R43: =IF(AND( C14="Buy", ISBLANK(W14), B14<>"DIV", NOW()-A14 < 365), D14, "") | S43: =IF(AND( C14="Buy", ISBLANK(W14), B14<>"DIV", NOW()-A14 > 365), T14/sum(F14:I14), "") | T43: =IF(AND( C14="Buy", ISBLANK(W14), B14<>"DIV", NOW()-A14 > 365), (1-Index!$F$2*2)*((J14*D14)-(E14*D14)), "") | U43: =IF(AND( C14="Buy", ISBLANK(W14), B14<>"DIV", NOW()-A14 > 365), ((E14*D14)+T14), "") | V43: =IF(AND( C14="Buy", ISBLANK(W14), B14<>"DIV", NOW()-A14 > 365), D14, "") | Y43: =IF(AND( C14="Buy", W14<>"", AA14<>"", B14<>"DIV"), Z14/sum(F14:I14), "") | AC43: =if(B14="DIV", F14,"")
A44: 44075 | B44: NSE | C44: Sell | D44: 60 | E44: 476.52 | F44: 28591.3 | G44: ~ | H44: 29 | I44: 170.7 | J44: =Index!$C$2 | K44: =IF(AND( C15="Buy", ISBLANK(W15), B15<>"DIV"), L15/sum(F15:I15), "") | L44: =IF(AND( C15="Buy", ISBLANK(W15), B15<>"DIV"), (1-Index!$F$2*2)*((J15*D15)-(E15*D15)), "") | M44: =IF(AND( C15="Buy", ISBLANK(W15), B15<>"DIV"), ((E15*D15)+L15), "") | N44: =IF(AND( C15="Buy", ISBLANK(W15), B15<>"DIV"), D15, "") | O44: =IF(AND( C15="Buy", ISBLANK(W15), B15<>"DIV", NOW()-A15 < 365), P15/sum(F15:I15), "") | P44: =IF(AND( C15="Buy", ISBLANK(W15), B15<>"DIV", NOW()-A15 < 365), (1-Index!$F$2*2)*((J15*D15)-(E15*D15)), "") | Q44: =IF(AND( C15="Buy", ISBLANK(W15), B15<>"DIV", NOW()-A15 < 365), ((E15*D15)+P15), "") | R44: =IF(AND( C15="Buy", ISBLANK(W15), B15<>"DIV", NOW()-A15 < 365), D15, "") | S44: =IF(AND( C15="Buy", ISBLANK(W15), B15<>"DIV", NOW()-A15 > 365), T15/sum(F15:I15), "") | T44: =IF(AND( C15="Buy", ISBLANK(W15), B15<>"DIV", NOW()-A15 > 365), (1-Index!$F$2*2)*((J15*D15)-(E15*D15)), "") | U44: =IF(AND( C15="Buy", ISBLANK(W15), B15<>"DIV", NOW()-A15 > 365), ((E15*D15)+T15), "") | V44: =IF(AND( C15="Buy", ISBLANK(W15), B15<>"DIV", NOW()-A15 > 365), D15, "") | Y44: =IF(AND( C15="Buy", W15<>"", AA15<>"", B15<>"DIV"), Z15/sum(F15:I15), "") | AC44: =if(B15="DIV", F15,"")
A45: 44060 | B45: NSE | C45: Sell | D45: 50 | E45: 484.77 | F45: 24238.46 | G45: ~ | H45: 22.16 | I45: 146.28 | J45: =Index!$C$2 | K45: =IF(AND( C16="Buy", ISBLANK(W16), B16<>"DIV"), L16/sum(F16:I16), "") | L45: =IF(AND( C16="Buy", ISBLANK(W16), B16<>"DIV"), (1-Index!$F$2*2)*((J16*D16)-(E16*D16)), "") | M45: =IF(AND( C16="Buy", ISBLANK(W16), B16<>"DIV"), ((E16*D16)+L16), "") | N45: =IF(AND( C16="Buy", ISBLANK(W16), B16<>"DIV"), D16, "") | O45: =IF(AND( C16="Buy", ISBLANK(W16), B16<>"DIV", NOW()-A16 < 365), P16/sum(F16:I16), "") | P45: =IF(AND( C16="Buy", ISBLANK(W16), B16<>"DIV", NOW()-A16 < 365), (1-Index!$F$2*2)*((J16*D16)-(E16*D16)), "") | Q45: =IF(AND( C16="Buy", ISBLANK(W16), B16<>"DIV", NOW()-A16 < 365), ((E16*D16)+P16), "") | R45: =IF(AND( C16="Buy", ISBLANK(W16), B16<>"DIV", NOW()-A16 < 365), D16, "") | S45: =IF(AND( C16="Buy", ISBLANK(W16), B16<>"DIV", NOW()-A16 > 365), T16/sum(F16:I16), "") | T45: =IF(AND( C16="Buy", ISBLANK(W16), B16<>"DIV", NOW()-A16 > 365), (1-Index!$F$2*2)*((J16*D16)-(E16*D16)), "") | U45: =IF(AND( C16="Buy", ISBLANK(W16), B16<>"DIV", NOW()-A16 > 365), ((E16*D16)+T16), "") | V45: =IF(AND( C16="Buy", ISBLANK(W16), B16<>"DIV", NOW()-A16 > 365), D16, "") | Y45: =IF(AND( C16="Buy", W16<>"", AA16<>"", B16<>"DIV"), Z16/sum(F16:I16), "") | AC45: =if(B16="DIV", F16,"")
A46: 44055 | B46: NSE | C46: Sell | D46: 50 | E46: 489.63 | F46: 24481.54 | G46: ~ | H46: 24.74 | I46: 148.72 | J46: =Index!$C$2 | K46: =IF(AND( C17="Buy", ISBLANK(W17), B17<>"DIV"), L17/sum(F17:I17), "") | L46: =IF(AND( C17="Buy", ISBLANK(W17), B17<>"DIV"), (1-Index!$F$2*2)*((J17*D17)-(E17*D17)), "") | M46: =IF(AND( C17="Buy", ISBLANK(W17), B17<>"DIV"), ((E17*D17)+L17), "") | N46: =IF(AND( C17="Buy", ISBLANK(W17), B17<>"DIV"), D17, "") | O46: =IF(AND( C17="Buy", ISBLANK(W17), B17<>"DIV", NOW()-A17 < 365), P17/sum(F17:I17), "") | P46: =IF(AND( C17="Buy", ISBLANK(W17), B17<>"DIV", NOW()-A17 < 365), (1-Index!$F$2*2)*((J17*D17)-(E17*D17)), "") | Q46: =IF(AND( C17="Buy", ISBLANK(W17), B17<>"DIV", NOW()-A17 < 365), ((E17*D17)+P17), "") | R46: =IF(AND( C17="Buy", ISBLANK(W17), B17<>"DIV", NOW()-A17 < 365), D17, "") | S46: =IF(AND( C17="Buy", ISBLANK(W17), B17<>"DIV", NOW()-A17 > 365), T17/sum(F17:I17), "") | T46: =IF(AND( C17="Buy", ISBLANK(W17), B17<>"DIV", NOW()-A17 > 365), (1-Index!$F$2*2)*((J17*D17)-(E17*D17)), "") | U46: =IF(AND( C17="Buy", ISBLANK(W17), B17<>"DIV", NOW()-A17 > 365), ((E17*D17)+T17), "") | V46: =IF(AND( C17="Buy", ISBLANK(W17), B17<>"DIV", NOW()-A17 > 365), D17, "") | Y46: =IF(AND( C17="Buy", W17<>"", AA17<>"", B17<>"DIV"), Z17/sum(F17:I17), "") | AC46: =if(B17="DIV", F17,"")
A47: 44050 | B47: NSE | C47: Sell | D47: 50 | E47: 470.08 | F47: 23504.1 | G47: ~ | H47: 23.54 | I47: 142.36 | J47: =Index!$C$2 | K47: =IF(AND( C18="Buy", ISBLANK(W18), B18<>"DIV"), L18/sum(F18:I18), "") | L47: =IF(AND( C18="Buy", ISBLANK(W18), B18<>"DIV"), (1-Index!$F$2*2)*((J18*D18)-(E18*D18)), "") | M47: =IF(AND( C18="Buy", ISBLANK(W18), B18<>"DIV"), ((E18*D18)+L18), "") | N47: =IF(AND( C18="Buy", ISBLANK(W18), B18<>"DIV"), D18, "") | O47: =IF(AND( C18="Buy", ISBLANK(W18), B18<>"DIV", NOW()-A18 < 365), P18/sum(F18:I18), "") | P47: =IF(AND( C18="Buy", ISBLANK(W18), B18<>"DIV", NOW()-A18 < 365), (1-Index!$F$2*2)*((J18*D18)-(E18*D18)), "") | Q47: =IF(AND( C18="Buy", ISBLANK(W18), B18<>"DIV", NOW()-A18 < 365), ((E18*D18)+P18), "") | R47: =IF(AND( C18="Buy", ISBLANK(W18), B18<>"DIV", NOW()-A18 < 365), D18, "") | S47: =IF(AND( C18="Buy", ISBLANK(W18), B18<>"DIV", NOW()-A18 > 365), T18/sum(F18:I18), "") | T47: =IF(AND( C18="Buy", ISBLANK(W18), B18<>"DIV", NOW()-A18 > 365), (1-Index!$F$2*2)*((J18*D18)-(E18*D18)), "") | U47: =IF(AND( C18="Buy", ISBLANK(W18), B18<>"DIV", NOW()-A18 > 365), ((E18*D18)+T18), "") | V47: =IF(AND( C18="Buy", ISBLANK(W18), B18<>"DIV", NOW()-A18 > 365), D18, "") | Y47: =IF(AND( C18="Buy", W18<>"", AA18<>"", B18<>"DIV"), Z18/sum(F18:I18), "") | AC47: =if(B18="DIV", F18,"")
... A54: 44025 | B54: NSE | C54: Sell | D54: 50 | E54: 437.94 | F54: 21896.98 | G54: ~ | H54: 21.87 | I54: 131.15 | J54: =Index!$C$2 | K54: =IF(AND( C25="Buy", ISBLANK(W25), B25<>"DIV"), L25/sum(F25:I25), "") | L54: =IF(AND( C25="Buy", ISBLANK(W25), B25<>"DIV"), (1-Index!$F$2*2)*((J25*D25)-(E25*D25)), "") | M54: =IF(AND( C25="Buy", ISBLANK(W25), B25<>"DIV"), ((E25*D25)+L25), "") | N54: =IF(AND( C25="Buy", ISBLANK(W25), B25<>"DIV"), D25, "") | O54: =IF(AND( C25="Buy", ISBLANK(W25), B25<>"DIV", NOW()-A25 < 365), P25/sum(F25:I25), "") | P54: =IF(AND( C25="Buy", ISBLANK(W25), B25<>"DIV", NOW()-A25 < 365), (1-Index!$F$2*2)*((J25*D25)-(E25*D25)), "") | Q54: =IF(AND( C25="Buy", ISBLANK(W25), B25<>"DIV", NOW()-A25 < 365), ((E25*D25)+P25), "") | R54: =IF(AND( C25="Buy", ISBLANK(W25), B25<>"DIV", NOW()-A25 < 365), D25, "") | S54: =IF(AND( C25="Buy", ISBLANK(W25), B25<>"DIV", NOW()-A25 > 365), T25/sum(F25:I25), "") | T54: =IF(AND( C25="Buy", ISBLANK(W25), B25<>"DIV", NOW()-A25 > 365), (1-Index!$F$2*2)*((J25*D25)-(E25*D25)), "") | U54: =IF(AND( C25="Buy", ISBLANK(W25), B25<>"DIV", NOW()-A25 > 365), ((E25*D25)+T25), "") | V54: =IF(AND( C25="Buy", ISBLANK(W25), B25<>"DIV", NOW()-A25 > 365), D25, "") | Y54: =IF(AND( C25="Buy", W25<>"", AA25<>"", B25<>"DIV"), Z25/sum(F25:I25), "") | AC54: =if(B25="DIV", F25,"")
A55: 43881 | B55: NSE | C55: Buy | D55: 10 | E55: 310.47 | F55: 3104.69 | G55: ~ | H55: 3.12 | I55: 18.57 | J55: =Index!$C$2 | L55: =IF(AND( C26="Buy", ISBLANK(W26), B26<>"DIV"), (1-Index!$F$2*2)*((J26*D26)-(E26*D26)), "") | M55: =IF(AND( C26="Buy", ISBLANK(W26), B26<>"DIV"), ((E26*D26)+L26), "") | N55: =IF(AND( C26="Buy", ISBLANK(W26), B26<>"DIV"), D26, "") | P55: =IF(AND( C26="Buy", ISBLANK(W26), B26<>"DIV", NOW()-A26 < 365), (1-Index!$F$2*2)*((J26*D26)-(E26*D26)), "") | Q55: =IF(AND( C26="Buy", ISBLANK(W26), B26<>"DIV", NOW()-A26 < 365), ((E26*D26)+P26), "") | R55: =IF(AND( C26="Buy", ISBLANK(W26), B26<>"DIV", NOW()-A26 < 365), D26, "") | T55: =IF(AND( C26="Buy", ISBLANK(W26), B26<>"DIV", NOW()-A26 > 365), (J26*D26)-(E26*D26)-(2*sum(H26:I26)), "") | U55: =IF(AND( C26="Buy", ISBLANK(W26), B26<>"DIV", NOW()-A26 > 365), ((E26*D26)+T26), "") | V55: =IF(AND( C26="Buy", ISBLANK(W26), B26<>"DIV", NOW()-A26 > 365), D26, "") | W55: 476.52 | X55: 44075 | Y55: =IF(AND( C26="Buy", W26<>"", AA26<>"", B26<>"DIV"), Z26/sum(F26:I26), "") | Z55: =(1-Index!$F$2*2)*((W26*D26)-(E26*D26)) | AA55: =((E26*D26)+Z26) | AB55: =D26 | AC55: =if(B26="DIV", F26,"")
A56: 43865 | B56: NSE | C56: Buy | D56: 10 | E56: 315.21 | F56: 3152.1 | G56: ~ | H56: 3.19 | I56: 18.91 | J56: =Index!$C$2 | L56: =IF(AND( C27="Buy", ISBLANK(W27), B27<>"DIV"), (1-Index!$F$2*2)*((J27*D27)-(E27*D27)), "") | M56: =IF(AND( C27="Buy", ISBLANK(W27), B27<>"DIV"), ((E27*D27)+L27), "") | N56: =IF(AND( C27="Buy", ISBLANK(W27), B27<>"DIV"), D27, "") | P56: =IF(AND( C27="Buy", ISBLANK(W27), B27<>"DIV", NOW()-A27 < 365), (1-Index!$F$2*2)*((J27*D27)-(E27*D27)), "") | Q56: =IF(AND( C27="Buy", ISBLANK(W27), B27<>"DIV", NOW()-A27 < 365), ((E27*D27)+P27), "") | R56: =IF(AND( C27="Buy", ISBLANK(W27), B27<>"DIV", NOW()-A27 < 365), D27, "") | T56: =IF(AND( C27="Buy", ISBLANK(W27), B27<>"DIV", NOW()-A27 > 365), (J27*D27)-(E27*D27)-(2*sum(H27:I27)), "") | U56: =IF(AND( C27="Buy", ISBLANK(W27), B27<>"DIV", NOW()-A27 > 365), ((E27*D27)+T27), "") | V56: =IF(AND( C27="Buy", ISBLANK(W27), B27<>"DIV", NOW()-A27 > 365), D27, "") | W56: 476.52 | X56: 44075 | Y56: =IF(AND( C27="Buy", W27<>"", AA27<>"", B27<>"DIV"), Z27/sum(F27:I27), "") | Z56: =(1-Index!$F$2*2)*((W27*D27)-(E27*D27)) | AA56: =((E27*D27)+Z27) | AB56: =D27 | AC56: =if(B27="DIV", F27,"")
A57: 43864 | B57: NSE | C57: Buy | D57: 10 | E57: 318.07 | F57: 3180.66 | G57: ~ | H57: 3.16 | I57: 19 | J57: =Index!$C$2 | L57: =IF(AND( C28="Buy", ISBLANK(W28), B28<>"DIV"), (1-Index!$F$2*2)*((J28*D28)-(E28*D28)), "") | M57: =IF(AND( C28="Buy", ISBLANK(W28), B28<>"DIV"), ((E28*D28)+L28), "") | N57: =IF(AND( C28="Buy", ISBLANK(W28), B28<>"DIV"), D28, "") | P57: =IF(AND( C28="Buy", ISBLANK(W28), B28<>"DIV", NOW()-A28 < 365), (1-Index!$F$2*2)*((J28*D28)-(E28*D28)), "") | Q57: =IF(AND( C28="Buy", ISBLANK(W28), B28<>"DIV", NOW()-A28 < 365), ((E28*D28)+P28), "") | R57: =IF(AND( C28="Buy", ISBLANK(W28), B28<>"DIV", NOW()-A28 < 365), D28, "") | T57: =IF(AND( C28="Buy", ISBLANK(W28), B28<>"DIV", NOW()-A28 > 365), (J28*D28)-(E28*D28)-(2*sum(H28:I28)), "") | U57: =IF(AND( C28="Buy", ISBLANK(W28), B28<>"DIV", NOW()-A28 > 365), ((E28*D28)+T28), "") | V57: =IF(AND( C28="Buy", ISBLANK(W28), B28<>"DIV", NOW()-A28 > 365), D28, "") | W57: 476.52 | X57: 44075 | Y57: =IF(AND( C28="Buy", W28<>"", AA28<>"", B28<>"DIV"), Z28/sum(F28:I28), "") | Z57: =(1-Index!$F$2*2)*((W28*D28)-(E28*D28)) | AA57: =((E28*D28)+Z28) | AB57: =D28 | AC57: =if(B28="DIV", F28,"")
A58: 43860 | B58: NSE | C58: Buy | D58: 10 | E58: 314.54 | F58: 3145.39 | G58: ~ | H58: 3.08 | I58: 18.81 | J58: =Index!$C$2 | L58: =IF(AND( C29="Buy", ISBLANK(W29), B29<>"DIV"), (1-Index!$F$2*2)*((J29*D29)-(E29*D29)), "") | M58: =IF(AND( C29="Buy", ISBLANK(W29), B29<>"DIV"), ((E29*D29)+L29), "") | N58: =IF(AND( C29="Buy", ISBLANK(W29), B29<>"DIV"), D29, "") | P58: =IF(AND( C29="Buy", ISBLANK(W29), B29<>"DIV", NOW()-A29 < 365), (1-Index!$F$2*2)*((J29*D29)-(E29*D29)), "") | Q58: =IF(AND( C29="Buy", ISBLANK(W29), B29<>"DIV", NOW()-A29 < 365), ((E29*D29)+P29), "") | R58: =IF(AND( C29="Buy", ISBLANK(W29), B29<>"DIV", NOW()-A29 < 365), D29, "") | T58: =IF(AND( C29="Buy", ISBLANK(W29), B29<>"DIV", NOW()-A29 > 365), (J29*D29)-(E29*D29)-(2*sum(H29:I29)), "") | U58: =IF(AND( C29="Buy", ISBLANK(W29), B29<>"DIV", NOW()-A29 > 365), ((E29*D29)+T29), "") | V58: =IF(AND( C29="Buy", ISBLANK(W29), B29<>"DIV", NOW()-A29 > 365), D29, "") | W58: 489.63 | X58: 44055 | Y58: =IF(AND( C29="Buy", W29<>"", AA29<>"", B29<>"DIV"), Z29/sum(F29:I29), "") | Z58: =(1-Index!$F$2*2)*((W29*D29)-(E29*D29)) | AA58: =((E29*D29)+Z29) | AB58: =D29 | AC58: =if(B29="DIV", F29,"")
A59: 43846 | B59: NSE | C59: Buy | D59: 10 | E59: 312.23 | F59: 3122.32 | G59: ~ | H59: 3.16 | I59: 18.66 | J59: =Index!$C$2 | L59: =IF(AND( C30="Buy", ISBLANK(W30), B30<>"DIV"), (1-Index!$F$2*2)*((J30*D30)-(E30*D30)), "") | M59: =IF(AND( C30="Buy", ISBLANK(W30), B30<>"DIV"), ((E30*D30)+L30), "") | N59: =IF(AND( C30="Buy", ISBLANK(W30), B30<>"DIV"), D30, "") | P59: =IF(AND( C30="Buy", ISBLANK(W30), B30<>"DIV", NOW()-A30 < 365), (1-Index!$F$2*2)*((J30*D30)-(E30*D30)), "") | Q59: =IF(AND( C30="Buy", ISBLANK(W30), B30<>"DIV", NOW()-A30 < 365), ((E30*D30)+P30), "") | R59: =IF(AND( C30="Buy", ISBLANK(W30), B30<>"DIV", NOW()-A30 < 365), D30, "") | T59: =IF(AND( C30="Buy", ISBLANK(W30), B30<>"DIV", NOW()-A30 > 365), (J30*D30)-(E30*D30)-(2*sum(H30:I30)), "") | U59: =IF(AND( C30="Buy", ISBLANK(W30), B30<>"DIV", NOW()-A30 > 365), ((E30*D30)+T30), "") | V59: =IF(AND( C30="Buy", ISBLANK(W30), B30<>"DIV", NOW()-A30 > 365), D30, "") | W59: 470.08 | X59: 44050 | Y59: =IF(AND( C30="Buy", W30<>"", AA30<>"", B30<>"DIV"), Z30/sum(F30:I30), "") | Z59: =(1-Index!$F$2*2)*((W30*D30)-(E30*D30)) | AA59: =((E30*D30)+Z30) | AB59: =D30 | AC59: =if(B30="DIV", F30,"")
A60: 43845 | B60: NSE | C60: Buy | D60: 20 | E60: 311.98 | F60: 6239.57 | G60: ~ | H60: 6.22 | I60: 37.35 | J60: =Index!$C$2 | L60: =IF(AND( C31="Buy", ISBLANK(W31), B31<>"DIV"), (1-Index!$F$2*2)*((J31*D31)-(E31*D31)), "") | M60: =IF(AND( C31="Buy", ISBLANK(W31), B31<>"DIV"), ((E31*D31)+L31), "") | N60: =IF(AND( C31="Buy", ISBLANK(W31), B31<>"DIV"), D31, "") | P60: =IF(AND( C31="Buy", ISBLANK(W31), B31<>"DIV", NOW()-A31 < 365), (1-Index!$F$2*2)*((J31*D31)-(E31*D31)), "") | Q60: =IF(AND( C31="Buy", ISBLANK(W31), B31<>"DIV", NOW()-A31 < 365), ((E31*D31)+P31), "") | R60: =IF(AND( C31="Buy", ISBLANK(W31), B31<>"DIV", NOW()-A31 < 365), D31, "") | T60: =IF(AND( C31="Buy", ISBLANK(W31), B31<>"DIV", NOW()-A31 > 365), (J31*D31)-(E31*D31)-(2*sum(H31:I31)), "") | U60: =IF(AND( C31="Buy", ISBLANK(W31), B31<>"DIV", NOW()-A31 > 365), ((E31*D31)+T31), "") | V60: =IF(AND( C31="Buy", ISBLANK(W31), B31<>"DIV", NOW()-A31 > 365), D31, "") | W60: 489.63 | X60: 44055 | Y60: =IF(AND( C31="Buy", W31<>"", AA31<>"", B31<>"DIV"), Z31/sum(F31:I31), "") | Z60: =(1-Index!$F$2*2)*((W31*D31)-(E31*D31)) | AA60: =((E31*D31)+Z31) | AB60: =D31 | AC60: =if(B31="DIV", F31,"")
A61: 43844 | B61: NSE | C61: Buy | D61: 20 | E61: 313.54 | F61: 6270.73 | G61: ~ | H61: 6.19 | I61: 37.54 | J61: =Index!$C$2 | L61: =IF(AND( C32="Buy", ISBLANK(W32), B32<>"DIV"), (1-Index!$F$2*2)*((J32*D32)-(E32*D32)), "") | M61: =IF(AND( C32="Buy", ISBLANK(W32), B32<>"DIV"), ((E32*D32)+L32), "") | N61: =IF(AND( C32="Buy", ISBLANK(W32), B32<>"DIV"), D32, "") | P61: =IF(AND( C32="Buy", ISBLANK(W32), B32<>"DIV", NOW()-A32 < 365), (1-Index!$F$2*2)*((J32*D32)-(E32*D32)), "") | Q61: =IF(AND( C32="Buy", ISBLANK(W32), B32<>"DIV", NOW()-A32 < 365), ((E32*D32)+P32), "") | R61: =IF(AND( C32="Buy", ISBLANK(W32), B32<>"DIV", NOW()-A32 < 365), D32, "") | T61: =IF(AND( C32="Buy", ISBLANK(W32), B32<>"DIV", NOW()-A32 > 365), (J32*D32)-(E32*D32)-(2*sum(H32:I32)), "") | U61: =IF(AND( C32="Buy", ISBLANK(W32), B32<>"DIV", NOW()-A32 > 365), ((E32*D32)+T32), "") | V61: =IF(AND( C32="Buy", ISBLANK(W32), B32<>"DIV", NOW()-A32 > 365), D32, "") | W61: 489.63 | X61: 44055 | Y61: =IF(AND( C32="Buy", W32<>"", AA32<>"", B32<>"DIV"), Z32/sum(F32:I32), "") | Z61: =(1-Index!$F$2*2)*((W32*D32)-(E32*D32)) | AA61: =((E32*D32)+Z32) | AB61: =D32 | AC61: =if(B32="DIV", F32,"")
A62: 43838 | B62: NSE | C62: Buy | D62: 10 | E62: 312.31 | F62: 3123.14 | G62: ~ | H62: 2.51 | I62: 18.63 | J62: =Index!$C$2 | L62: =IF(AND( C33="Buy", ISBLANK(W33), B33<>"DIV"), (1-Index!$F$2*2)*((J33*D33)-(E33*D33)), "") | M62: =IF(AND( C33="Buy", ISBLANK(W33), B33<>"DIV"), ((E33*D33)+L33), "") | N62: =IF(AND( C33="Buy", ISBLANK(W33), B33<>"DIV"), D33, "") | P62: =IF(AND( C33="Buy", ISBLANK(W33), B33<>"DIV", NOW()-A33 < 365), (1-Index!$F$2*2)*((J33*D33)-(E33*D33)), "") | Q62: =IF(AND( C33="Buy", ISBLANK(W33), B33<>"DIV", NOW()-A33 < 365), ((E33*D33)+P33), "") | R62: =IF(AND( C33="Buy", ISBLANK(W33), B33<>"DIV", NOW()-A33 < 365), D33, "") | T62: =IF(AND( C33="Buy", ISBLANK(W33), B33<>"DIV", NOW()-A33 > 365), (J33*D33)-(E33*D33)-(2*sum(H33:I33)), "") | U62: =IF(AND( C33="Buy", ISBLANK(W33), B33<>"DIV", NOW()-A33 > 365), ((E33*D33)+T33), "") | V62: =IF(AND( C33="Buy", ISBLANK(W33), B33<>"DIV", NOW()-A33 > 365), D33, "") | W62: 470.08 | X62: 44050 | Y62: =IF(AND( C33="Buy", W33<>"", AA33<>"", B33<>"DIV"), Z33/sum(F33:I33), "") | Z62: =(1-Index!$F$2*2)*((W33*D33)-(E33*D33)) | AA62: =((E33*D33)+Z33) | AB62: =D33 | AC62: =if(B33="DIV", F33,"")
A63: 43837 | B63: NSE | C63: Buy | D63: 20 | E63: 310.55 | F63: 6210.95 | G63: ~ | H63: 2.45 | I63: 37 | J63: =Index!$C$2 | L63: =IF(AND( C34="Buy", ISBLANK(W34), B34<>"DIV"), (1-Index!$F$2*2)*((J34*D34)-(E34*D34)), "") | M63: =IF(AND( C34="Buy", ISBLANK(W34), B34<>"DIV"), ((E34*D34)+L34), "") | N63: =IF(AND( C34="Buy", ISBLANK(W34), B34<>"DIV"), D34, "") | P63: =IF(AND( C34="Buy", ISBLANK(W34), B34<>"DIV", NOW()-A34 < 365), (1-Index!$F$2*2)*((J34*D34)-(E34*D34)), "") | Q63: =IF(AND( C34="Buy", ISBLANK(W34), B34<>"DIV", NOW()-A34 < 365), ((E34*D34)+P34), "") | R63: =IF(AND( C34="Buy", ISBLANK(W34), B34<>"DIV", NOW()-A34 < 365), D34, "") | T63: =IF(AND( C34="Buy", ISBLANK(W34), B34<>"DIV", NOW()-A34 > 365), (J34*D34)-(E34*D34)-(2*sum(H34:I34)), "") | U63: =IF(AND( C34="Buy", ISBLANK(W34), B34<>"DIV", NOW()-A34 > 365), ((E34*D34)+T34), "") | V63: =IF(AND( C34="Buy", ISBLANK(W34), B34<>"DIV", NOW()-A34 > 365), D34, "") | W63: 470.08 | X63: 44050 | Y63: =IF(AND( C34="Buy", W34<>"", AA34<>"", B34<>"DIV"), Z34/sum(F34:I34), "") | Z63: =(1-Index!$F$2*2)*((W34*D34)-(E34*D34)) | AA63: =((E34*D34)+Z34) | AB63: =D34 | AC63: =if(B34="DIV", F34,"")
...

Sheet Index
B1: Code | C1: NSE:SYNGENE
B2: Current Price | C2: =IFERROR(__xludf.DUMMYFUNCTION("GOOGLEFINANCE($C$1, ""price"")"),447.95) | E2: Commission | F2: 0.007
B3: 52 Week High | C3: =IFERROR(__xludf.DUMMYFUNCTION("GOOGLEFINANCE($C$1, ""high52"")"),760.0)
B4: 52 Week Low | C4: =IFERROR(__xludf.DUMMYFUNCTION("GOOGLEFINANCE($C$1, ""low52"")"),439.0)
B6: UnRealised
A8: All | B8: Units | C8: =SUM('Trading History'!$N$4:$N1007) | E8: ST Units | F8: =IFERROR(SUM('Trading History'!$R$4:$R1007), 0) | H8: LT Units | I8: =SUM('Trading History'!$V$4:$V1007) | K8: Units | L8: =SUM('Trading History'!$AB$4:$AB1007)
B9: Avg % | C9: =IFERROR(Index!C10/(Index!C8*Index!$C$2), 0) | E9: ST Avg % | F9: =IFERROR(Index!F10/(Index!F8*Index!$C$2), 0) | H9: LT Avg % | I9: =IFERROR(Index!I10/(Index!I8*Index!$C$2), 0) | K9: Avg % | L9: =IFERROR(Index!L10/(Index!L8*Index!$C$2), 0)
B10: Gain | C10: =SUM('Trading History'!$L$4:$L1007) | E10: ST Gain | F10: =SUM('Trading History'!$P$4:$P1007) | H10: LT Gain | I10: =SUM('Trading History'!$T$4:$T1007) | K10: Gain | L10: =SUM('Trading History'!$Z$4:$Z1007)
B11: Invested | C11: =Index!C12-Index!C10 | E11: ST Invested | F11: =Index!F12-Index!F10 | H11: LT Invested | I11: =Index!I12-Index!I10 | K11: Invested | L11: =Index!L12-Index!L10
B12: Gross | C12: =SUM('Trading History'!$M$4:$M1007) | E12: ST Gross | F12: =SUM('Trading History'!$Q$4:$Q1007) | H12: LT Gross | I12: =SUM('Trading History'!$U$4:$U1007) | K12: Gross | L12: =SUM('Trading History'!$AA$4:$AA1007)
K13: Dividends | L13: =SUMIF('Trading History'!$B17:$B1007,"DIV",'Trading History'!$AC$4:$AC1007)
A15: 0.5 | B15: Units | C15: =SUMIFS('Trading History'!$N$4:$N1007, 'Trading History'!$K$4:$K1007, CONCAT(">", $A15)) | E15: ST Units | F15: =IFERROR(SUMIFS('Trading History'!$R$4:$R1007, 'Trading History'!$O$4:$O1007, CONCAT(">", $A15)), 0) | H15: LT Units | I15: =SUMIFS('Trading History'!$V$4:$V1007, 'Trading History'!$S$4:$S1007, CONCAT(">", $A15)) | K15: Units | L15: =SUMIFS('Trading History'!$AB$4:$AB1007, 'Trading History'!$Y$4:$Y1007, CONCAT(">", $A15))
B16: Avg % | C16: =IFERROR(Index!C17/(Index!C15*Index!$C$2), 0) | E16: ST Avg % | F16: =IFERROR(Index!F17/(Index!F15*Index!$C$2), 0) | H16: LT Avg % | I16: =IFERROR(Index!I17/(Index!I15*Index!$C$2), 0) | K16: Avg % | L16: =IFERROR(Index!L17/(Index!L15*Index!$C$2), 0)
B17: Gain | C17: =SUMIFS('Trading History'!$L$4:$L1007, 'Trading History'!$K$4:$K1007, CONCAT(">", $A15)) | E17: ST Gain | F17: =SUMIFS('Trading History'!$P$4:$P1007, 'Trading History'!$O$4:$O1007, CONCAT(">", $A15)) | H17: LT Gain | I17: =SUMIFS('Trading History'!$T$4:$T1007, 'Trading History'!$S$4:$S1007, CONCAT(">", $A15)) | K17: Gain | L17: =SUMIFS('Trading History'!$Z$4:$Z1007, 'Trading History'!$Y$4:$Y1007, CONCAT(">", $A15))
B18: Invested | C18: =Index!C19-Index!C17 | E18: ST Invested | F18: =Index!F19-Index!F17 | H18: LT Invested | I18: =Index!I19-Index!I17 | K18: Invested | L18: =Index!L19-Index!L17
B19: Gross | C19: =SUMIFS('Trading History'!$M$4:$M1007, 'Trading History'!$K$4:$K1007, CONCAT(">", $A15)) | E19: ST Gross | F19: =SUMIFS('Trading History'!$Q$4:$Q1007, 'Trading History'!$O$4:$O1007, CONCAT(">", $A15)) | H19: LT Gross | I19: =SUMIFS('Trading History'!$U$4:$U1007, 'Trading History'!$S$4:$S1007, CONCAT(">", $A15)) | K19: Gross | L19: =SUMIFS('Trading History'!$AA$4:$AA1007, 'Trading History'!$Y$4:$Y1007, CONCAT(">", $A15))
A22: 0.45 | B22: Units | C22: =SUMIFS('Trading History'!$N$4:$N1007, 'Trading History'!$K$4:$K1007, CONCAT(">", $A22)) | E22: ST Units | F22: =IFERROR(SUMIFS('Trading History'!$R$4:$R1007, 'Trading History'!$O$4:$O1007, CONCAT(">", $A22)), 0) | H22: LT Units | I22: =SUMIFS('Trading History'!$V$4:$V1007, 'Trading History'!$S$4:$S1007, CONCAT(">", $A22)) | K22: Units | L22: =SUMIFS('Trading History'!$AB$4:$AB1007, 'Trading History'!$Y$4:$Y1007, CONCAT(">", $A22))
B23: Avg % | C23: =IFERROR(Index!C24/(Index!C22*Index!$C$2), 0) | E23: ST Avg % | F23: =IFERROR(Index!F24/(Index!F22*Index!$C$2), 0) | H23: LT Avg % | I23: =IFERROR(Index!I24/(Index!I22*Index!$C$2), 0) | K23: Avg % | L23: =IFERROR(Index!L24/(Index!L22*Index!$C$2), 0)
B24: Gain | C24: =SUMIFS('Trading History'!$L$4:$L1007, 'Trading History'!$K$4:$K1007, CONCAT(">", $A22)) | E24: ST Gain | F24: =SUMIFS('Trading History'!$P$4:$P1007, 'Trading History'!$O$4:$O1007, CONCAT(">", $A22)) | H24: LT Gain | I24: =SUMIFS('Trading History'!$T$4:$T1007, 'Trading History'!$S$4:$S1007, CONCAT(">", $A22)) | K24: Gain | L24: =SUMIFS('Trading History'!$Z$4:$Z1007, 'Trading History'!$Y$4:$Y1007, CONCAT(">", $A22))
B25: Invested | C25: =Index!C26-Index!C24 | E25: ST Invested | F25: =Index!F26-Index!F24 | H25: LT Invested | I25: =Index!I26-Index!I24 | K25: Invested | L25: =Index!L26-Index!L24
B26: Gross | C26: =SUMIFS('Trading History'!$M$4:$M1007, 'Trading History'!$K$4:$K1007, CONCAT(">", $A22)) | E26: ST Gross | F26: =SUMIFS('Trading History'!$Q$4:$Q1007, 'Trading History'!$O$4:$O1007, CONCAT(">", $A22)) | H26: LT Gross | I26: =SUMIFS('Trading History'!$U$4:$U1007, 'Trading History'!$S$4:$S1007, CONCAT(">", $A22)) | K26: Gross | L26: =SUMIFS('Trading History'!$AA$4:$AA1007, 'Trading History'!$Y$4:$Y1007, CONCAT(">", $A22))
A29: 0.4 | B29: Units | C29: =SUMIFS('Trading History'!$N$4:$N1007, 'Trading History'!$K$4:$K1007, CONCAT(">", $A29)) | E29: ST Units | F29: =IFERROR(SUMIFS('Trading History'!$R$4:$R1007, 'Trading History'!$O$4:$O1007, CONCAT(">", $A29)), 0) | H29: LT Units | I29: =SUMIFS('Trading History'!$V$4:$V1007, 'Trading History'!$S$4:$S1007, CONCAT(">", $A29)) | K29: Units | L29: =SUMIFS('Trading History'!$AB$4:$AB1007, 'Trading History'!$Y$4:$Y1007, CONCAT(">", $A29))
B30: Avg % | C30: =IFERROR(Index!C31/(Index!C29*Index!$C$2), 0) | E30: ST Avg % | F30: =IFERROR(Index!F31/(Index!F29*Index!$C$2), 0) | H30: LT Avg % | I30: =IFERROR(Index!I31/(Index!I29*Index!$C$2), 0) | K30: Avg % | L30: =IFERROR(Index!L31/(Index!L29*Index!$C$2), 0)
B31: Gain | C31: =SUMIFS('Trading History'!$L$4:$L1007, 'Trading History'!$K$4:$K1007, CONCAT(">", $A29)) | E31: ST Gain | F31: =SUMIFS('Trading History'!$P$4:$P1007, 'Trading History'!$O$4:$O1007, CONCAT(">", $A29)) | H31: LT Gain | I31: =SUMIFS('Trading History'!$T$4:$T1007, 'Trading History'!$S$4:$S1007, CONCAT(">", $A29)) | K31: Gain | L31: =SUMIFS('Trading History'!$Z$4:$Z1007, 'Trading History'!$Y$4:$Y1007, CONCAT(">", $A29))
B32: Invested | C32: =Index!C33-Index!C31 | E32: ST Invested | F32: =Index!F33-Index!F31 | H32: LT Invested | I32: =Index!I33-Index!I31 | K32: Invested | L32: =Index!L33-Index!L31
B33: Gross | C33: =SUMIFS('Trading History'!$M$4:$M1007, 'Trading History'!$K$4:$K1007, CONCAT(">", $A29)) | E33: ST Gross | F33: =SUMIFS('Trading History'!$Q$4:$Q1007, 'Trading History'!$O$4:$O1007, CONCAT(">", $A29)) | H33: LT Gross | I33: =SUMIFS('Trading History'!$U$4:$U1007, 'Trading History'!$S$4:$S1007, CONCAT(">", $A29)) | K33: Gross | L33: =SUMIFS('Trading History'!$AA$4:$AA1007, 'Trading History'!$Y$4:$Y1007, CONCAT(">", $A29))
A36: 0.35 | B36: Units | C36: =SUMIFS('Trading History'!$N$4:$N1007, 'Trading History'!$K$4:$K1007, CONCAT(">", $A36)) | E36: ST Units | F36: =IFERROR(SUMIFS('Trading History'!$R$4:$R1007, 'Trading History'!$O$4:$O1007, CONCAT(">", $A36)), 0) | H36: LT Units | I36: =SUMIFS('Trading History'!$V$4:$V1007, 'Trading History'!$S$4:$S1007, CONCAT(">", $A36)) | K36: Units | L36: =SUMIFS('Trading History'!$AB$4:$AB1007, 'Trading History'!$Y$4:$Y1007, CONCAT(">", $A36))
B37: Avg % | C37: =IFERROR(Index!C38/(Index!C36*Index!$C$2), 0) | E37: ST Avg % | F37: =IFERROR(Index!F38/(Index!F36*Index!$C$2), 0) | H37: LT Avg % | I37: =IFERROR(Index!I38/(Index!I36*Index!$C$2), 0) | K37: Avg % | L37: =IFERROR(Index!L38/(Index!L36*Index!$C$2), 0)
B38: Gain | C38: =SUMIFS('Trading History'!$L$4:$L1007, 'Trading History'!$K$4:$K1007, CONCAT(">", $A36)) | E38: ST Gain | F38: =SUMIFS('Trading History'!$P$4:$P1007, 'Trading History'!$O$4:$O1007, CONCAT(">", $A36)) | H38: LT Gain | I38: =SUMIFS('Trading History'!$T$4:$T1007, 'Trading History'!$S$4:$S1007, CONCAT(">", $A36)) | K38: Gain | L38: =SUMIFS('Trading History'!$Z$4:$Z1007, 'Trading History'!$Y$4:$Y1007, CONCAT(">", $A36))
B39: Invested | C39: =Index!C40-Index!C38 | E39: ST Invested | F39: =Index!F40-Index!F38 | H39: LT Invested | I39: =Index!I40-Index!I38 | K39: Invested | L39: =Index!L40-Index!L38
B40: Gross | C40: =SUMIFS('Trading History'!$M$4:$M1007, 'Trading History'!$K$4:$K1007, CONCAT(">", $A36)) | E40: ST Gross | F40: =SUMIFS('Trading History'!$Q$4:$Q1007, 'Trading History'!$O$4:$O1007, CONCAT(">", $A36)) | H40: LT Gross | I40: =SUMIFS('Trading History'!$U$4:$U1007, 'Trading History'!$S$4:$S1007, CONCAT(">", $A36)) | K40: Gross | L40: =SUMIFS('Trading History'!$AA$4:$AA1007, 'Trading History'!$Y$4:$Y1007, CONCAT(">", $A36))
A43: 0.3 | B43: Units | C43: =SUMIFS('Trading History'!$N$4:$N1007, 'Trading History'!$K$4:$K1007, CONCAT(">", $A43)) | E43: ST Units | F43: =IFERROR(SUMIFS('Trading History'!$R$4:$R1007, 'Trading History'!$O$4:$O1007, CONCAT(">", $A43)), 0) | H43: LT Units | I43: =SUMIFS('Trading History'!$V$4:$V1007, 'Trading History'!$S$4:$S1007, CONCAT(">", $A43)) | K43: Units | L43: =SUMIFS('Trading History'!$AB$4:$AB1007, 'Trading History'!$Y$4:$Y1007, CONCAT(">", $A43))
B44: Avg % | C44: =IFERROR(Index!C45/(Index!C43*Index!$C$2), 0) | E44: ST Avg % | F44: =IFERROR(Index!F45/(Index!F43*Index!$C$2), 0) | H44: LT Avg % | I44: =IFERROR(Index!I45/(Index!I43*Index!$C$2), 0) | K44: Avg % | L44: =IFERROR(Index!L45/(Index!L43*Index!$C$2), 0)
B45: Gain | C45: =SUMIFS('Trading History'!$L$4:$L1007, 'Trading History'!$K$4:$K1007, CONCAT(">", $A43)) | E45: ST Gain | F45: =SUMIFS('Trading History'!$P$4:$P1007, 'Trading History'!$O$4:$O1007, CONCAT(">", $A43)) | H45: LT Gain | I45: =SUMIFS('Trading History'!$T$4:$T1007, 'Trading History'!$S$4:$S1007, CONCAT(">", $A43)) | K45: Gain | L45: =SUMIFS('Trading History'!$Z$4:$Z1007, 'Trading History'!$Y$4:$Y1007, CONCAT(">", $A43))
B46: Invested | C46: =Index!C47-Index!C45 | E46: ST Invested | F46: =Index!F47-Index!F45 | H46: LT Invested | I46: =Index!I47-Index!I45 | K46: Invested | L46: =Index!L47-Index!L45
B47: Gross | C47: =SUMIFS('Trading History'!$M$4:$M1007, 'Trading History'!$K$4:$K1007, CONCAT(">", $A43)) | E47: ST Gross | F47: =SUMIFS('Trading History'!$Q$4:$Q1007, 'Trading History'!$O$4:$O1007, CONCAT(">", $A43)) | H47: LT Gross | I47: =SUMIFS('Trading History'!$U$4:$U1007, 'Trading History'!$S$4:$S1007, CONCAT(">", $A43)) | K47: Gross | L47: =SUMIFS('Trading History'!$AA$4:$AA1007, 'Trading History'!$Y$4:$Y1007, CONCAT(">", $A43))
A50: 0.25 | B50: Units | C50: =SUMIFS('Trading History'!$N$4:$N1007, 'Trading History'!$K$4:$K1007, CONCAT(">", $A50)) | E50: ST Units | F50: =IFERROR(SUMIFS('Trading History'!$R$4:$R1007, 'Trading History'!$O$4:$O1007, CONCAT(">", $A50)), 0) | H50: LT Units | I50: =SUMIFS('Trading History'!$V$4:$V1007, 'Trading History'!$S$4:$S1007, CONCAT(">", $A50)) | K50: Units | L50: =SUMIFS('Trading History'!$AB$4:$AB1007, 'Trading History'!$Y$4:$Y1007, CONCAT(">", $A50))
B51: Avg % | C51: =IFERROR(Index!C52/(Index!C50*Index!$C$2), 0) | E51: ST Avg % | F51: =IFERROR(Index!F52/(Index!F50*Index!$C$2), 0) | H51: LT Avg % | I51: =IFERROR(Index!I52/(Index!I50*Index!$C$2), 0) | K51: Avg % | L51: =IFERROR(Index!L52/(Index!L50*Index!$C$2), 0)
B52: Gain | C52: =SUMIFS('Trading History'!$L$4:$L1007, 'Trading History'!$K$4:$K1007, CONCAT(">", $A50)) | E52: ST Gain | F52: =SUMIFS('Trading History'!$P$4:$P1007, 'Trading History'!$O$4:$O1007, CONCAT(">", $A50)) | H52: LT Gain | I52: =SUMIFS('Trading History'!$T$4:$T1007, 'Trading History'!$S$4:$S1007, CONCAT(">", $A50)) | K52: Gain | L52: =SUMIFS('Trading History'!$Z$4:$Z1007, 'Trading History'!$Y$4:$Y1007, CONCAT(">", $A50))
B53: Invested | C53: =Index!C54-Index!C52 | E53: ST Invested | F53: =Index!F54-Index!F52 | H53: LT Invested | I53: =Index!I54-Index!I52 | K53: Invested | L53: =Index!L54-Index!L52
...
